Workbook

Sheet CASES
C4: WHEN MORATORIUM,EMI AND SALE BILL IN SAME YEAR
C5: First year 12 month period
C6: Moratorium period | D6: 0
B7: CASE 1 | C7: Moratorium Interest | D7: 0
C8: EMI period | D8: 12
C9: Sale bill period | D9: 12
C11: First year 12 month period
C12: Moratorium period | D12: 3
B13: CASE 2 | C13: Moratorium Interest | D13: 3
C14: EMI period | D14: 9
C15: Sale bill period | D15: 12
C18: WHEN MORATORIUM,EMI AND SALE BILL IN 2 YEARS
C19: First year 6 month period | F19: Balance covered in 2nd year
C20: Moratorium period | D20: 0 | F20: Moratorium period | H20: 0
B21: CASE 3 | C21: Moratorium Interest | D21: 0 | F21: Moratorium Interest | H21: 0
C22: EMI period | D22: 3 | F22: EMI period | H22: 12
C23: Sale bill period | D23: 3 | F23: Sale bill period | H23: 12
C25: First year 6 month period | F25: Balance covered in 2nd year
C26: Moratorium period | D26: 6 | F26: Moratorium period | H26: 0
B27: CASE 4 | C27: Moratorium Interest | D27: 6 | F27: Moratorium Interest | H27: 0
C28: EMI period | D28: 0 | F28: EMI period | H28: 12
C29: Sale bill period | D29: 6 | F29: Sale bill period | H29: 12
C31: First year 6 month period | F31: Balance covered in 2nd year
C32: Moratorium period | D32: 6 | F32: Moratorium period | H32: 0
B33: CASE 5 | C33: Moratorium Interest | D33: 6 | F33: Moratorium Interest | H33: 0
C34: EMI period | D34: 0 | F34: EMI period | H34: 12
C35: Sale bill period | D35: 0 | F35: Sale bill period | H35: 12
C38: WHEN MORATORIUM,EMI AND SALE BILL IN 2 YEARS
C39: First year 3 month period | F39: Balance covered in 2nd year
C40: Moratorium period | D40: 0 | F40: Moratorium period | H40: 0
B41: CASE 6 | C41: Moratorium Interest | D41: 0 | F41: Moratorium Interest | H41: 0
C42: EMI period | D42: 3 | F42: EMI period | H42: 12
C43: Sale bill period | D43: 3 | F43: Sale bill period | H43: 12
C45: First year 3 month period | F45: Balance covered in 2nd year
C46: Moratorium period | D46: 6(3) | F46: Moratorium period | H46: 12(3)
B47: CASE 7 | C47: Moratorium Interest | D47: 6(3) | F47: Moratorium Interest | H47: 12(3)
C48: EMI period | D48: 0 | F48: EMI period | H48: 9
C49: Sale bill period | D49: 3 | F49: Sale bill period | H49: 12
C51: First year 6 month period | F51: Balance covered in 2nd year
C52: Moratorium period | D52: 6(3) | F52: Moratorium period | H52: 12(3)
...

Sheet Assumptions
B2: Section | C2: Question | I2: Answer | K2: Paticulars
D6: Question Type | E6: Editable | F6: Min and Max | G6: Options
B7: General information | C7: Status of Concern | D7: Dropdown Option to be provided | E7: No | G7: Sole Proprietorship / Partnership Firm / Private limited Company,LLP,Society,Trust,Federation | I7: Sole Proprietorship
C8: Name of proprietor / Managing Partner / Managing Director | D8: Manual entry | E8: No | I8: John Doe
C9: Mobile Number of proprietor / Managing Partner / Managing Director | D9: Manual entry | E9: No | I9: 9876543210
C10: Adhar number(Optional) | D10: Manual entry | E10: No | I10: 123456789012
C11: PAN of proprietor / Managing Partner / Managing Director(Optional) | D11: Manual entry | E11: No | I11: ABCDE1234F
C12: Age of Proprietorship / Managing Partner / Managing Director | D12: Manual entry | E12: No | I12: 35
C13: Gender | D13: Dropdown Option to be provided | E13: No | G13: Male,Female,Others | I13: Male
C14: Sector | D14: Dropdown Option to be provided | E14: No | G14: Manufacturing sector / Service Sector (With stock) / Service sector (Without stock) | I14: Manufacturing sector | K14: Applicable to Manufacturing or Service Sector (With Stock)
C15: Nature of Business | D15: Manual entry | E15: No | I15: Textile Manufacturing
C16: Address of office/Factory | D16: Manual entry | E16: No | I16: 123 Industrial Area, City
C17: Name of Firm / Company (Optional) | D17: Manual entry | E17: No | I17: Doe Textiles
C18: PAN of Firm / Company (Optional) | D18: Manual entry | E18: No | I18: ABCDE1234F
C19: Education Qualification | D19: Dropdown Option to be provided | E19: No | G19: Below 8th,Above 8th,SSC 10th+2,Graduate,Post Graduate | I19: Graduate
C20: Project covered under which Scheme | D20: Dropdown Option to be provided | E20: No | G20: AP IDP 4.0,Industrial park Land Allotment,PMEGP,Mudra,Other MSME | I20: PMEGP
C21: Caste | D21: Dropdown Option to be provided | E21: No | G21: OC,SC,ST,BC,Minority | I21: OC
C22: Unit location | D22: Dropdown Option to be provided | E22: No | G22: Rural,Urban | I22: Urban
J23: Salary per Month
B24: Expected Employment Generation : | C24: Skilled employees | D24: Manual entry | E24: Yes | I24: 5 | J24: 15000
C25: Semi Skilled Employees | D25: Manual entry | E25: Yes | I25: 3 | J25: 12000
C26: Unskiled Employees | D26: Manual entry | E26: Yes | I26: 2 | J26: 10000
I27: Rs in Lacs | K27: Loan % (Manual entry) | L27: Loan Amount(Rs in lacs)
B28: Cost of Project details | C28: Plant and Machinery | D28: Manual entry | E28: Yes | I28: =F134 -> 70000 | K28: 90 | L28: =K28/100*I28 -> 63000
C29: Service Equipment | D29: Manual entry | E29: Yes | I29: =F144 -> 0 | L29: =K29/100*I29 -> 0
C30: Shed Construction and Civil works | D30: Manual entry | E30: Yes | I30: =F154 -> 0 | L30: =K30/100*I30 -> 0
C31: Land | D31: Manual entry | E31: Yes | I31: =F164 -> 0 | L31: =K31/100*I31 -> 0
C32: Electrical Items & fittings | D32: Manual entry | E32: Yes | I32: =F167 -> 0 | L32: =K32/100*I32 -> 0
C33: Electronic Items | D33: Manual entry | E33: Yes | I33: =F177 -> 0 | L33: =K33/100*I33 -> 0
A34: STEP 1 | C34: Furniture and Fittings | D34: Manual entry | E34: Yes | I34: =F187 -> 5000 | L34: =K34/100*I34 -> 0
C35: Vehicles | D35: Manual entry | E35: Yes | I35: =F197 -> 0 | L35: =K35/100*I35 -> 0
C36: Live stock | D36: Manual entry | E36: Yes | I36: =F206 -> 0 | L36: =K36/100*I36 -> 0
C37: Other Assets | D37: Manual entry | E37: Yes | I37: =F216 -> 0 | L37: =K37/100*I37 -> 0
C38: Other Assets (Nil Depreciation) | D38: Manual entry | E38: Yes | I38: =F226 -> 0 | L38: =K38/100*I38 -> 0
C39: Non Current Assets (Deposits , Advances etc) | D39: Manual entry | E39: Yes | I39: =F235 -> 0 | L39: =K39/100*I39 -> 0
C40: Working capital Requirement | D40: Manual entry | E40: Yes | I40: 500000 | K40: 90 | L40: =K40/100*I40 -> 450000
C41: Total Project Cost | D41: Autogenerated | E41: Not applicable since Autogenrated | I41: =SUM(I28:J40) -> 575000 | L41: =SUM(L28:L40) -> 513000
B43: Means of Finance details | C43: Eligible Term Loan amount | D43: Autogenerated and also manually edited | E43: Yes | I43: =SUM(L28:L39) -> 63000 | K43: Lacs
C44: Margin money amount for Fixed Assets | D44: Manual entry | E44: Yes | I44: =SUM(I28:J39)-SUM(L28:L39) -> 12000 | K44: Lacs
C45: Term Loan Rate of Interest | D45: Manual entry | E45: Yes | H45: 10.5 | I45: =H45/100 -> 0.105
...

Sheet Workings for PL BS 1
A1: STEP 2 : BACK GROUND CALCULATION . NOT TO BE VISIBLE TO CUSTOMER
A2: WORKINGS FOR PROFIT AND LOSS ACCOUNT ,BALANCE SHEET , EXPENDITURE AND INTEREST
A3: PARTICULARS
D4: =Assumptions!I78 -> 2024-25 | E4: =Assumptions!I79 -> 2025-26 | F4: =Assumptions!I80 -> 2026-27 | G4: =Assumptions!I81 -> 2027-28 | H4: =Assumptions!I82 -> 2028-29 | I4: =Assumptions!I83 -> 2029-30 | J4: =Assumptions!I84 -> 2030-31 | K4: =Assumptions!I85 -> 2031-32
A8: Gross Revenue | D8: =D17+D16 -> 27534148125 | E8: =E17+E16 -> -8.5736031e+09 | F8: =F17+F16 -> 4.475018e+10 | G8: =G17+G16 -> 4.6822652e+10 | H8: =H17+H16 -> 4.88953e+10 | I8: =I17+I16 -> 5.0967902e+10 | J8: =J17+J16 -> 5.3040456e+10 | K8: =K17+K16 -> 5.5112963e+10
A9: Opening Stock | D9: 0 | E9: =D11 -> #REF! | F9: =E11 -> #REF! | G9: =F11 -> #REF! | H9: =G11 -> #REF! | I9: =H11 -> #REF! | J9: =I11 -> #REF! | K9: =J11 -> #REF!
A10: Direct expenses | D10: =D6*Assumptions!#REF! -> #REF! | E10: =E6*Assumptions!#REF! -> #REF! | F10: =F6*Assumptions!#REF! -> #REF! | G10: =G6*Assumptions!#REF! -> #REF! | H10: =H6*Assumptions!#REF! -> #REF! | I10: =I6*Assumptions!#REF! -> #REF! | J10: =J6*Assumptions!#REF! -> #REF! | K10: =J10*Assumptions!#REF! -> #REF! | AE10: =#REF! -> #REF! | AF10: =#REF! -> #REF! | AG10: =#REF! -> #REF! | AH10: =#REF! -> #REF! | AI10: =#REF! -> #REF! | AJ10: =#REF! -> #REF! | AK10: =#REF! -> #REF!
A11: Closing Stock | D11: =Assumptions!#REF!*D6 -> #REF! | E11: =Assumptions!#REF!*E6 -> #REF! | F11: =Assumptions!#REF!*F6 -> #REF! | G11: =Assumptions!#REF!*G6 -> #REF! | H11: =Assumptions!#REF!*H6 -> #REF! | I11: =Assumptions!#REF!*I6 -> #REF! | J11: =Assumptions!#REF!*J6 -> #REF! | K11: =Assumptions!#REF!*K6 -> #REF! | AE11: =#REF!/D6*100 -> #REF! | AF11: =#REF!/E6*100 -> #REF! | AG11: =#REF!/F6*100 -> #REF! | AH11: =#REF!/G6*100 -> #REF! | AI11: =#REF!/H6*100 -> #REF! | AJ11: =#REF!/I6*100 -> #REF! | AK11: =#REF!/J6*100 -> #REF!
A12: Opening Stock | D12: 0 | E12: =D14 -> 6.6697626e+09 | F12: =E14 -> 58500000000 | G12: =F14 -> 59085000000 | H12: =G14 -> 59675850000 | I12: =H14 -> 60272608500 | J12: =I14 -> 60875334585 | K12: =J14 -> 6.1484088e+10
A13: Purchases | D13: =D17*Assumptions!F125 -> 2.2232542e+10 | E13: =IF(AND(Assumptions!I62=0,Assumptions!I63=0),0, IF(AND(Assumptions!I62=0,Assumptions!I63>0,Assumptions!I63<7),E17*65/28,E17*65/35)) -> 2.8116812e+10 | F13: =F17*Assumptions!F125 -> 2.9467867e+10 | G13: =G17*Assumptions!F125 -> 3.0818776e+10 | H13: =H17*Assumptions!F125 -> 3.2169838e+10 | I13: =I17*Assumptions!F125 -> 3.3520908e+10 | J13: =J17*Assumptions!F125 -> 3.4871986e+10 | K13: =K17*Assumptions!F125 -> 3.6223072e+10
A14: Closing stock | D14: =MIN(D53,D55) -> 6.6697626e+09 | E14: =D54 -> 58500000000 | F14: =E14*Assumptions!F123 -> 59085000000 | G14: =F14*Assumptions!F123 -> 59675850000 | H14: =G14*Assumptions!F123 -> 60272608500 | I14: =H14*Assumptions!F123 -> 60875334585 | J14: =I14*Assumptions!F123 -> 6.1484088e+10 | K14: =J14*Assumptions!F123 -> 6.2098929e+10
E15: =IF(Assumptions!I62>0,'Workings for PL BS 1'!E54,MIN(E53,E55)) -> 58500000000
A16: Operating Expenses | D16: =D12+D13-D14 -> 15562779375 | E16: =E12+E13-E15 -> -2.3713425e+10 | F16: =F12+F13-F14 -> 2.8882867e+10 | G16: =G12+G13-G14 -> 3.0227926e+10 | H16: =H12+H13-H14 -> 3.157308e+10 | I16: =I12+I13-I14 -> 3.2918182e+10 | J16: =J12+J13-J14 -> 3.4263233e+10 | K16: =K12+K13-K14 -> 3.5608232e+10
A17: Gross profit | D17: =D19+D18 -> 11971368750 | E17: =E19+E18 -> 1.5139822e+10 | F17: =F19+F18 -> 1.5867313e+10 | G17: =G19+G18 -> 1.6594726e+10 | H17: =H19+H18 -> 17322220630 | I17: =I19+I18 -> 1.804972e+10 | J17: =J19+J18 -> 1.8777223e+10 | K17: =K19+K18 -> 1.9504731e+10
A18: Administrative and Selling Expenses | D18: =D47 -> 606650000 | E18: =E47 -> 591572000 | F18: =F47 -> 591650600 | G18: =G47 -> 591650600 | H18: =H47 -> 591733130 | I18: =I47 -> 5.9181979e+08 | J18: =J47 -> 5.9191078e+08 | K18: =K47 -> 5.9200631e+08
A19: EBDIT | D19: ='WorKings for PL BS 2'!B31 -> 11364718750 | E19: ='WorKings for PL BS 2'!C31 -> 1.454825e+10 | F19: ='WorKings for PL BS 2'!D31 -> 1.5275662e+10 | G19: ='WorKings for PL BS 2'!E31 -> 1.6003075e+10 | H19: ='WorKings for PL BS 2'!F31 -> 1.6730487e+10 | I19: ='WorKings for PL BS 2'!G31 -> 1.74579e+10 | J19: ='WorKings for PL BS 2'!H31 -> 18185312500 | K19: ='WorKings for PL BS 2'!I31 -> 18912725000
A20: Less : Depreciation | D20: ='Dep IT act'!M17*100000 -> 9.1666667e+08 | E20: ='Dep IT act'!M24*100000 -> 9.6458333e+08 | F20: ='Dep IT act'!M31*100000 -> 822187500 | G20: ='Dep IT act'!M38*100000 -> 700921875 | H20: ='Dep IT act'!M45*100000 -> 5.9763984e+08 | I20: ='Dep IT act'!M52*100000 -> 5.0966449e+08 | J20: ='Dep IT act'!M59*100000 -> 4.3471838e+08 | K20: ='Dep IT act'!M66*100000 -> 3.7086383e+08
A21: EBIT | D21: =D19-D20 -> 1.0448052e+10 | E21: =E19-E20 -> 1.3583667e+10 | F21: =F19-F20 -> 1.4453475e+10 | G21: =G19-G20 -> 1.5302153e+10 | H21: =H19-H20 -> 1.6132848e+10 | I21: =I19-I20 -> 1.6948236e+10 | J21: =J19-J20 -> 1.7750594e+10 | K21: =K19-K20 -> 1.8541861e+10 | AE21: =RATIO!C11 -> 1.7500002 | AF21: =RATIO!D11 | AG21: =RATIO!E11 -> 2.143313 | AH21: =RATIO!F11 -> 2.2837842 | AI21: =RATIO!G11 -> 2.6972292 | AJ21: =RATIO!H11 -> 3.169084 | AK21: =RATIO!I11 -> 3.2847088
A22: Less: Interest | D22: =D51 -> 5094125000 | E22: =E51 -> 5.874125e+09 | F22: =F51 -> 5.727125e+09 | G22: =G51 -> 5.60726e+09 | H22: =H51 -> 5.5028432e+09 | I22: =I51 -> 5.5088127e+09 | J22: =J51 -> 5.5363568e+09 | K22: =K51 -> 5.5640386e+09
A24: EBT | D24: =D21-D22 -> 5.3539271e+09 | E24: =E21-E22 -> 7.7095417e+09 | F24: =F21-F22 -> 8.72635e+09 | G24: =G21-G22 -> 9.6948931e+09 | H24: =H21-H22 -> 1.0630004e+10 | I24: =I21-I22 -> 1.1439423e+10 | J24: =J21-J22 -> 1.2214237e+10 | K24: =K21-K22 -> 1.2977823e+10
A26: Net Capital | D26: =D31-SUM(D27:D30) -> -1.4411215e+09 | E26: =E31-SUM(E27:E30) -> 1.1506128e+10 | F26: =F31-SUM(F27:F30) -> 3.4293305e+10 | G26: =G31-SUM(G27:G30) -> 4.0199483e+10 | H26: =H31-SUM(H27:H30) -> 4.6546552e+10 | I26: =I31-SUM(I27:I30) -> #VALUE! | J26: =J31-SUM(J27:J30) -> #VALUE! | K26: =K31-SUM(K27:K30) -> 6.5576573e+10
A27: Term Loan | D27: ='WorKings for PL BS 2'!B14 -> 4.7833333e+09 | E27: ='WorKings for PL BS 2'!C14 -> 3.3833333e+09 | F27: ='WorKings for PL BS 2'!D14 -> 1.9833333e+09 | G27: ='WorKings for PL BS 2'!E14 -> 1.2833333e+09 | H27: ='WorKings for PL BS 2'!F14 -> 5.8333333e+08 | I27: ='WorKings for PL BS 2'!G14 -> #VALUE! | J27: ='WorKings for PL BS 2'!H14 -> #VALUE! | K27: ='WorKings for PL BS 2'!I14 -> 0
A28: ='project cost'!A31 -> Working capital Loan | D28: =Assumptions!I51*100000 -> 45000000000 | E28: =Assumptions!I51*100000 -> 45000000000 | F28: =E28 -> 45000000000 | G28: =F28 -> 45000000000 | H28: =G28 -> 45000000000 | I28: =H28 -> 45000000000 | J28: =I28 -> 45000000000 | K28: =J28 -> 45000000000
A29: Short Term Loan | D29: ='WorKings for PL BS 2'!B13 -> 1400000000 | E29: ='WorKings for PL BS 2'!C13 -> 1400000000 | F29: ='WorKings for PL BS 2'!D13 -> 1400000000 | G29: ='WorKings for PL BS 2'!E13 -> 700000000 | H29: ='WorKings for PL BS 2'!F13 -> 0 | I29: ='WorKings for PL BS 2'!G13 -> 0 | J29: ='WorKings for PL BS 2'!H13 -> 0 | K29: ='WorKings for PL BS 2'!I13 -> 0
A31: Total Liabilities | D31: =D38 -> 4.9742212e+10 | E31: =E38 -> 6.1289461e+10 | F31: =F38 -> 82676638220 | G31: =G38 -> 8.7182816e+10 | H31: =H38 -> 9.2129885e+10 | I31: =I38 -> 9.8012161e+10 | J31: =J38 -> 1.0434845e+11 | K31: =K38 -> 1.1057657e+11
A33: Fixed Assets | D33: ='Dep IT act'!M18*100000 -> 6.5833333e+09 | E33: ='Dep IT act'!M25*100000 -> 5618750000 | F33: ='Dep IT act'!M32*100000 -> 4796562500 | G33: ='Dep IT act'!M39*100000 -> 4095640625 | H33: ='Dep IT act'!M46*100000 -> 3.4980008e+09 | I33: ='Dep IT act'!M53*100000 -> 2.9883363e+09 | J33: ='Dep IT act'!M60*100000 -> 2.5536179e+09 | K33: ='Dep IT act'!M67*100000 -> 2.1827541e+09
A34: Non Current Assets | D34: =Assumptions!I39 -> 0 | E34: =D34 -> 0 | F34: =E34 -> 0 | G34: =F34 -> 0 | H34: =G34 -> 0 | I34: =H34 -> 0 | J34: =I34 -> 0 | K34: =J34 -> 0
A35: =A14 -> Closing stock | D35: =D59 -> 36000000000 | E35: ='Final workings'!C9 -> 58500000000 | F35: ='Final workings'!D9 -> 59085000000 | G35: ='Final workings'!E9 -> 59675850000 | H35: ='Final workings'!F9 -> 60272610000 | I35: ='Final workings'!G9 -> 60875330000 | J35: ='Final workings'!H9 -> 61484090000 | K35: ='Final workings'!I9 -> 62098930000
A36: Recievables | D36: =D8*Assumptions!F91 -> 2.4780733e+09 | E36: =E8*Assumptions!F92 -> -8.5736031e+08 | F36: =F8*Assumptions!F93 -> 4.9225198e+09 | G36: =G8*Assumptions!F94 -> 5.6187182e+09 | H36: =H8*Assumptions!F95 -> 6.3563891e+09 | I36: =I8*Assumptions!F96 -> 7.1355063e+09 | J36: =J8*Assumptions!F97 -> 7.9560684e+09 | K36: =K8*Assumptions!F98 -> 8.8180741e+09
A37: Cash and Cash Equivalents | D37: =D8*Assumptions!F100 -> 4.6808052e+09 | E37: =E8*Assumptions!F101 -> -1.9719287e+09 | F37: =F8*Assumptions!F102 -> 1.3872556e+10 | G37: =G8*Assumptions!F103 -> 1.7792608e+10 | H37: =H8*Assumptions!F104 -> 2.2002885e+10 | I37: =I8*Assumptions!F105 -> 2.7012988e+10 | J37: =J8*Assumptions!F106 -> 3.2354678e+10 | K37: =K8*Assumptions!F107 -> 3.7476815e+10
A38: Total Assets | D38: =SUM(D33:D37) -> 4.9742212e+10 | E38: =SUM(E33:E37) -> 6.1289461e+10 | F38: =SUM(F33:F37) -> 82676638220 | G38: =SUM(G33:G37) -> 8.7182816e+10 | H38: =SUM(H33:H37) -> 9.2129885e+10 | I38: =SUM(I33:I37) -> 9.8012161e+10 | J38: =SUM(J33:J37) -> 1.0434845e+11 | K38: =SUM(K33:K37) -> 1.1057657e+11
A40: Processing fees | D40: =Assumptions!I54*Assumptions!I53*100000 -> 605340000 | E40: =Assumptions!I40*100000*Assumptions!I53 -> 590000000 | F40: =E40 -> 590000000 | G40: =F40 -> 590000000 | H40: =G40 -> 590000000 | I40: =H40 -> 590000000 | J40: =I40 -> 590000000 | K40: =J40 -> 590000000
A41: =Assumptions!C65 -> Employee Related Expenses | D41: =Assumptions!I65*Assumptions!I62 -> 1310000 | E41: =Assumptions!I65*Assumptions!I63 -> 1572000 | F41: =Assumptions!I65*Assumptions!F130*Assumptions!I71 -> 1650600 | G41: =Assumptions!I65*Assumptions!F130*Assumptions!I71 -> 1650600 | H41: =G41*Assumptions!I71 -> 1733130 | I41: =H41*Assumptions!I71 -> 1819786.5 | J41: =I41*Assumptions!I71 -> 1910775.8 | K41: =J41*Assumptions!I71 -> 2006314.6
A42: =Assumptions!C66 -> Administrative & Office Expenses | D42: =Assumptions!I66*Assumptions!I62 -> 0 | E42: =Assumptions!I66*Assumptions!I63 -> 0 | F42: =Assumptions!I66*Assumptions!F130*Assumptions!I72 -> 0 | G42: =Assumptions!I66*Assumptions!F130*Assumptions!I72 -> 0 | H42: =G42*Assumptions!I72 -> 0 | I42: =H42*Assumptions!I72 -> 0 | J42: =I42*Assumptions!I72 -> 0 | K42: =J42*Assumptions!I72 -> 0
A43: =Assumptions!C67 -> Selling and Distribution Expenses | D43: =Assumptions!I67*Assumptions!I62 -> 0 | E43: =Assumptions!I67*Assumptions!I63 -> 0 | F43: =Assumptions!I67*Assumptions!F130*Assumptions!I73 -> 0 | G43: =F43*Assumptions!I73 -> 0 | H43: =G43*Assumptions!I73 -> 0 | I43: =H43*Assumptions!I73 -> 0 | J43: =I43*Assumptions!I73 -> 0 | K43: =J43*Assumptions!I73 -> 0
A44: =Assumptions!C68 -> General Overheads | D44: =Assumptions!I68*Assumptions!I62 -> 0 | E44: =Assumptions!I68*Assumptions!I63 -> 0 | F44: =Assumptions!I68*Assumptions!F130*Assumptions!I74 -> 0 | G44: =Assumptions!I68*Assumptions!F130*Assumptions!I74 -> 0 | H44: =G44*Assumptions!I74 -> 0 | I44: =H44*Assumptions!I74 -> 0 | J44: =I44*Assumptions!I74 -> 0 | K44: =J44*Assumptions!I74 -> 0
A45: =Assumptions!C69 -> Miscellaneous Expenses | D45: =Assumptions!I69*Assumptions!I62 -> 0 | E45: =Assumptions!I69*Assumptions!I63 -> 0 | F45: =Assumptions!I69*Assumptions!F130 -> 0 | G45: =Assumptions!I69*Assumptions!F130*Assumptions!I75 -> 0 | H45: =G45*Assumptions!I75 -> 0 | I45: =H45*Assumptions!I75 -> 0 | J45: =I45*Assumptions!I75 -> 0 | K45: =J45*Assumptions!I75 -> 0
A47: Total Selling & Adminstrative expenses | D47: =SUM(D40:D46) -> 606650000 | E47: =SUM(E40:E46) -> 591572000 | F47: =SUM(F40:F46) -> 591650600 | G47: =SUM(G40:G46) -> 591650600 | H47: =SUM(H40:H46) -> 591733130 | I47: =SUM(I40:I46) -> 5.9181979e+08 | J47: =SUM(J40:J46) -> 5.9191078e+08 | K47: =SUM(K40:K46) -> 5.9200631e+08
A49: Interest on Term Loan | D49: =SUM('Loan sch'!E24:E35) -> 5.94125e+08 | E49: =SUM('Loan sch'!E36:E47) -> 4.47125e+08 | F49: =SUM('Loan sch'!E48:E59) -> 3.00125e+08 | G49: =SUM('Loan sch'!E60:E71) -> 1.53125e+08 | H49: =SUM('Loan sch'!E72:E83) -> 21437500 | I49: =SUM('Loan sch'!E84:E95) -> 0 | J49: =SUM('Loan sch'!E96:E107) -> 0 | K49: =SUM('Loan sch'!E108:E119) -> 0
A50: Interest on CC Loan | D50: =D28*Assumptions!I52*Assumptions!I62/Assumptions!F130 -> 4500000000 | E50: =E28*Assumptions!I52*Assumptions!I63/Assumptions!F130*Assumptions!F120 -> 5.427e+09 | F50: =IF(E50=0,Assumptions!I51*100000*Assumptions!I52,Assumptions!I51*100000*Assumptions!I52*Assumptions!F127) -> 5.427e+09 | G50: =F50*Assumptions!F127 -> 5.454135e+09 | H50: =G50*Assumptions!F127 -> 5.4814057e+09 | I50: =H50*Assumptions!F127 -> 5.5088127e+09 | J50: =I50*Assumptions!F127 -> 5.5363568e+09 | K50: =J50*Assumptions!F127 -> 5.5640386e+09
...

Sheet WorKings for PL BS 2
A2: Back ground calculation (Not to be visible to customer)
A3: STEP 2: Calculation of Interest,Repayment Schedule,Loan Outstanding , Depreciation Schedule
A4: Particulars | B4: =Assumptions!I78 -> 2024-25 | C4: =Assumptions!I79 -> 2025-26 | D4: =Assumptions!I80 -> 2026-27 | E4: =Assumptions!I81 -> 2027-28 | F4: =Assumptions!I82 -> 2028-29 | G4: =Assumptions!I83 -> 2029-30 | H4: =Assumptions!I84 -> 2030-31 | I4: =Assumptions!I85 -> 2031-32
A5: Interest on Term Loan | B5: ='Workings for PL BS 1'!D49 -> 5.94125e+08 | C5: ='Workings for PL BS 1'!E49 -> 4.47125e+08 | D5: ='Workings for PL BS 1'!F49 -> 3.00125e+08 | E5: ='Workings for PL BS 1'!G49 -> 1.53125e+08 | F5: ='Workings for PL BS 1'!H49 -> 21437500 | G5: ='Workings for PL BS 1'!I49 -> 0 | H5: ='Workings for PL BS 1'!J49 -> 0 | I5: ='Workings for PL BS 1'!K49 -> 0
A6: Interest on CC Loan | B6: ='Workings for PL BS 1'!D50 -> 4500000000 | C6: ='Workings for PL BS 1'!E50 -> 5.427e+09 | D6: ='Workings for PL BS 1'!F50 -> 5.427e+09 | E6: ='Workings for PL BS 1'!G50 -> 5.454135e+09 | F6: ='Workings for PL BS 1'!H50 -> 5.4814057e+09 | G6: ='Workings for PL BS 1'!I50 -> 5.5088127e+09 | H6: ='Workings for PL BS 1'!J50 -> 5.5363568e+09 | I6: ='Workings for PL BS 1'!K50 -> 5.5640386e+09
A7: Total Interest | B7: =SUM(B5:B6) -> 5094125000 | C7: =SUM(C5:C6) -> 5.874125e+09 | D7: =SUM(D5:D6) -> 5.727125e+09 | E7: =SUM(E5:E6) -> 5.60726e+09 | F7: =SUM(F5:F6) -> 5.5028432e+09 | G7: =SUM(G5:G6) -> 5.5088127e+09 | H7: =SUM(H5:H6) -> 5.5363568e+09 | I7: =SUM(I5:I6) -> 5.5640386e+09
A9: Please refer "Repayment Sheet"
A10: Total Principal amount Repayment | B10: =Repayment!B21 -> 1400000000 | C10: =Repayment!C21 -> 1400000000 | D10: =Repayment!D21 -> 1400000000 | E10: =Repayment!E21 -> 1400000000 | F10: =Repayment!F21 -> 700000000 | G10: =Repayment!G21 -> 0 | H10: =Repayment!H21 -> 0 | I10: =Repayment!I21 -> 0
A12: Term Loan Outstanding (Including Short term loan) | B12: ='Loan sch'!G24 -> 6.1833333e+09 | C12: ='Loan sch'!G36 -> 4.7833333e+09 | D12: ='Loan sch'!G48 -> 3.3833333e+09 | E12: ='Loan sch'!G60 -> 1.9833333e+09 | F12: ='Loan sch'!G72 -> 5.8333333e+08 | G12: ='Loan sch'!G84 | H12: ='Loan sch'!G96 | I12: ='Loan sch'!G108 -> 0
A13: Short Term Loan Oustanding | B13: =Repayment!B22 -> 1400000000 | C13: =Repayment!C22 -> 1400000000 | D13: =Repayment!D22 -> 1400000000 | E13: =Repayment!E22 -> 700000000 | F13: =Repayment!F22 -> 0 | G13: =Repayment!G22 -> 0 | H13: =Repayment!H22 -> 0 | I13: =Repayment!I22 -> 0
A14: Term Loan (Only Long Term) Outstanding | B14: =B12-B13 -> 4.7833333e+09 | C14: =C12-C13 -> 3.3833333e+09 | D14: =D12-D13 -> 1.9833333e+09 | E14: =E12-E13 -> 1.2833333e+09 | F14: =F12-F13 -> 5.8333333e+08 | G14: =G12-G13 -> #VALUE! | H14: =H12-H13 -> #VALUE! | I14: =I12-I13 -> 0
A15: CC Loan Outstanding as on | B15: =IF('PL BS'!D14>0,Assumptions!I51*100000,0) -> 45000000000 | C15: =IF('PL BS'!E14>0,Assumptions!I51*100000,0) -> 0 | D15: =IF('PL BS'!F14>0,Assumptions!I51*100000,0) -> 45000000000 | E15: =IF('PL BS'!G14>0,Assumptions!I51*100000) -> 45000000000 | F15: =IF('PL BS'!H14>0,Assumptions!I51*100000,0) -> 45000000000 | G15: =IF('PL BS'!I14>0,Assumptions!I51*100000,0) -> 45000000000 | H15: =IF('PL BS'!J14>0,Assumptions!I51*100000,0) -> 45000000000 | I15: =IF('PL BS'!K14>0,Assumptions!I51*100000,0) -> 45000000000
A18: Please refer "Dep IT Act" Sheet
A19: Total Fixed Asset Value arrived
A20: Gross Fixed Assets | B20: ='Dep IT act'!M16*100000 -> 7500000000 | C20: ='Dep IT act'!M23*100000 -> 6.5833333e+09 | D20: ='Dep IT act'!M30*100000 -> 5618750000 | E20: ='Dep IT act'!M37*100000 -> 4796562500 | F20: ='Dep IT act'!M44*100000 -> 4095640625 | G20: ='Dep IT act'!M51*100000 -> 3.4980008e+09 | H20: ='Dep IT act'!M58*100000 -> 2.9883363e+09 | I20: ='Dep IT act'!M65*100000 -> 2.5536179e+09
A21: Total Depreciation | B21: ='Dep IT act'!M17*100000 -> 9.1666667e+08 | C21: ='Dep IT act'!M24*100000 -> 9.6458333e+08 | D21: ='Dep IT act'!M31*100000 -> 822187500 | E21: ='Dep IT act'!M38*100000 -> 700921875 | F21: ='Dep IT act'!M45*100000 -> 5.9763984e+08 | G21: ='Dep IT act'!M52*100000 -> 5.0966449e+08 | H21: ='Dep IT act'!M59*100000 -> 4.3471838e+08 | I21: ='Dep IT act'!M66*100000 -> 3.7086383e+08
A22: Net Fixed Assets | B22: =B20-B21 -> 6.5833333e+09 | C22: =C20-C21 -> 5618750000 | D22: =D20-D21 -> 4796562500 | E22: =E20-E21 -> 4095640625 | F22: =F20-F21 -> 3.4980008e+09 | G22: =G20-G21 -> 2.9883363e+09 | H22: =H20-H21 -> 2.5536179e+09 | I22: =I20-I21 -> 2.1827541e+09
A25: =A10 -> Total Principal amount Repayment | B25: =B10 -> 1400000000 | C25: =C10 -> 1400000000 | D25: =D10 -> 1400000000 | E25: =E10 -> 1400000000 | F25: =F10 -> 700000000 | G25: =G10 -> 0 | H25: =H10 -> 0 | I25: =I10 -> 0
A26: =A7 -> Total Interest | B26: =B7 -> 5094125000 | C26: =C7 -> 5.874125e+09 | D26: =D7 -> 5.727125e+09 | E26: =E7 -> 5.60726e+09 | F26: =F7 -> 5.5028432e+09 | G26: =G7 -> 5.5088127e+09 | H26: =H7 -> 5.5363568e+09 | I26: =I7 -> 5.5640386e+09
A27: Total (Principal + Interest) | B27: =B26+B25 -> 6494125000 | C27: =C26+C25 -> 7.274125e+09 | D27: =D26+D25 -> 7.127125e+09 | E27: =E26+E25 -> 7.00726e+09 | F27: =F26+F25 -> 6.2028432e+09 | G27: =G26+G25 -> 5.5088127e+09 | H27: =H26+H25 -> 5.5363568e+09 | I27: =I26+I25 -> 5.5640386e+09
A28: Base value for Calculating EBDIT | B28: =B27 -> 6494125000 | C28: =C27 -> 7.274125e+09 | D28: =MAX(C27:I27) -> 7.274125e+09
A31: (Finvois Value - EBDIT ) | B31: ='Final workings'!B6*'WorKings for PL BS 2'!B28 -> 11364718750 | C31: ='Final workings'!C6*C28 -> 1.454825e+10 | D31: ='Final workings'!D6*'WorKings for PL BS 2'!D28 -> 1.5275662e+10 | E31: ='Final workings'!E6*'WorKings for PL BS 2'!D28 -> 1.6003075e+10 | F31: ='Final workings'!F6*'WorKings for PL BS 2'!D28 -> 1.6730487e+10 | G31: ='Final workings'!G6*'WorKings for PL BS 2'!D28 -> 1.74579e+10 | H31: ='Final workings'!H6*'WorKings for PL BS 2'!D28 -> 18185312500 | I31: ='Final workings'!I6*'WorKings for PL BS 2'!D28 -> 18912725000

Sheet Final workings
A3: FINANCIALS AND RATIOS AT A GLANCE
A4: ='WorKings for PL BS 2'!A4 -> Particulars | B4: =Assumptions!I78 -> 2024-25 | C4: =Assumptions!I79 -> 2025-26 | D4: =Assumptions!I80 -> 2026-27 | E4: =Assumptions!I81 -> 2027-28 | F4: =Assumptions!I82 -> 2028-29 | G4: =Assumptions!I83 -> 2029-30 | H4: =Assumptions!I84 -> 2030-31 | I4: =Assumptions!I85 -> 2031-32
A5: PROFIT AND LOSS ACCOUNT Items at a Glance:
A6: Finvois Factor (Predefined and Editable) | B6: =IF(Assumptions!I62=0,0,Assumptions!F88) -> 1.75 | C6: =IF(Assumptions!I63=0,0,Assumptions!F89) -> 2 | D6: =IF(C6=0,Assumptions!F89,C6+0.1) -> 2.1 | E6: =D6+0.1 -> 2.2 | F6: =E6+0.1 -> 2.3 | G6: =F6+0.1 -> 2.4 | H6: =G6+0.1 -> 2.5 | I6: =H6+0.1 -> 2.6
A7: Turnover (Editable) | B7: =ROUND(IF(Assumptions!I62=0,0,'Workings for PL BS 1'!D8),-4) -> 27534150000 | C7: =ROUND(IF(Assumptions!I63=0,0,'Workings for PL BS 1'!E8),-4) -> -8573600000 | D7: =ROUND('Workings for PL BS 1'!F8,-4) -> 44750180000 | E7: =ROUND('Workings for PL BS 1'!G8,-4) -> 46822650000 | F7: =ROUND('Workings for PL BS 1'!H8,-4) -> 48895300000 | G7: =ROUND('Workings for PL BS 1'!I8,-4) -> 50967900000 | H7: =ROUND('Workings for PL BS 1'!J8,-4) -> 53040460000 | I7: =ROUND('Workings for PL BS 1'!K8,-4) -> 55112960000
A8: Direct Material / Expenses (Editable) | B8: =ROUND(IF(Assumptions!I62=0,0,'Workings for PL BS 1'!D13),-4) -> 22232540000 | C8: =ROUND('Workings for PL BS 1'!E13,-4) -> 28116810000 | D8: =ROUND('Workings for PL BS 1'!D77,-4) -> 29467870000 | E8: =ROUND(IF(C8=0,'Workings for PL BS 1'!E77,'Workings for PL BS 1'!G13),-4) -> 30818780000 | F8: =ROUND('Workings for PL BS 1'!H13,-4) -> 32169840000 | G8: =ROUND('Workings for PL BS 1'!I13,-4) -> 33520910000 | H8: =ROUND('Workings for PL BS 1'!J13,-4) -> 34871990000 | I8: =ROUND('Workings for PL BS 1'!K13,-4) -> 36223070000
A9: Closing stock / Closing WIP (Editable) | B9: =ROUND(IF(Assumptions!I62=0,0,'Workings for PL BS 1'!D14),-4) -> 6669760000 | C9: =ROUND(IF(C7=0,0,'Workings for PL BS 1'!E15),-4) -> 58500000000 | D9: =ROUND(IF(C9=0,'Workings for PL BS 1'!E55,'Workings for PL BS 1'!F14),-4) -> 59085000000 | E9: =ROUND('Workings for PL BS 1'!G14,-4) -> 59675850000 | F9: =ROUND('Workings for PL BS 1'!H14,-4) -> 60272610000 | G9: =ROUND('Workings for PL BS 1'!I14,-4) -> 60875330000 | H9: =ROUND('Workings for PL BS 1'!J14,-4) -> 61484090000 | I9: =ROUND('Workings for PL BS 1'!K14,-4) -> 62098930000
A10: Employee Related Expenses (Editable) | B10: =ROUND('Workings for PL BS 1'!D41,-4) -> 1310000 | C10: =ROUND('Workings for PL BS 1'!E41,-4) -> 1570000 | D10: =ROUND('Workings for PL BS 1'!F41,-4) -> 1650000 | E10: =ROUND('Workings for PL BS 1'!G41,-4) -> 1650000 | F10: =ROUND('Workings for PL BS 1'!H41,-4) -> 1730000 | G10: =ROUND('Workings for PL BS 1'!I41,-4) -> 1820000 | H10: =ROUND('Workings for PL BS 1'!J41,-4) -> 1910000 | I10: =ROUND('Workings for PL BS 1'!K41,-4) -> 2010000
A11: Administrative & Office Expenses (Editable) | B11: =ROUND('Workings for PL BS 1'!D42,-3) -> 0 | C11: =ROUND('Workings for PL BS 1'!E42,-3) -> 0 | D11: =ROUND('Workings for PL BS 1'!F42,-3) -> 0 | E11: =ROUND('Workings for PL BS 1'!G42,-3) -> 0 | F11: =ROUND('Workings for PL BS 1'!H42,-3) -> 0 | G11: =ROUND('Workings for PL BS 1'!I42,-3) -> 0 | H11: =ROUND('Workings for PL BS 1'!J42,-3) -> 0 | I11: =ROUND('Workings for PL BS 1'!K42,-3) -> 0
A12: Selling and Distribution Expenses (Editable) | B12: =ROUND('Workings for PL BS 1'!D43,-3) -> 0 | C12: =ROUND('Workings for PL BS 1'!E43,-3) -> 0 | D12: =ROUND('Workings for PL BS 1'!F43,-3) -> 0 | E12: =ROUND('Workings for PL BS 1'!G43,-3) -> 0 | F12: =ROUND('Workings for PL BS 1'!H43,-3) -> 0 | G12: =ROUND('Workings for PL BS 1'!I43,-3) -> 0 | H12: =ROUND('Workings for PL BS 1'!J43,-3) -> 0 | I12: =ROUND('Workings for PL BS 1'!K43,-3) -> 0
A13: General Overheads (Editable) | B13: =ROUND('Workings for PL BS 1'!D44,-3) -> 0 | C13: =ROUND('Workings for PL BS 1'!E44,-3) -> 0 | D13: =ROUND('Workings for PL BS 1'!F44,-3) -> 0 | E13: =ROUND('Workings for PL BS 1'!G44,-3) -> 0 | F13: =ROUND('Workings for PL BS 1'!H44,-3) -> 0 | G13: =ROUND('Workings for PL BS 1'!I44,-3) -> 0 | H13: =ROUND('Workings for PL BS 1'!J44,-3) -> 0 | I13: =ROUND('Workings for PL BS 1'!K44,-3) -> 0
A14: Miscellaneous Expenses | B14: =ROUND('Workings for PL BS 1'!D45,-3) -> 0 | C14: =ROUND('Workings for PL BS 1'!E45,-3) -> 0 | D14: =ROUND('Workings for PL BS 1'!F45,-3) -> 0 | E14: =ROUND('Workings for PL BS 1'!G45,-3) -> 0 | F14: =ROUND('Workings for PL BS 1'!H45,-3) -> 0 | G14: =ROUND('Workings for PL BS 1'!I45,-3) -> 0 | H14: =ROUND('Workings for PL BS 1'!J45,-3) -> 0 | I14: =ROUND('Workings for PL BS 1'!K45,-3) -> 0
A15: Earnings before Tax (Not Editable since Autogenerated & Visible to customer) | B15: ='PL BS'!D41 -> 5.3539283e+09 | C15: ='PL BS'!E41 -> 7.7095517e+09 | D15: ='PL BS'!F41 -> 8726347500 | E15: ='PL BS'!G41 -> 9.6948881e+09 | F15: ='PL BS'!H41 -> 1.0630007e+10 | G15: ='PL BS'!I41 -> 1.1439413e+10 | H15: ='PL BS'!J41 -> 1.2214245e+10 | I15: ='PL BS'!K41 -> 1.2977818e+10
A16: BALANCE SHEET Items at a Glance:
A17: Net Capital Inluding Net Reserves and Surplus (Opening capital + Net Profit - Drawings) (Autogenerated , Not Editable) | B17: ='PL BS'!D54 -> 7987280000 | C17: ='PL BS'!E54 -> 1.3059807e+10 | D17: ='PL BS'!F54 -> 3.4293309e+10 | E17: ='PL BS'!G54 -> 4.0199487e+10 | F17: ='PL BS'!H54 -> 4.6546557e+10 | G17: ='PL BS'!I54 -> #VALUE! | H17: ='PL BS'!J54 -> #VALUE! | I17: ='PL BS'!K54 -> 6.5576564e+10
A18: Closing Cash and Cash Equivalents (Editable) | B18: =ROUND(IF(Assumptions!I62=0,0,'Workings for PL BS 1'!D37),-4) -> 4680810000 | C18: =ROUND(IF(Assumptions!I63=0,0,'Workings for PL BS 1'!E37),-4) -> -1971930000 | D18: =ROUND('Workings for PL BS 1'!F37,-4) -> 13872560000 | E18: =ROUND('Workings for PL BS 1'!G37,-4) -> 17792610000 | F18: =ROUND('Workings for PL BS 1'!H37,-4) -> 22002890000 | G18: =ROUND('Workings for PL BS 1'!I37,-4) -> 27012990000 | H18: =ROUND('Workings for PL BS 1'!J37,-4) -> 32354680000 | I18: =ROUND('Workings for PL BS 1'!K37,-4) -> 37476810000
A19: Recievables / Debtors (Editable) | B19: =ROUND(IF(Assumptions!I62=0,0,'Workings for PL BS 1'!D36),-4) -> 2478070000 | C19: =ROUND(IF(Assumptions!I63=0,0,'Workings for PL BS 1'!E36),-4) -> -857360000 | D19: =ROUND('Workings for PL BS 1'!F36,-4) -> 4922520000 | E19: =ROUND('Workings for PL BS 1'!G36,-4) -> 5618720000 | F19: =ROUND('Workings for PL BS 1'!H36,-4) -> 6356390000 | G19: =ROUND('Workings for PL BS 1'!I36,-4) -> 7135510000 | H19: =ROUND('Workings for PL BS 1'!J36,-4) -> 7956070000 | I19: =ROUND('Workings for PL BS 1'!K36,-4) -> 8818070000
A20: Non Current Assets (Editable) | B20: =ROUND('Workings for PL BS 1'!D34,-4) -> 0 | C20: =ROUND('Workings for PL BS 1'!E34,-4) -> 0 | D20: =ROUND('Workings for PL BS 1'!F34,-4) -> 0 | E20: =ROUND('Workings for PL BS 1'!G34,-4) -> 0 | F20: =ROUND('Workings for PL BS 1'!H34,-4) -> 0 | G20: =ROUND('Workings for PL BS 1'!I34,-4) -> 0 | H20: =ROUND('Workings for PL BS 1'!J34,-4) -> 0 | I20: =ROUND('Workings for PL BS 1'!K34,-4) -> 0
A21: CASH FLOW (Surplus / Deficiet) at a Glance:
A22: Net Surplus during the year (Not Editable but Displayed) | B22: =CFs!B45 -> 4680810000 | C22: =CFs!C45 -> -6652740000 | D22: =CFs!D45 -> 15844490000 | E22: =CFs!E45 -> 3.92005e+09 | F22: =CFs!F45 -> 4210280000 | G22: =CFs!G45 -> 5010100000 | H22: =CFs!H45 -> 5.34169e+09 | I22: =CFs!I45 -> 5.12213e+09
A24: MAXIMUM PERMISSABLE BANK FINANCE LIMIT:
A25: Method 1 - Working capital Method | B25: ='MPBF '!B28 -> 6241360000 | C25: ='MPBF '!C28 -> 40703032500 | D25: ='MPBF '!D28 -> 45000000000 | E25: ='MPBF '!E28 -> 45000000000 | F25: ='MPBF '!F28 -> 45000000000 | G25: ='MPBF '!G28 -> 45000000000 | H25: ='MPBF '!H28 -> 45000000000 | I25: ='MPBF '!I28 -> 45000000000
A26: Method 2 - Total Current Assets <ethod | B26: ='MPBF '!B53 -> 6241360000 | C26: ='MPBF '!C53 -> 4.0353033e+10 | D26: ='MPBF '!D53 -> 45000000000 | E26: ='MPBF '!E53 -> 45000000000 | F26: ='MPBF '!F53 -> 45000000000 | G26: ='MPBF '!G53 -> 45000000000 | H26: ='MPBF '!H53 -> 45000000000 | I26: ='MPBF '!I53 -> 45000000000
A27: Method 3 - Nayak Committee recommandaions | B27: =Nayak!B23 -> 5506830000 | C27: =Nayak!C23 -> -1714720000 | D27: =Nayak!D23 -> 8950036000 | E27: =Nayak!E23 -> 9364530000 | F27: =Nayak!F23 -> 9779060000 | G27: =Nayak!G23 -> 10193580000 | H27: =Nayak!H23 -> 10608092000 | I27: =Nayak!I23 -> 11022592000
A28: RATIO ANALYSIS at a Glance: (Auto generated and Not Editable but displayed to customer)
A29: Arrived DSCR | B29: =IF(B7=0,0,RATIO!C11) -> 1.7500002 | C29: =IF(C7=0,0,RATIO!D11) | D29: =RATIO!E11 -> 2.143313 | E29: =RATIO!F11 -> 2.2837842 | F29: =RATIO!G11 -> 2.6972292 | G29: =RATIO!H11 -> 3.169084 | H29: =RATIO!I11 -> 3.2847088 | I29: =RATIO!J11 -> 3.3990994
A30: Required DSCR Ratio | B30: =Assumptions!I76 -> 2.5
A31: Total Outside Liabilities to Total Networth | B31: =RATIO!C77 -> 1.55556 | C31: =RATIO!D77 -> 3.6929837 | D31: =RATIO!E77 -> 1.410868 | E31: =RATIO!F77 -> 1.1687545 | F31: =RATIO!G77 -> 0.97930622 | G31: =RATIO!H77 -> #VALUE! | H31: =RATIO!I77 -> #VALUE! | I31: =RATIO!J77 -> 0.68622077
A32: Gross Profit Ratio | B32: =IF(B7=0,0,RATIO!C46) -> 43.478262 | C32: =IF(C7=0,0,RATIO!D46) -> -176.58661 | D32: =RATIO!E46 -> 35.457533 | E32: =RATIO!F46 -> 35.441651 | F32: =RATIO!G46 -> 35.427168 | G32: =RATIO!H46 -> 35.413878 | H32: =RATIO!I46 -> 35.40171 | I32: =RATIO!J46 -> 35.39046
A33: Net profit ratio | B33: =IF(B7=0,0,RATIO!C54) -> 19.444684 | C33: =IF(C7=0,0,RATIO!D54) -> -89.921989 | D33: =RATIO!E54 -> 19.500139 | E33: =RATIO!F54 -> 20.705552 | F33: =RATIO!G54 -> 21.740345 | G33: =RATIO!H54 -> 22.444348 | H33: =RATIO!I54 -> 23.028165 | I33: =RATIO!J54 -> 23.547669
A34: Current Ratio | B34: =RATIO!C34 -> 1.8097093 | C34: =RATIO!D34 -> 1.2413663 | D34: =RATIO!E34 -> 1.67845 | E34: =RATIO!F34 -> 1.8181002 | F34: =RATIO!G34 -> 1.9695976 | G34: =RATIO!H34 -> 2.1116407 | H34: =RATIO!I34 -> 2.2621076 | I34: =RATIO!J34 -> 2.4087513
A35: Debtors / Recievables Turnover Ratio (Days) | B35: =IF(B7=0,0,RATIO!C68) -> 32.849954 | C35: =IF(C7=0,0,RATIO!D68) -> 36.5 | D35: =RATIO!E68 -> 40.150002 | E35: =RATIO!F68 -> 43.800016 | F35: =RATIO!G68 -> 47.450007 | G35: =RATIO!H68 -> 51.100029 | H35: =RATIO!I68 -> 54.750007 | I35: =RATIO!J68 -> 58.399976

Sheet Cover page
D6: DETAILED PROJECT REPORT
D8: OF
D10: =Assumptions!I17 -> Doe Textiles
D12: =Assumptions!I8 -> John Doe
D15: Line of Activity : | G15: =Assumptions!I15 -> Textile Manufacturing
D20: UNIT ADDRESS :
D21: =Assumptions!I16 -> 123 Industrial Area, City
D25: REQUIREMENT:
D27: Equity Capital (Margin) | H27: =Assumptions!I55 -> 62000 | I27: Lacs
D28: Term Loan | H28: =Assumptions!I43 -> 63000 | I28: Lacs
D29: Working Capital Loan | H29: =Assumptions!I51 -> 450000 | I29: =I28 -> Lacs
D30: Total Project cost | H30: =Assumptions!I56 -> 575000 | I30: Lacs
D33: PREPARED BY
D35: FINVOIS OPEN BUSINESS SOLUTIONS LLP
D36: MSME & DPR Consultants
D37: Contact No : 9618221011

Sheet Index
C5: INDEX
D7: 1 | E7: PROJECT PROFILE OVERVIEW
D9: 2 | E9: FIRM CONSTITUTION , PROPRIETOR PROFILE & BACKGROUND
D11: 3 | E11: INTRODUCTION AND FEATURES OF RAW MATERIAL AND FINISHED PRODUCT, DEMAND SUPPLY AND ITS MARKETABILITY, SWOT ANALYSIS,STATUTORY GOVERNMENT APPROVALS,POWER REQUIREMENTS.
D15: 3 | E15: PROJECT COST AND MEANS OF FINANCE
D17: 4 | E17: PROJECTED PROFIT AND LOSS ACCOUNT & BALANCE SHEET
D19: 5 | E19: RATIO ANALYSIS
D21: 6 | E21: DEPRECIATION SCHEDULE
D23: 7 | E23: TERM LOAN SCHEDULE
D25: 8 | E25: CALCULATION OF MAXIMUM PERMISSABLE BANK FINANCE LIMIT
F26: a) Method 1 - Working Capital Method
F27: b) Method 2 - Total Current Assets Method
F28: c) Method 3 - Nayak Committee Recommandation Method
D30: 9 | E30: PRINCIPAL REPAYMENT SCHEDULE
D32: 10 | E32: CASH FLOW STATEMENT
D34: 11 | E34: FUNDS FLOW STATEMENT
D36: 12 | E36: INTERNAL RATE OF RETURN (IRR)
D38: 13 | E38: MODIFIED INTERNAL RATE OF RETURN (MIRR)
D40: 14 | E40: WEIGHTED AVERAGE COST OF CAPITAL (WACC)
D42: 14 | E42: PROFITABILITY INDEX (PI)
D44: 15 | E44: NET PRESENT VALUE (NPV)
D46: 16 | E46: INVESTMENT PAYBACK PERIOD - SIMPLE METHOD & DISCOUNTED CASHFLOW METHOD
D48: 17 | E48: SENSITIVITY ANALYSIS
D50: 18 | E50: BREAK EVEN POINT (BEP) & MARGIN OF SAFETY (MOS)
D52: 19 | E52: ALTMAN Z SCORE

Sheet profile
A2: =Assumptions!I17 -> Doe Textiles
A3: =Assumptions!I8 -> John Doe
A4: =Assumptions!I16 -> 123 Industrial Area, City
A6: PROJECT PROFILE AT A GLANCE
A7: =[1]Coverpage!C9 -> Firm Name : | C7: =A2 -> Doe Textiles
A9: Name of the proprietor | B9: : | C9: =A3 -> John Doe
A11: Address Unit | B11: : | C11: =A4 -> 123 Industrial Area, City
A13: Location of Unit | C13: =Assumptions!I22 -> Urban
A15: Manufacturing / Service / Trading Concern | B15: : | C15: =Assumptions!I14 -> Manufacturing sector
A17: =[1]Coverpage!C18 -> Line of Activity : | B17: : | C17: =Assumptions!I15 -> Textile Manufacturing
A19: Constitution | B19: : | C19: =Assumptions!I7 -> Sole Proprietorship
A21: Average DSCR | B21: : | C21: =Assumptions!I76 -> 2.5
A23: =Assumptions!B24 -> Expected Employment Generation :
A24: =Assumptions!C24 -> Skilled employees | B24: : | C24: =Assumptions!I24 -> 5
A25: =Assumptions!C25 -> Semi Skilled Employees | B25: : | C25: =Assumptions!I25 -> 3
A26: =Assumptions!C26 -> Unskiled Employees | B26: : | C26: =Assumptions!I26 -> 2
A28: Gender | B28: : | C28: =Assumptions!I13 -> Male
A30: Age of Proprietor | B30: : | C30: =Assumptions!I12 -> 35
A32: Caste | B32: : | C32: =Assumptions!I21 -> OC
A34: Pan No | B34: : | C34: =Assumptions!I11 -> ABCDE1234F
A36: Adhar No | B36: : | C36: =Assumptions!I10 -> 123456789012
A38: Mobile No | B38: : | C38: =Assumptions!I9 -> 9876543210
A40: REQUIREMENT:
A42: Term Loan | B42: : | C42: =Assumptions!I43 -> 63000 | D42: ='[2]cover page'!H30 -> Lacs
A44: =[1]Coverpage!C31 -> Capital | B44: : | C44: =Assumptions!I55 -> 62000 | D44: ='[2]cover page'!H32 -> Lacs
A46: =[1]Coverpage!C32 -> Total Project cost | B46: : | C46: =Assumptions!I41 -> 575000 | D46: ='[2]cover page'!H33 -> Lacs
A50: DISCLAIMER :
A52: The views expressed in this Project Report are advisory in nature. We assume no
A53: financial liability to anyone using the content for any purpose. All the materials
A54: and content contained in Project report is for educational purpose and reflect the
A55: views of the industry which are drawn from various research material sources from
A56: internet, experts, suppliers and various other sources. The actual cost of the
A57: project or industry will have to be taken on case to case basis considering
A58: specific requirement of the project, capacity and type of plant and other specific
A59: factors/cost directly related to the implementation of project. It is intended for
A60: general guidance only and must not be considered a substitute for a competent
A61: legal advice provided by a licensed industry professional. We hereby disclaims
A62: any and all liability to any party for any direct, indirect, implied, punitive, special,
... A64: use of the Project Report Content, which is provided as is, and without warranties.

Sheet Descriptive
B2: From the above project data/profile available ,Please prepare the following
B4: √ | C4: The Constitution of the firm | F4: Must read from "profile" sheet
B5: √ | C5: Proprietors/Partners background and experience | F5: Manually enter the description | G5: (Ex:Residential address details , Previous work experience,personal Networth, etc)
B6: √ | C6: Education back ground of each partner
C8: DETAILS OF PRODUCT MANUFACTURED / FINISHED PRODUCT:
B9: √ | C9: Introduction of product being manufactured / Service | F9: Manually enter the description | G9: (Main component of Product Manufactured / Service provided) Ex:Manufacturing of food Products
F10: Manually enter the description | G10: (Sub Component) Ex: Manufacturing of Chilly powder
B11: √ | C11: Key charecteristics of product manufactured / Service
B12: √ | C12: Manufacturing capacity of the product | F12: Manually enter the description | G12: (Ex : 80 tonnes per hour/day/month)
B13: √ | C13: Flowchart of product manufactured
B14: √ | C14: SWOT Analysis of product/Service
B15: √ | C15: Competitors data
B16: √ | C16: Market trend for this product/Service
B17: √ | C17: Statutory government approvals
B18: √ | C18: Marketing Techniques applied
D19: √ | E19: Have previous experience in the same line of business
F20: Manual Enter the description | G20: Share past experience details if any (Ex: Company name ,designation,experience in years), previous successful projects done etc
D21: √ | E21: Have Purchase orders
F22: Manual Enter the description | G22: Share PO details (Ex: Purchaser details,Monthly Quantity etc)
D23: √ | E23: Will market the products through Marketing team
D24: √ | E24: Other Marketing technique
F25: Manual Enter the description | G25: (Ex: Will Market product through Marketing team or Retail stores or Wholesalers etc)
B26: √ | C26: Targeted Customers/Audience
D27: Manual Enter the description | F27: (Ex: food processing units , farmers etc)
C31: RAW MATERIALS DETAILS:( Applicable to only manufacturing units)
B32: √ | C32: Following Raw Materials required | G32: Manually enter the description | I32: (Ex:Fruits , Vegetables , wood etc)
B33: √ | C33: Quanity required | G33: Manually enter the description | I33: (Ex : 100 tonnes per day/month)
B34: √ | C34: Description regarding the Raw Materials , Demand , supply , availability nearer to your unit.
B35: √ | C35: Raw Material suppliers details | G35: Manually enter the description | I35: (Share details like Name of supplier,place of purchase etc)
B38: √ | C38: PRODUCTION CAPACITY
C39: S.No | E39: Product Name | F39: Production capacity per Annum (Specify the capacity along with units of measurement)
C40: 1 | E40: Ex:U Bolts - 20MM to 300MM | F40: (Ex:10-15Tonnes per year)
C41: 2 | E41: Ex:U Clamps - 20MM to 300MM | F41: (Ex:5-7 Tonnes per year)
C42: 3 | E42: Ex:Anchor Fastners - 8MM to 20MM
B44: √ | C44: INVENTORY / STOCK DETAILS
C45: S.No | E45: Type of Material | F45: Quanitity to be manufactured per month | G45: Quanitity to be Stored per month | H45: No of Days of Stock | I45: Justification,if any
C46: 1 | E46: Raw material | F46: (Ex:10-15Tonnes per year)
C47: 2 | E47: Finished product | F47: (Ex:5-7 Tonnes per year)
C48: 3 | E48: Ex:Anchor Fastners - 8MM to 20MM
B51: √ | C51: MANPOWER:
...

Sheet project cost
A1: =Assumptions!I17 -> Doe Textiles
A2: =Assumptions!I8 -> John Doe
A3: =Assumptions!I16 -> 123 Industrial Area, City
A6: PROJECT COST AND MEANS OF FINANCE
A8: Nature of Business : | B8: =Assumptions!I15 -> Textile Manufacturing
A11: A. COST OF THE PROJECT
C12: Rs in Lakhs
A13: Particulars | C13: Amount
A15: =Assumptions!C29 -> Service Equipment | C15: =Assumptions!I28 -> 70000
A17: =Assumptions!C40 -> Working capital Requirement | C17: =Assumptions!I40 -> 500000
A20: Total | C20: =SUM(C15:C19) -> 570000
A23: B. MEANS OF FINANCE
C24: =C12 -> Rs in Lakhs
A25: Particulars | C25: Amount
A27: Equity Capital (Margin) | C27: =C34-C31-C29 -> 57000
A29: Term Loan | C29: =Assumptions!I43 -> 63000
A31: Working capital Loan | C31: =Assumptions!I51 -> 450000
A34: Total | C34: =C20 -> 570000

Sheet PL BS
A1: =Assumptions!I17 -> Doe Textiles
A2: =Assumptions!I8 -> John Doe
A3: =Assumptions!I16 -> 123 Industrial Area, City
A5: PROFIT & LOSS ACCOUNT FOR YEAR ENDED
A6: PARTICULARS | B6: Sch | D6: =Assumptions!J78 -> Estimated | E6: =Assumptions!J79 -> Projected | F6: =Assumptions!J80 -> Projected | G6: =Assumptions!J81 -> Projected | H6: =Assumptions!J82 -> Projected | I6: =Assumptions!J83 -> Projected | J6: =Assumptions!J84 -> Projected | K6: =Assumptions!J85 -> Projected
D7: =Assumptions!I78 -> 2024-25 | E7: =Assumptions!I79 -> 2025-26 | F7: =Assumptions!I80 -> 2026-27 | G7: =Assumptions!I81 -> 2027-28 | H7: =Assumptions!I82 -> 2028-29 | I7: =Assumptions!I83 -> 2029-30 | J7: =Assumptions!I84 -> 2030-31 | K7: =Assumptions!I85 -> 2031-32
A9: Gross reciepts
A14: Gross Revenue | D14: ='Final workings'!B7 -> 27534150000 | E14: ='Final workings'!C7 -> -8573600000 | F14: ='Final workings'!D7 -> 44750180000 | G14: ='Final workings'!E7 -> 46822650000 | H14: ='Final workings'!F7 -> 48895300000 | I14: ='Final workings'!G7 -> 50967900000 | J14: ='Final workings'!H7 -> 53040460000 | K14: ='Final workings'!I7 -> 55112960000
A16: Opening Stock | D16: 0 | E16: =D18 -> #REF! | F16: =E18 -> #REF! | G16: =F18 -> #REF! | H16: =G18 -> #REF! | I16: =H18 -> #REF! | J16: =I18 -> #REF! | K16: =J18 -> #REF!
A17: Direct expenses | D17: =D11*Assumptions!#REF! -> #REF! | E17: =E11*Assumptions!#REF! -> #REF! | F17: =F11*Assumptions!#REF! -> #REF! | G17: =G11*Assumptions!#REF! -> #REF! | H17: =H11*Assumptions!#REF! -> #REF! | I17: =I11*Assumptions!#REF! -> #REF! | J17: =J11*Assumptions!#REF! -> #REF! | K17: =J17*Assumptions!#REF! -> #REF!
A18: Closing Stock | D18: =Assumptions!#REF!*D11 -> #REF! | E18: =Assumptions!#REF!*E11 -> #REF! | F18: =Assumptions!#REF!*F11 -> #REF! | G18: =Assumptions!#REF!*G11 -> #REF! | H18: =Assumptions!#REF!*H11 -> #REF! | I18: =Assumptions!#REF!*I11 -> #REF! | J18: =Assumptions!#REF!*J11 -> #REF! | K18: =Assumptions!#REF!*K11 -> #REF!
A19: Less : Cost of Goods Sold / Direct Costs
A21: Opening Stock | D21: =Assumptions!F124 -> 0 | E21: =D25 -> 6669760000 | F21: =E25 -> 58500000000 | G21: =F25 -> 59085000000 | H21: =G25 -> 59675850000 | I21: =H25 -> 60272610000 | J21: =I25 -> 60875330000 | K21: =J25 -> 61484090000
A23: Direct Material/Expenses | D23: ='Final workings'!B8 -> 22232540000 | E23: ='Final workings'!C8 -> 28116810000 | F23: ='Final workings'!D8 -> 29467870000 | G23: ='Final workings'!E8 -> 30818780000 | H23: ='Final workings'!F8 -> 32169840000 | I23: ='Final workings'!G8 -> 33520910000 | J23: ='Final workings'!H8 -> 34871990000 | K23: ='Final workings'!I8 -> 36223070000
A25: Closing stock / WIP | D25: ='Final workings'!B9 -> 6669760000 | E25: ='Final workings'!C9 -> 58500000000 | F25: ='Final workings'!D9 -> 59085000000 | G25: ='Final workings'!E9 -> 59675850000 | H25: ='Final workings'!F9 -> 60272610000 | I25: ='Final workings'!G9 -> 60875330000 | J25: ='Final workings'!H9 -> 61484090000 | K25: ='Final workings'!I9 -> 62098930000
A27: Cost of Goods Sold / Direct Costs | D27: =D21+D23-D25 -> 15562780000 | E27: =E21+E23-E25 -> -23713430000 | F27: =F21+F23-F25 -> 28882870000 | G27: =G21+G23-G25 -> 30227930000 | H27: =H21+H23-H25 -> 31573080000 | I27: =I21+I23-I25 -> 32918190000 | J27: =J21+J23-J25 -> 34263230000 | K27: =K21+K23-K25 -> 35608230000
A29: Gross profit | D29: =D14-D27 -> 11971370000 | E29: =E14-E27 -> 15139830000 | F29: =F14-F27 -> 15867310000 | G29: =G14-G27 -> 16594720000 | H29: =H14-H27 -> 17322220000 | I29: =I14-I27 -> 18049710000 | J29: =J14-J27 -> 18777230000 | K29: =K14-K27 -> 19504730000
A31: Less: Indirect Expenses | B31: Sch 1 | D31: =D106 -> 606650000 | E31: =E106 -> 591570000 | F31: =F106 -> 591650000 | G31: =G106 -> 591650000 | H31: =H106 -> 591730000 | I31: =I106 -> 591820000 | J31: =J106 -> 591910000 | K31: =K106 -> 592010000
A33: EBDIT | D33: =D29-D31 -> 11364720000 | E33: =E29-E31 -> 14548260000 | F33: =F29-F31 -> 15275660000 | G33: =G29-G31 -> 16003070000 | H33: =H29-H31 -> 16730490000 | I33: =I29-I31 -> 17457890000 | J33: =J29-J31 -> 18185320000 | K33: =K29-K31 -> 18912720000
A35: Less : Depreciation | D35: ='Dep IT act'!M17*100000 -> 9.1666667e+08 | E35: ='Dep IT act'!M24*100000 -> 9.6458333e+08 | F35: ='Dep IT act'!M31*100000 -> 822187500 | G35: ='Dep IT act'!M38*100000 -> 700921875 | H35: ='Dep IT act'!M45*100000 -> 5.9763984e+08 | I35: ='Dep IT act'!M52*100000 -> 5.0966449e+08 | J35: ='Dep IT act'!M59*100000 -> 4.3471838e+08 | K35: ='Dep IT act'!M66*100000 -> 3.7086383e+08
A37: EBIT | D37: =D33-D35 -> 1.0448053e+10 | E37: =E33-E35 -> 1.3583677e+10 | F37: =F33-F35 -> 14453472500 | G37: =G33-G35 -> 15302148125 | H37: =H33-H35 -> 1.613285e+10 | I37: =I33-I35 -> 1.6948226e+10 | J37: =J33-J35 -> 1.7750602e+10 | K37: =K33-K35 -> 1.8541856e+10
A39: Less: Interest | B39: Sch 2 | D39: =D119 -> 5094125000 | E39: =E119 -> 5.874125e+09 | F39: =F119 -> 5.727125e+09 | G39: =G119 -> 5.60726e+09 | H39: =H119 -> 5.5028432e+09 | I39: =I119 -> 5.5088127e+09 | J39: =J119 -> 5.5363568e+09 | K39: =K119 -> 5.5640386e+09
A41: Earnings before Tax (EBT) | D41: =D37-D39 -> 5.3539283e+09 | E41: =E37-E39 -> 7.7095517e+09 | F41: =F37-F39 -> 8726347500 | G41: =G37-G39 -> 9.6948881e+09 | H41: =H37-H39 -> 1.0630007e+10 | I41: =I37-I39 -> 1.1439413e+10 | J41: =J37-J39 -> 1.2214245e+10 | K41: =K37-K39 -> 1.2977818e+10
A45: =Assumptions!I17 -> Doe Textiles
A46: =Assumptions!I8 -> John Doe
A47: =Assumptions!I16 -> 123 Industrial Area, City
A49: BALANCE SHEET AS ON
A50: Particulars | B50: =B6 -> Sch | D50: =Assumptions!J78 -> Estimated | E50: =Assumptions!J79 -> Projected | F50: =Assumptions!J80 -> Projected | G50: =Assumptions!J81 -> Projected | H50: =Assumptions!J82 -> Projected | I50: =Assumptions!J83 -> Projected | J50: =Assumptions!J84 -> Projected | K50: =Assumptions!J85 -> Projected
D51: =Assumptions!I78 -> 2024-25 | E51: =Assumptions!I79 -> 2025-26 | F51: =Assumptions!I80 -> 2026-27 | G51: =Assumptions!I81 -> 2027-28 | H51: =Assumptions!I82 -> 2028-29 | I51: =Assumptions!I83 -> 2029-30 | J51: =Assumptions!I84 -> 2030-31 | K51: =Assumptions!I85 -> 2031-32
A52: SOURCES OF FUNDS:
A54: Net Capital Including Net Reserves and Surplus | D54: =D66-SUM(D57:D65) -> 7987280000 | E54: =E66-SUM(E57:E65) -> 1.3059807e+10 | F54: =F66-SUM(F57:F65) -> 3.4293309e+10 | G54: =G66-SUM(G57:G65) -> 4.0199487e+10 | H54: =H66-SUM(H57:H65) -> 4.6546557e+10 | I54: =I66-SUM(I57:I65) -> #VALUE! | J54: =J66-SUM(J57:J65) -> #VALUE! | K54: =K66-SUM(K57:K65) -> 6.5576564e+10
A56: (Opening capital + Net profit - Drawings)
A58: TERM LOANS : | D58: ='WorKings for PL BS 2'!B14 -> 4.7833333e+09 | E58: ='WorKings for PL BS 2'!C14 -> 3.3833333e+09 | F58: ='WorKings for PL BS 2'!D14 -> 1.9833333e+09 | G58: ='WorKings for PL BS 2'!E14 -> 1.2833333e+09 | H58: ='WorKings for PL BS 2'!F14 -> 5.8333333e+08 | I58: ='WorKings for PL BS 2'!G14 -> #VALUE! | J58: ='WorKings for PL BS 2'!H14 -> #VALUE! | K58: ='WorKings for PL BS 2'!I14 -> 0
A60: CURRENT LIABILITIES :
A62: ='project cost'!A31 -> Working capital Loan | D62: ='Workings for PL BS 1'!D72 -> 6241360000 | E62: ='Workings for PL BS 1'!E72 -> 43446320000 | F62: ='WorKings for PL BS 2'!D15 -> 45000000000 | G62: ='WorKings for PL BS 2'!E15 -> 45000000000 | H62: ='WorKings for PL BS 2'!F15 -> 45000000000 | I62: ='WorKings for PL BS 2'!G15 -> 45000000000 | J62: ='WorKings for PL BS 2'!H15 -> 45000000000 | K62: ='WorKings for PL BS 2'!I15 -> 45000000000
A64: Short Term Loan | D64: ='WorKings for PL BS 2'!B13 -> 1400000000 | E64: ='WorKings for PL BS 2'!C13 -> 1400000000 | F64: ='WorKings for PL BS 2'!D13 -> 1400000000 | G64: ='WorKings for PL BS 2'!E13 -> 700000000 | H64: ='WorKings for PL BS 2'!F13 -> 0 | I64: ='WorKings for PL BS 2'!G13 -> 0 | J64: ='WorKings for PL BS 2'!H13 -> 0 | K64: ='WorKings for PL BS 2'!I13 -> 0
D66: =D82 -> 2.0411973e+10 | E66: =E82 -> 61289460000 | F66: =F82 -> 82676642500 | G66: =G82 -> 87182820625 | H66: =H82 -> 9.2129891e+10 | I66: =I82 -> 9.8012166e+10 | J66: =J82 -> 1.0434846e+11 | K66: =K82 -> 1.1057656e+11
A68: APPLICATION OF FUNDS:
A70: FIXED ASSETS: | D70: ='WorKings for PL BS 2'!B22 -> 6.5833333e+09 | E70: ='WorKings for PL BS 2'!C22 -> 5618750000 | F70: ='WorKings for PL BS 2'!D22 -> 4796562500 | G70: ='WorKings for PL BS 2'!E22 -> 4095640625 | H70: ='WorKings for PL BS 2'!F22 -> 3.4980008e+09 | I70: ='WorKings for PL BS 2'!G22 -> 2.9883363e+09 | J70: ='WorKings for PL BS 2'!H22 -> 2.5536179e+09 | K70: ='WorKings for PL BS 2'!I22 -> 2.1827541e+09
A72: =IF('Final workings'!B20=0,"",NON CURRENT ASSETS) | D72: =IF('Final workings'!B20=0,"",'Final workings'!B20) | E72: =IF('Final workings'!C20=0,"",'Final workings'!C20) | F72: =IF('Final workings'!D20=0,"",'Final workings'!D20) | G72: =IF('Final workings'!E20=0,"",'Final workings'!E20) | H72: =IF('Final workings'!F20=0,"",'Final workings'!F20) | I72: =IF('Final workings'!G20=0,"",'Final workings'!G20) | J72: =IF('Final workings'!H20=0,"",'Final workings'!H20) | K72: =IF('Final workings'!I20=0,"",'Final workings'!I20)
...

Sheet RATIO
A1: =Assumptions!I17 -> Doe Textiles
A2: =Assumptions!I8 -> John Doe
A3: =Assumptions!I16 -> 123 Industrial Area, City
A5: RATIO ANALYSIS
A7: A . DEBT SERVICE COVERAGE RATIO
B8: IDEAL RATIO - 1.75 TO 3 Times
A9: Partiiculars | C9: =IF(Assumptions!I62=0,"",'Workings for PL BS 1'!D4) -> 2024-25 | D9: =IF(Assumptions!I63=0,"",Assumptions!I79) -> 2025-26 | E9: ='Workings for PL BS 1'!F4 -> 2026-27 | F9: ='Workings for PL BS 1'!G4 -> 2027-28 | G9: ='Workings for PL BS 1'!H4 -> 2028-29 | H9: ='Workings for PL BS 1'!I4 -> 2029-30 | I9: ='Workings for PL BS 1'!J4 -> 2030-31 | J9: ='Workings for PL BS 1'!K4 -> 2031-32
A11: DSCR ( A / B ) | C11: =IF('Final workings'!B7<=0,"",RATIO!C16/RATIO!C23) -> 1.7500002 | D11: =IF('Final workings'!C7<=0,"",D16/D23) | E11: =E16/E23 -> 2.143313 | F11: =F16/F23 -> 2.2837842 | G11: =G16/G23 -> 2.6972292 | H11: =H16/H23 -> 3.169084 | I11: =I16/I23 -> 3.2847088 | J11: =J16/J23 -> 3.3990994
A13: Earnings before Interest,Depreciation
A14: Interest and Installment
A16: A .Earnings Before Interest ,Depreciation | C16: ='PL BS'!D33 -> 11364720000 | D16: ='PL BS'!E33 -> 14548260000 | E16: ='PL BS'!F33 -> 15275660000 | F16: ='PL BS'!G33 -> 16003070000 | G16: ='PL BS'!H33 -> 16730490000 | H16: ='PL BS'!I33 -> 17457890000 | I16: ='PL BS'!J33 -> 18185320000 | J16: ='PL BS'!K33 -> 18912720000
A18: B .Interest and Installment
A20: Total Interest (CC & TL) | C20: ='WorKings for PL BS 2'!B7 -> 5094125000 | D20: ='WorKings for PL BS 2'!C7 -> 5.874125e+09 | E20: ='WorKings for PL BS 2'!D7 -> 5.727125e+09 | F20: ='WorKings for PL BS 2'!E7 -> 5.60726e+09 | G20: ='WorKings for PL BS 2'!F7 -> 5.5028432e+09 | H20: ='WorKings for PL BS 2'!G7 -> 5.5088127e+09 | I20: ='WorKings for PL BS 2'!H7 -> 5.5363568e+09 | J20: ='WorKings for PL BS 2'!I7 -> 5.5640386e+09
A21: Installment | C21: ='WorKings for PL BS 2'!B10 -> 1400000000 | D21: ='WorKings for PL BS 2'!C10 -> 1400000000 | E21: ='WorKings for PL BS 2'!D10 -> 1400000000 | F21: ='WorKings for PL BS 2'!E10 -> 1400000000 | G21: ='WorKings for PL BS 2'!F10 -> 700000000 | H21: ='WorKings for PL BS 2'!G10 -> 0 | I21: ='WorKings for PL BS 2'!H10 -> 0 | J21: ='WorKings for PL BS 2'!I10 -> 0
C23: =C20+C21 -> 6494125000 | D23: =D20+D21 -> 7.274125e+09 | E23: =E20+E21 -> 7.127125e+09 | F23: =F20+F21 -> 7.00726e+09 | G23: =G20+G21 -> 6.2028432e+09 | H23: =H20+H21 -> 5.5088127e+09 | I23: =I20+I21 -> 5.5363568e+09 | J23: =J20+J21 -> 5.5640386e+09
A27: NOTE : Indicates extent of current Earnings Available for meeting commitments towards interest and Instalment .
A30: B .CURRENT ASSETS RATIO
A32: Particulars | C32: =IF(Assumptions!I62=0,"",Assumptions!I78) -> 2024-25 | D32: =IF(Assumptions!I63=0,"",Assumptions!I79) -> 2025-26 | E32: =E107 -> 2026-27 | F32: =F107 -> 2027-28 | G32: =G107 -> 2028-29 | H32: =H107 -> 2029-30 | I32: =I107 -> 2030-31 | J32: =J107 -> 2031-32
A34: Current Ratio | C34: =IF(C38<=0,"",C36/C37) -> 1.8097093 | D34: =IF(D38<=0,"",D36/D37) -> 1.2413663 | E34: =E36/E37 -> 1.67845 | F34: =F36/F37 -> 1.8181002 | G34: =G36/G37 -> 1.9695976 | H34: =H36/H37 -> 2.1116407 | I34: =I36/I37 -> 2.2621076 | J34: =J36/J37 -> 2.4087513
A36: Current Assets | C36: =SUM('PL BS'!D76:D80) -> 13828640000 | D36: =SUM('PL BS'!E76:E80) -> 55670710000 | E36: =SUM('PL BS'!F76:F80) -> 77880080000 | F36: =SUM('PL BS'!G76:G80) -> 83087180000 | G36: =SUM('PL BS'!H76:H80) -> 88631890000 | H36: =SUM('PL BS'!I76:I80) -> 95023830000 | I36: =SUM('PL BS'!J76:J80) -> 101794840000 | J36: =SUM('PL BS'!K76:K80) -> 108393810000
A37: Current Liabilities | C37: =SUM('PL BS'!D62:D65) -> 7641360000 | D37: =SUM('PL BS'!E62:E65) -> 44846320000 | E37: =SUM('PL BS'!F62:F65) -> 46400000000 | F37: =SUM('PL BS'!G62:G65) -> 45700000000 | G37: =SUM('PL BS'!H62:H65) -> 45000000000 | H37: =SUM('PL BS'!I62:I65) -> 45000000000 | I37: =SUM('PL BS'!J62:J65) -> 45000000000 | J37: =SUM('PL BS'!K62:K65) -> 45000000000
A38: Net Current Assets | C38: =C36-C37 -> 6187280000 | D38: =D36-D37 -> 10824390000 | E38: =E36-E37 -> 31480080000 | F38: =F36-F37 -> 37387180000 | G38: =G36-G37 -> 43631890000 | H38: =H36-H37 -> 50023830000 | I38: =I36-I37 -> 56794840000 | J38: =J36-J37 -> 63393810000
A40: NOTE : Indicates Net Income on Average Assets .
A42: C . GROSS PROFIT RATIO
A44: Particulars | C44: =IF(Assumptions!I62=0,"",Assumptions!I78) -> 2024-25 | D44: =IF(Assumptions!I63=0,"",Assumptions!I79) -> 2025-26 | E44: =E115 -> 2026-27 | F44: =F115 -> 2027-28 | G44: =G115 -> 2028-29 | H44: =H115 -> 2029-30 | I44: =I115 -> 2030-31 | J44: =J115 -> 2031-32
A46: Gross Profit / Sales * 100 | C46: =IF('Final workings'!B7=0,"",'PL BS'!D29/'PL BS'!D14*100) -> 43.478262 | D46: =IF('Final workings'!C7=0,"",'PL BS'!E29/'PL BS'!E14*100) -> -176.58661 | E46: ='PL BS'!F29/'PL BS'!F14*100 -> 35.457533 | F46: ='PL BS'!G29/'PL BS'!G14*100 -> 35.441651 | G46: ='PL BS'!H29/'PL BS'!H14*100 -> 35.427168 | H46: ='PL BS'!I29/'PL BS'!I14*100 -> 35.413878 | I46: ='PL BS'!J29/'PL BS'!J14*100 -> 35.40171 | J46: ='PL BS'!K29/'PL BS'!K14*100 -> 35.39046
A48: NOTES : Indicates overall Profitability of the Business.
A50: D . NETPROFIT RATIO
A52: Particulars | C52: =IF(Assumptions!I62=0,"",Assumptions!I78) -> 2024-25 | D52: =IF(Assumptions!I63=0,"",Assumptions!I79) -> 2025-26 | E52: ='Workings for PL BS 1'!F4 -> 2026-27 | F52: ='Workings for PL BS 1'!G4 -> 2027-28 | G52: ='Workings for PL BS 1'!H4 -> 2028-29 | H52: ='Workings for PL BS 1'!I4 -> 2029-30 | I52: ='Workings for PL BS 1'!J4 -> 2030-31 | J52: ='Workings for PL BS 1'!K4 -> 2031-32
A54: Netprofit / Sales * 100 | C54: =IF('Final workings'!B7=0,"",'PL BS'!D41/'PL BS'!D14*100) -> 19.444684 | D54: =IF('Final workings'!C7=0,"",'PL BS'!E41/'PL BS'!E14*100) -> -89.921989 | E54: ='PL BS'!F41/'PL BS'!F14*100 -> 19.500139 | F54: ='PL BS'!G41/'PL BS'!G14*100 -> 20.705552 | G54: ='PL BS'!H41/'PL BS'!H14*100 -> 21.740345 | H54: ='PL BS'!I41/'PL BS'!I14*100 -> 22.444348 | I54: ='PL BS'!J41/'PL BS'!J14*100 -> 23.028165 | J54: ='PL BS'!K41/'PL BS'!K14*100 -> 23.547669
A56: NOTES : Indicates overall Profitability of the Business.
A59: E . DEBTORS / RECIEVABLES TURNOVER RATIO
