Workbook

Sheet Assumptions 1
C4: STEP 1 - START WITH
C6: Sector | D6: Manufacturing / Service (with stock) / Trading
C7: Business ( New / Existing) | D7: Existing
C8: Loan required | D8: Working capital Loan
C11: STEP 2
C12: If First Financial year is Selected as "Audited / Provisional"
C14: 1st Financial year | D14: Completed Financial year and audited | E14: Audited / Provisional | F14: 2024-25 | I14: Non Editable
C16: The Next financial year is selected as Estimated
C18: 2nd Financial year | D18: Next Financial year | E18: Estimated | F18: 2025-26
C21: The very Next financial year will be (Option to select how many financial years projected is required will be given)
C23: 3rd Financial year | D23: Next Financial year | E23: Projected | F23: 2026-27
C24: 4th Financial year | D24: Next Financial year | E24: Projected | F24: 2027-28
C25: 5th Financial year | D25: Next Financial year | E25: Projected | F25: 2028-29
C27: STEP 3
C28: Next fill the Means of finance,General Information.
C31: Note :
C32: Provisonal means - running financial year , but not yet audited

Sheet Assumptions.1
B2: Section | C2: Question | D2: Question Type | E2: Editable | F2: Options | G2: Min - Max | H2: Details which are required to be given by Customer | I2: Answer | J2: Particulars
B3: General Information | C3: Name of Firm | D3: Manual entry | E3: No
C4: Status of Concern | D4: Dropdown options to be provided | E4: No | F4: Soleproprietorship,Partnership,LLP,Company
C5: Proprietor / Managing Partner / Managing Director | D5: Manual entry | E5: No
C6: Firm address | D6: Manual entry | E6: No
C7: Sector | D7: Dropdown options to be provided | E7: No | F7: Manufacturing sector / Service sector (with stock) / Trading sector
C8: Nature of Business | D8: Manual entry | E8: No
B10: Means of Finance details | C10: Do you have working capital limit at present ? | D10: Dropdown options to be provided | E10: Yes | F10: Yes,No
C11: Are you going for Working capital limit Topup from present limit? | D11: Dropdown options to be provided | E11: Yes | F11: Yes,No
C12: Working capital Loan requirement | D12: Manual entry | E12: Yes | J12: Loan amount
C13: Working capital loan interest | D13: Manual entry | E13: Yes | I13: =H13/100 -> 0 | J13: per annum
C14: Processing fees (Inclusing GST) | D14: Manual entry | E14: Yes | I14: =H14/100*118/100 -> 0 | J14: of loan amount
C15: Working capital (% on Turnover) | D15: Manual entry | E15: Yes | G15: 15% or more than 15% | I15: =H15/100 -> 0 | J15: on Sales
C16: Are you going for Fresh Term Loan in the Present Financial Year | D16: Dropdown options to be provided | E16: Yes
B18: Financial Year | C18: 1st Financial year | D18: Dropdown options to be provided | E18: Yes | F18: 2024 - 25 to provide 10 years with Start Month to End Month | J18: Provisional / Audited
C19: 2nd Financial year | D19: Dropdown options to be provided | E19: Yes | F19: 2024 - 25 to provide 10 years with Start Month to End Month | J19: Estimated
C20: 3rd Financial year | D20: Dropdown options to be provided | E20: Yes | F20: 2024 - 25 to provide 10 years with Start Month to End Month | J20: Projected
C21: 4th Financial year | D21: Dropdown options to be provided | E21: Yes | F21: 2024 - 25 to provide 10 years with Start Month to End Month | J21: Projected
C22: 5th Financial year | D22: Dropdown options to be provided | E22: Yes | F22: 2024 - 25 to provide 10 years with Start Month to End Month | J22: Projected
C23: 6th Financial year | D23: Dropdown options to be provided | E23: Yes | F23: 2025 - 25 to provide 10 years with Start Month to End Month | J23: Projected
C24: 7th Financial year | D24: Dropdown options to be provided | E24: Yes | F24: 2025 - 25 to provide 10 years with Start Month to End Month | J24: Projected
C25: 2024-25
B26: Provisional or Audited | C26: Turnover | D26: Manual entry | E26: Yes
C27: Opening Stock | D27: Manual entry | E27: Yes
A28: STEP 1 | C28: Direct Material & Expenses | D28: Manual entry | E28: Yes
C29: Closing Stock | D29: Manual entry | E29: Yes
C30: Non Operating Income | D30: Manual entry | E30: Yes
C31: Electricity | D31: Manual entry | E31: Yes
C32: Depreciation | D32: Manual entry | E32: Yes
C33: Rent | D33: Manual entry | E33: Yes
C34: Salaries & Wages | D34: Manual entry | E34: Yes
C35: Processing fees (Inclusing GST) | D35: Manual entry | E35: Yes
C36: Interest on CC / OD Loan | D36: Manual entry | E36: Yes
C37: Interest on Other loans | D37: Manual entry | E37: Yes
C38: Net Profit Before Tax | D38: Manual entry | E38: Yes
C39: Office Admin, Marketing and Miscelleneous Expenses | D39: Autogenerated | E39: NA | I39: =I26+I29+I30-I27-I28-I38-I32-I36-I37-I33-I34-I35 -> 0
C40: Net Capital (Opening capital +Net Profit -Drawings) | D40: Manual entry | E40: Yes
C41: Term Loans (Secured and Unsecured Loans Total) | D41: Manual entry | E41: Yes
C42: CC Loan Outstanding | D42: Manual entry | E42: Yes
C43: Other Current Liabilities | D43: Manual entry | E43: Yes
...

Sheet Working for PL & BS
A3: STEP 2 : BACK GROUND CALCULATION . NOT TO BE VISIBLE TO CUSTOMER
A4: WORKINGS FOR PROFIT AND LOSS ACCOUNT
A5: PARTICULARS | C5: =Assumptions.1!J18 -> Provisional / Audited | D5: =Assumptions.1!J19 -> Estimated | E5: =Assumptions.1!J20 -> Projected | F5: =Assumptions.1!J21 -> Projected | G5: =Assumptions.1!J22 -> Projected | H5: =Assumptions.1!J23 -> Projected | I5: =Assumptions.1!J24 -> Projected
C6: =Assumptions.1!I18 -> 0 | D6: =Assumptions.1!I19 -> 0 | E6: =Assumptions.1!I20 -> 0 | F6: =Assumptions.1!I21 -> 0 | G6: =Assumptions.1!I22 -> 0 | H6: =Assumptions.1!I23 -> 0 | I6: =Assumptions.1!I24 -> 0
A8: Gross Reciepts:
A10: Turnover (A1) | C10: =Assumptions.1!I26 -> 0 | D10: =Assumptions.1!I111 -> #DIV/0! | E10: =D10*Assumptions.1!I102 -> #DIV/0! | F10: =E10*Assumptions.1!I102 -> #DIV/0! | G10: =F10*Assumptions.1!I102 -> #DIV/0! | H10: =G10*Assumptions.1!I102 -> #DIV/0! | I10: =H10*Assumptions.1!I102 -> #DIV/0!
C12: =SUM(C10:C11) -> 0 | D12: =SUM(D10:D11) -> #DIV/0! | E12: =SUM(E10:E11) -> #DIV/0! | F12: =SUM(F10:F11) -> #DIV/0! | G12: =SUM(G10:G11) -> #DIV/0! | H12: =SUM(H10:H11) -> #DIV/0! | I12: =SUM(I10:I11) -> #DIV/0!
A14: Cost of Goods Sold:
A16: Opening Stock (A) | C16: =Assumptions.1!I27 -> 0 | D16: =C18 -> 0 | E16: =D18 -> 0 | F16: =E18 -> 0 | G16: =F18 -> 0 | H16: =G18 -> 0 | I16: =H18 -> 0
A17: Direct Material & Expenses (B) | C17: =Assumptions.1!I28 -> 0 | D17: =D19-D16+D18 -> #DIV/0! | E17: =E19-E16+E18 -> #DIV/0! | F17: =F19-F16+F18 -> #DIV/0! | G17: =G19-G16+G18 -> #DIV/0! | H17: =H19-H16+H18 -> #DIV/0! | I17: =I19-I16+I18 -> #DIV/0!
A18: Closing Stock(C ) | C18: =Assumptions.1!I29 -> 0 | D18: =Assumptions.1!I115 -> 0 | E18: =D18*Assumptions.1!I106 -> 0 | F18: =E18*Assumptions.1!I106 -> 0 | G18: =F18*Assumptions.1!I106 -> 0 | H18: =G18*Assumptions.1!I106 -> 0 | I18: =H18*Assumptions.1!I106 -> 0
A19: Operating Expenses (D = A+B-C) | C19: =C16+C17-C18 -> 0 | D19: =D10-D21 -> #DIV/0! | E19: =E12-E21 -> #DIV/0! | F19: =F12-F21 -> #DIV/0! | G19: =G12-G21 -> #DIV/0! | H19: =H12-H21 -> #DIV/0! | I19: =I12-I21 -> #DIV/0!
A21: Gross Profit ( E = A1-D) | C21: =C12-C19 -> 0 | D21: =D10*Assumptions.1!I83 -> #DIV/0! | E21: =E10*Assumptions.1!I84 -> #DIV/0! | F21: =F10*Assumptions.1!I85 -> #DIV/0! | G21: =G10*Assumptions.1!I86 -> #DIV/0! | H21: =H10*Assumptions.1!I87 -> #DIV/0! | I21: =I10*Assumptions.1!I88 -> #DIV/0!
A23: Non Operating Income (F) | C23: =Assumptions.1!I30 -> 0 | D23: =C23*Assumptions.1!I104 -> 0 | E23: =D23*Assumptions.1!I104 -> 0 | F23: =E23*Assumptions.1!I104 -> 0 | G23: =F23*Assumptions.1!I104 -> 0 | H23: =G23*Assumptions.1!I104 -> 0 | I23: =H23*Assumptions.1!I104 -> 0
A25: Adm & Selling Expenses(G) | C25: =C92 -> 0 | D25: =D92 -> #DIV/0! | E25: =E92 -> #DIV/0! | F25: =F92 -> #DIV/0! | G25: =G92 -> #DIV/0! | H25: =H92 -> #DIV/0! | I25: =I92 -> #DIV/0!
A27: EBDIT(H = E+F-G) | C27: =C21+C23-C25 -> 0 | D27: =D21+D23-D25 -> #DIV/0! | E27: =E21+E23-E25 -> #DIV/0! | F27: =F21+F23-F25 -> #DIV/0! | G27: =G21+G23-G25 -> #DIV/0! | H27: =H21+H23-H25 -> #DIV/0! | I27: =I21+I23-I25 -> #DIV/0!
A29: Less : Depreciation ( I ) | C29: =Assumptions.1!I32 -> 0 | D29: ='Dep sch'!N19 -> 0 | E29: ='Dep sch'!N26 -> 0 | F29: ='Dep sch'!N33 -> 0 | G29: ='Dep sch'!N40 -> 0 | H29: ='Dep sch'!N47 -> 0 | I29: ='Dep sch'!N54 -> 0
A31: EBIT( J = H - I ) | C31: =C27-C29 -> 0 | D31: =D27-D29 -> #DIV/0! | E31: =E27-E29 -> #DIV/0! | F31: =F27-F29 -> #DIV/0! | G31: =G27-G29 -> #DIV/0! | H31: =H27-H29 -> #DIV/0! | I31: =I27-I29 -> #DIV/0!
A33: Less: Interest (K) | B33: Sch 2 | C33: =C102 -> 0 | D33: =D102 -> #DIV/0! | E33: =E102 -> #DIV/0! | F33: =F102 -> #DIV/0! | G33: =G102 -> #DIV/0! | H33: =H102 -> #DIV/0! | I33: =I102 -> #DIV/0!
A35: EBT(L = J- K ) | C35: =C31-C33 -> 0 | D35: =D31-D33 -> #DIV/0! | E35: =E31-E33 -> #DIV/0! | F35: =F31-F33 -> #DIV/0! | G35: =G31-G33 -> #DIV/0! | H35: =H31-H33 -> #DIV/0! | I35: =I31-I33 -> #DIV/0!
A44: WORKINGS FOR BALANCESHEET
A45: Particulars | C45: =C5 -> Provisional / Audited | D45: =D5 -> Estimated | E45: =E5 -> Projected | F45: =F5 -> Projected | G45: =G5 -> Projected | H45: =H5 -> Projected | I45: =I5 -> Projected
C46: =C6 -> 0 | D46: =D6 -> 0 | E46: =E6 -> 0 | F46: =F6 -> 0 | G46: =G6 -> 0 | H46: =H6 -> 0 | I46: =I6 -> 0
A47: SOURCES OF FUNDS:
A49: Net Capital | C49: =Assumptions.1!I40 -> 0 | D49: =D60-SUM(D51:D58) -> #DIV/0! | E49: =E60-SUM(E51:E58) -> #DIV/0! | F49: =F60-SUM(F51:F58) -> #DIV/0! | G49: =G60-SUM(G51:G58) -> #DIV/0! | H49: =H60-SUM(H51:H58) -> #DIV/0! | I49: =I60-SUM(I51:I58) -> #DIV/0!
A50: (Opening capital + Net profit -Drawings)
A51: TERM LOANS:
A52: Secured and Unsecured Loans | C52: =Assumptions.1!I41 -> 0 | D52: =C52-Assumptions.1!I119 -> 0 | E52: =D52-Assumptions.1!I119 -> 0 | F52: =E52-Assumptions.1!I119 -> 0 | G52: =F52-Assumptions.1!I119 -> 0 | H52: =G52-Assumptions.1!I119 -> 0 | I52: =H52-Assumptions.1!I119 -> 0
A53: New Term Loan | C53: =C119 -> 0 | D53: =D119 -> #DIV/0! | E53: =E119 -> #DIV/0! | F53: =F119 -> #DIV/0! | G53: =G119 -> #DIV/0! | H53: =H119 -> #DIV/0! | I53: =I119 -> #DIV/0!
A55: CURRENT LIABILITIES:
A56: Bank CC/OD loan | C56: =Assumptions.1!I42 -> 0 | D56: =IF(D129<D124,D129,D124) -> #DIV/0! | E56: =IF(E129<E124,E129,E124) -> #DIV/0! | F56: =IF(F129<F124,F129,F124) -> #DIV/0! | G56: =IF(G129<G124,G129,G124) -> #DIV/0! | H56: =IF(H129<H124,H129,H124) -> #DIV/0! | I56: =IF(I129<I124,I129,I124) -> #DIV/0!
A57: Other Current liabilities | C57: =Assumptions.1!I43 -> 0 | D57: 10000000 | E57: 10000000 | F57: 10000000 | G57: 10000000 | H57: 10000000 | I57: 10000000
A58: ='Repayment sch'!A22 -> Short Term Loan Outstanding | C58: =C118 -> 0 | D58: =D118 -> #DIV/0! | E58: =E118 -> #DIV/0! | F58: =F118 -> #DIV/0! | G58: =G118 -> #DIV/0! | H58: =H118 -> #DIV/0! | I58: =I118 -> #DIV/0!
C60: =SUM(C49:C58) -> 0 | D60: =D75 -> #DIV/0! | E60: =E75 -> #DIV/0! | F60: =F75 -> #DIV/0! | G60: =G75 -> #DIV/0! | H60: =H75 -> #DIV/0! | I60: =I75 -> #DIV/0!
A63: APPLICATION OF FUNDS:
A65: FIXED ASSETS: | C65: =Assumptions.1!I44 -> 0 | D65: ='Dep sch'!N20 -> 0 | E65: ='Dep sch'!N27 -> 0 | F65: ='Dep sch'!N34 -> 0 | G65: ='Dep sch'!N41 -> 0 | H65: ='Dep sch'!N48 -> 0 | I65: ='Dep sch'!N55 -> 0
A67: INVESTMENTS: | C67: =Assumptions.1!I47 -> 0 | D67: =C67 -> 0 | E67: =D67 -> 0 | F67: =E67 -> 0 | G67: =F67 -> 0 | H67: =G67 -> 0 | I67: =H67 -> 0
A69: CURRENT ASSETS:
A70: Other current Assets | C70: =Assumptions.1!I50 -> 0 | D70: 2000000 | E70: 1700000 | F70: 1500000 | G70: 1500000 | H70: 1500000 | I70: 1500000
A71: =A18 -> Closing Stock(C ) | C71: =C18 -> 0 | D71: =D18 -> 0 | E71: =E18 -> 0 | F71: =F18 -> 0 | G71: =G18 -> 0 | H71: =H18 -> 0 | I71: =I18 -> 0
...

Sheet Workings for PLBS
A1: MEDICAID LABS LLP
A2: =Assumptions.1!I5 -> 0
A3: AUTONAGAR , VIJAYAWADA - 520 007
A4: TRADING, PROFIT & LOSS ACCOUNT FOR YEAR ENDED
A5: PARTICULARS | B5: Schedules | C5: =Assumptions.1!J18 -> Provisional / Audited | D5: =Assumptions.1!J19 -> Estimated | E5: =Assumptions.1!J20 -> Projected | F5: =Assumptions.1!J21 -> Projected
C6: =Assumptions.1!I18 -> 0 | D6: =Assumptions.1!I19 -> 0 | E6: =Assumptions.1!I20 -> 0 | F6: =Assumptions.1!I21 -> 0
A8: Gross Reciepts:
A10: Turnover | C10: ='Working for PL & BS'!C10 -> 0 | D10: ='Working for PL & BS'!D10 -> #DIV/0! | E10: ='Working for PL & BS'!E10 -> #DIV/0! | F10: ='Working for PL & BS'!F10 -> #DIV/0!
C12: =SUM(C10:C11) -> 0 | D12: =SUM(D10:D11) -> #DIV/0! | E12: =SUM(E10:E11) -> #DIV/0! | F12: =SUM(F10:F11) -> #DIV/0!
A14: Cost of Goods Sold:
A16: Opening Stock | C16: ='Working for PL & BS'!C16 -> 0 | D16: ='Working for PL & BS'!D16 -> 0 | E16: ='Working for PL & BS'!E16 -> 0 | F16: ='Working for PL & BS'!F16 -> 0
A17: Direct Material & Expenses | C17: ='Working for PL & BS'!C17 -> 0 | D17: ='Working for PL & BS'!D17 -> #DIV/0! | E17: ='Working for PL & BS'!E17 -> #DIV/0! | F17: ='Working for PL & BS'!F17 -> #DIV/0!
A18: Closing Stock | C18: ='Working for PL & BS'!C18 -> 0 | D18: ='Working for PL & BS'!D18 -> 0 | E18: ='Working for PL & BS'!E18 -> 0 | F18: ='Working for PL & BS'!F18 -> 0
A19: Operating Expenses | C19: =C16+C17-C18 -> 0 | D19: =D16+D17-D18 -> #DIV/0! | E19: =E16+E17-E18 -> #DIV/0! | F19: =F16+F17-F18 -> #DIV/0!
A21: Gross Profit | C21: =C12-C19 -> 0 | D21: =D12-D19 -> #DIV/0! | E21: =E12-E19 -> #DIV/0! | F21: =F12-F19 -> #DIV/0!
A23: Non Operating Income | C23: ='Working for PL & BS'!C23 -> 0 | D23: ='Working for PL & BS'!D23 -> 0 | E23: ='Working for PL & BS'!E23 -> 0 | F23: ='Working for PL & BS'!F23 -> 0
A25: Adm & Selling Expenses | B25: Sch 1 | C25: =C89 -> 0 | D25: =D89 -> #DIV/0! | E25: =E89 -> #DIV/0! | F25: =F89 -> #DIV/0!
A27: EBDIT | C27: =C21+C23-C25 -> 0 | D27: =D21+D23-D25 -> #DIV/0! | E27: =E21+E23-E25 -> #DIV/0! | F27: =F21+F23-F25 -> #DIV/0!
A29: Less : Depreciation | C29: ='Working for PL & BS'!C29 -> 0 | D29: ='Working for PL & BS'!D29 -> 0 | E29: ='Working for PL & BS'!E29 -> 0 | F29: ='Working for PL & BS'!F29 -> 0
A31: EBIT | C31: =C27-C29 -> 0 | D31: =D27-D29 -> #DIV/0! | E31: =E27-E29 -> #DIV/0! | F31: =F27-F29 -> #DIV/0!
A33: Less: Interest | B33: Sch 2 | C33: =C99 -> 0 | D33: =D99 -> #DIV/0! | E33: =E99 -> #DIV/0! | F33: =F99 -> #DIV/0!
A35: EBT | C35: =C31-C33 -> 0 | D35: =D31-D33 -> #DIV/0! | E35: =E31-E33 -> #DIV/0! | F35: =F31-F33 -> #DIV/0!
A39: =A1 -> MEDICAID LABS LLP
A40: =A2 -> 0
A41: =A3 -> AUTONAGAR , VIJAYAWADA - 520 007
A43: BALANCE SHEET AS ON
A44: PARTICULARS | B44: Schedules | C44: =C5 -> Provisional / Audited | D44: =D5 -> Estimated | E44: =E5 -> Projected | F44: =F5 -> Projected
C45: =C6 -> 0 | D45: =D6 -> 0 | E45: =E6 -> 0 | F45: =F6 -> 0
A47: SOURCES OF FUNDS:
A49: Net Capital | C49: =C58-SUM(C51:C57) -> 0 | D49: =D58-SUM(D51:D57) -> #DIV/0! | E49: =E58-SUM(E51:E57) -> #DIV/0! | F49: =F58-SUM(F51:F57) -> #DIV/0!
A50: (Opening capital + Net profit -Drawings)
A51: TERM LOANS:
A52: Secured and Unsecured Loans | C52: ='Working for PL & BS'!C52 -> 0 | D52: ='Working for PL & BS'!D52 -> 0 | E52: ='Working for PL & BS'!E52 -> 0 | F52: ='Working for PL & BS'!F52 -> 0
A54: CURRENT LIABILITIES:
A55: Bank CC/OD loan | C55: ='Working for PL & BS'!C56 -> 0 | D55: ='Working for PL & BS'!D56 -> #DIV/0! | E55: ='Working for PL & BS'!E56 -> #DIV/0! | F55: ='Working for PL & BS'!F56 -> #DIV/0!
A56: Other current liabilities | C56: ='Working for PL & BS'!C57 -> 0 | D56: ='Working for PL & BS'!D57 -> 10000000 | E56: ='Working for PL & BS'!E57 -> 10000000 | F56: ='Working for PL & BS'!F57 -> 10000000
C58: =C73 -> 0 | D58: =D73 -> #DIV/0! | E58: =E73 -> #DIV/0! | F58: =F73 -> #DIV/0!
A61: APPLICATION OF FUNDS:
A63: FIXED ASSETS: | C63: ='Working for PL & BS'!C65 -> 0 | D63: ='Working for PL & BS'!D65 -> 0 | E63: ='Working for PL & BS'!E65 -> 0 | F63: ='Working for PL & BS'!F65 -> 0
A65: INVESTMENTS: | C65: ='Working for PL & BS'!C67 -> 0 | D65: ='Working for PL & BS'!D67 -> 0 | E65: ='Working for PL & BS'!E67 -> 0 | F65: ='Working for PL & BS'!F67 -> 0
...

Sheet Final workings
A3: STEP 5 : DISPLAY TO CUSTOMER FOR MAKING EDITING
A4: Financials and Ratios at a Glance
A5: PARTICULARS | B5: =Assumptions.1!J18 -> Provisional / Audited | C5: ='Working for PL & BS'!D5 -> Estimated | D5: ='Working for PL & BS'!E5 -> Projected | E5: ='Working for PL & BS'!F5 -> Projected | F5: ='Working for PL & BS'!G5 -> Projected | G5: ='Working for PL & BS'!H5 -> Projected | H5: ='Working for PL & BS'!I5 -> Projected
B6: =Assumptions.1!I18 -> 0 | C6: ='Working for PL & BS'!C6 -> 0 | D6: ='Working for PL & BS'!D6 -> 0 | E6: ='Working for PL & BS'!E6 -> 0 | F6: ='Working for PL & BS'!F6 -> 0 | G6: ='Working for PL & BS'!G6 -> 0 | H6: ='Working for PL & BS'!H6 -> 0
B7: Audited, Hence Not editable | C7: All Items Editable | D7: All Items Editable | E7: All Items Editable | F7: All Items Editable | G7: All Items Editable | H7: All Items Editable
A8: Profit and Loss Items at a Glance :
A9: Gross Revenue / Turnover | B9: ='Working for PL & BS'!C10 -> 0 | C9: ='Working for PL & BS'!D10 -> #DIV/0! | D9: ='Working for PL & BS'!E10 -> #DIV/0! | E9: ='Working for PL & BS'!F10 -> #DIV/0! | F9: ='Working for PL & BS'!G10 -> #DIV/0! | G9: ='Working for PL & BS'!H10 -> #DIV/0! | H9: ='Working for PL & BS'!I10 -> #DIV/0!
A10: Direct Material & Expenses | B10: ='Working for PL & BS'!C17 -> 0 | C10: ='Working for PL & BS'!D17 -> #DIV/0! | D10: ='Working for PL & BS'!E17 -> #DIV/0! | E10: ='Working for PL & BS'!F17 -> #DIV/0! | F10: ='Working for PL & BS'!G17 -> #DIV/0! | G10: ='Working for PL & BS'!H17 -> #DIV/0! | H10: ='Working for PL & BS'!I17 -> #DIV/0!
A11: Closing Stock / WIP | B11: ='Working for PL & BS'!C18 -> 0 | C11: ='Working for PL & BS'!D18 -> 0 | D11: ='Working for PL & BS'!E18 -> 0 | E11: ='Working for PL & BS'!F18 -> 0 | F11: ='Working for PL & BS'!G18 -> 0 | G11: ='Working for PL & BS'!H18 -> 0 | H11: ='Working for PL & BS'!I18 -> 0
A12: Non Operating Income | B12: ='Working for PL & BS'!C23 -> 0 | C12: ='Working for PL & BS'!D23 -> 0 | D12: ='Working for PL & BS'!E23 -> 0 | E12: ='Working for PL & BS'!F23 -> 0 | F12: ='Working for PL & BS'!G23 -> 0 | G12: ='Working for PL & BS'!H23 -> 0 | H12: ='Working for PL & BS'!I23 -> 0
A13: Electricity | B13: ='Working for PL & BS'!C83 -> 0 | C13: ='Working for PL & BS'!D83 -> #DIV/0! | D13: ='Working for PL & BS'!E83 -> #DIV/0! | E13: ='Working for PL & BS'!F83 -> #DIV/0! | F13: ='Working for PL & BS'!G83 -> #DIV/0! | G13: ='Working for PL & BS'!H83 -> #DIV/0! | H13: ='Working for PL & BS'!I83 -> #DIV/0!
A14: Rent | B14: ='Working for PL & BS'!C84 -> 0 | C14: ='Working for PL & BS'!D84 -> 0 | D14: ='Working for PL & BS'!E84 -> 0 | E14: ='Working for PL & BS'!F84 -> 0 | F14: ='Working for PL & BS'!G84 -> 0 | G14: ='Working for PL & BS'!H84 -> 0 | H14: ='Working for PL & BS'!I84 -> 0
A15: Salaries & Wages | B15: ='Working for PL & BS'!C85 -> 0 | C15: ='Working for PL & BS'!D85 -> #DIV/0! | D15: ='Working for PL & BS'!E85 -> #DIV/0! | E15: ='Working for PL & BS'!F85 -> #DIV/0! | F15: ='Working for PL & BS'!G85 -> #DIV/0! | G15: ='Working for PL & BS'!H85 -> #DIV/0! | H15: ='Working for PL & BS'!I85 -> #DIV/0!
A16: Office Admin and Marketing Expenses | B16: ='Working for PL & BS'!C88 -> 0 | C16: ='Working for PL & BS'!D88 -> #DIV/0! | D16: ='Working for PL & BS'!E88 -> #DIV/0! | E16: ='Working for PL & BS'!F88 -> #DIV/0! | F16: ='Working for PL & BS'!G88 -> #DIV/0! | G16: ='Working for PL & BS'!H88 -> #DIV/0! | H16: ='Working for PL & BS'!I88 -> #DIV/0!
A17: Interest on Other loans | B17: ='Working for PL & BS'!C98 -> 0 | C17: ='Working for PL & BS'!D98 -> #DIV/0! | D17: =IF(C23=0,0,'Working for PL & BS'!E98) -> 0 | E17: =IF(D23=0,0,'Working for PL & BS'!F98) -> 0 | F17: =IF(E23=0,0,'Working for PL & BS'!G98) -> 0 | G17: =IF(F23=0,0,'Working for PL & BS'!H98) -> 0 | H17: =IF(G23=0,0,'Working for PL & BS'!I98) -> 0
A18: Interest on CC/OD | B18: ='Working for PL & BS'!C99 -> 0 | C18: ='Working for PL & BS'!D99 -> #DIV/0! | D18: ='Working for PL & BS'!E99 -> #DIV/0! | E18: ='Working for PL & BS'!F99 -> #DIV/0! | F18: ='Working for PL & BS'!G99 -> #DIV/0! | G18: ='Working for PL & BS'!H99 -> #DIV/0! | H18: ='Working for PL & BS'!I99 -> #DIV/0!
A19: ='Working for PL & BS'!A100 -> Interest on New Term loan | B19: ='Working for PL & BS'!C110 -> 0 | C19: ='Working for PL & BS'!D110 -> #DIV/0! | D19: ='Working for PL & BS'!E110 -> #DIV/0! | E19: ='Working for PL & BS'!F110 -> #DIV/0! | F19: ='Working for PL & BS'!G110 -> #DIV/0! | G19: ='Working for PL & BS'!H110 -> #DIV/0! | H19: ='Working for PL & BS'!I110 -> #DIV/0!
A20: Earnings Before Tax (Not Editable) | B20: =PLBS!C36 -> 0 | C20: =PLBS!D36 -> #DIV/0! | D20: =PLBS!E36 -> #DIV/0! | E20: =PLBS!F36 -> #DIV/0! | F20: =PLBS!G36 -> #DIV/0! | G20: =PLBS!H36 -> #DIV/0! | H20: =PLBS!I36 -> #DIV/0!
A22: BalanceSheet Items at a Glance:
A23: Existing Term Loans(Secured and Unsecured) | B23: =ROUND('Working for PL & BS'!C52,-4) -> 0 | C23: =ROUND('Working for PL & BS'!D52,-4) -> 0 | D23: =ROUND('Working for PL & BS'!E52,-4) -> 0 | E23: =ROUND('Working for PL & BS'!F52,-4) -> 0 | F23: =ROUND('Working for PL & BS'!G52,-4) -> 0 | G23: =ROUND('Working for PL & BS'!H52,-4) -> 0 | H23: =ROUND('Working for PL & BS'!I52,-4) -> 0
A24: ='Working for PL & BS'!A53 -> New Term Loan | B24: ='Working for PL & BS'!C117 -> 0 | C24: ='Working for PL & BS'!D119 -> #DIV/0! | D24: ='Working for PL & BS'!E119 -> #DIV/0! | E24: ='Working for PL & BS'!F119 -> #DIV/0! | F24: ='Working for PL & BS'!G119 -> #DIV/0! | G24: ='Working for PL & BS'!H119 -> #DIV/0! | H24: ='Working for PL & BS'!I119 -> #DIV/0!
A25: ='Working for PL & BS'!A58 -> Short Term Loan Outstanding | B25: ='Working for PL & BS'!C58 -> 0 | C25: ='Working for PL & BS'!D118 -> #DIV/0! | D25: ='Working for PL & BS'!E118 -> #DIV/0! | E25: ='Working for PL & BS'!F118 -> #DIV/0! | F25: ='Working for PL & BS'!G118 -> #DIV/0! | G25: ='Working for PL & BS'!H118 -> #DIV/0! | H25: ='Working for PL & BS'!I118 -> #DIV/0!
A26: Bank CC/OD loan | B26: ='Working for PL & BS'!C56 -> 0 | C26: ='Working for PL & BS'!D56 -> #DIV/0! | D26: ='Working for PL & BS'!E56 -> #DIV/0! | E26: ='Working for PL & BS'!F56 -> #DIV/0! | F26: ='Working for PL & BS'!G56 -> #DIV/0! | G26: ='Working for PL & BS'!H56 -> #DIV/0! | H26: ='Working for PL & BS'!I56 -> #DIV/0!
A27: Other current liabilities | B27: ='Working for PL & BS'!C57 -> 0 | C27: ='Working for PL & BS'!D57 -> 10000000 | D27: ='Working for PL & BS'!E57 -> 10000000 | E27: ='Working for PL & BS'!F57 -> 10000000 | F27: ='Working for PL & BS'!G57 -> 10000000 | G27: ='Working for PL & BS'!H57 -> 10000000 | H27: ='Working for PL & BS'!I57 -> 10000000
A28: Investments | B28: ='Working for PL & BS'!C67 -> 0 | C28: ='Working for PL & BS'!D67 -> 0 | D28: ='Working for PL & BS'!E67 -> 0 | E28: ='Working for PL & BS'!F67 -> 0 | F28: ='Working for PL & BS'!G67 -> 0 | G28: ='Working for PL & BS'!H67 -> 0 | H28: ='Working for PL & BS'!I67 -> 0
A29: Other current Assets | B29: ='Working for PL & BS'!C70 -> 0 | C29: ='Working for PL & BS'!D70 -> 2000000 | D29: ='Working for PL & BS'!E70 -> 1700000 | E29: ='Working for PL & BS'!F70 -> 1500000 | F29: ='Working for PL & BS'!G70 -> 1500000 | G29: ='Working for PL & BS'!H70 -> 1500000 | H29: ='Working for PL & BS'!I70 -> 1500000
A30: Debtors | B30: ='Working for PL & BS'!C72 -> 0 | C30: ='Working for PL & BS'!D72 -> #DIV/0! | D30: ='Working for PL & BS'!E72 -> #DIV/0! | E30: ='Working for PL & BS'!F72 -> #DIV/0! | F30: ='Working for PL & BS'!G72 -> #DIV/0! | G30: ='Working for PL & BS'!H72 -> #DIV/0! | H30: ='Working for PL & BS'!I72 -> #DIV/0!
A31: Cash and Cash Equivalents | B31: ='Working for PL & BS'!C73 -> 0 | C31: ='Working for PL & BS'!D73 -> #DIV/0! | D31: ='Working for PL & BS'!E73 -> #DIV/0! | E31: ='Working for PL & BS'!F73 -> #DIV/0! | F31: ='Working for PL & BS'!G73 -> #DIV/0! | G31: ='Working for PL & BS'!H73 -> #DIV/0! | H31: ='Working for PL & BS'!I73 -> #DIV/0!
A33: RATIO ANALYSIS at a Glance: (Not Editable but displayed)
A34: Gross profit ratio (%) | B34: =RATIO!C42 -> #DIV/0! | C34: =RATIO!D42 -> #DIV/0! | D34: =RATIO!E42 -> #DIV/0! | E34: =RATIO!F42 -> #DIV/0! | F34: =RATIO!G42 -> #DIV/0! | G34: =RATIO!H42 -> #DIV/0! | H34: =RATIO!I42 -> #DIV/0!
A35: Net Profit Ratio (%) | B35: =RATIO!C50 -> #DIV/0! | C35: =RATIO!D50 -> #DIV/0! | D35: =RATIO!E50 -> #DIV/0! | E35: =RATIO!F50 -> #DIV/0! | F35: =RATIO!G50 -> #DIV/0! | G35: =RATIO!H50 -> #DIV/0! | H35: =RATIO!I50 -> #DIV/0!
A36: Debtors Turonver Ratio (Days) | B36: =RATIO!C84 -> #DIV/0! | C36: =RATIO!D84 -> #DIV/0! | D36: =RATIO!E84 -> #DIV/0! | E36: =RATIO!F84 -> #DIV/0! | F36: =RATIO!G84 -> #DIV/0! | G36: =RATIO!H84 -> #DIV/0! | H36: =RATIO!I84 -> #DIV/0!
A37: Current Ratio | B37: =RATIO!C31 -> #DIV/0! | C37: =RATIO!D31 -> #DIV/0! | D37: =RATIO!E31 -> #DIV/0! | E37: =RATIO!F31 -> #DIV/0! | F37: =RATIO!G31 -> #DIV/0! | G37: =RATIO!H31 -> #DIV/0! | H37: =RATIO!I31 -> #DIV/0!
A38: Total outside Liabilities to Total Networth | B38: =RATIO!C58 -> #DIV/0! | C38: =RATIO!D58 -> #DIV/0! | D38: =RATIO!E58 -> #DIV/0! | E38: =RATIO!F58 -> #DIV/0! | F38: =RATIO!G58 -> #DIV/0! | G38: =RATIO!H58 -> #DIV/0! | H38: =RATIO!I58 -> #DIV/0!
A40: MAXIMUM PERMISSABLE BANK FINANCE:
A41: Method 1 : Working capital Method | C41: ='MPBF '!B28 -> #DIV/0! | D41: ='MPBF '!C28 -> #DIV/0! | E41: ='MPBF '!D28 -> #DIV/0! | F41: ='MPBF '!E28 -> #DIV/0! | G41: ='MPBF '!F28 -> #DIV/0! | H41: ='MPBF '!G28 -> #DIV/0!
A42: Method 1 : Current Assets Method | C42: ='MPBF '!B52 -> #DIV/0! | D42: ='MPBF '!C52 -> #DIV/0! | E42: ='MPBF '!D52 -> #DIV/0! | F42: ='MPBF '!E52 -> #DIV/0! | G42: ='MPBF '!F52 -> #DIV/0! | H42: ='MPBF '!G52 -> #DIV/0!
A43: Method 3 : Nayak Committee | C43: =nayak!C23 -> #DIV/0! | D43: =nayak!D23 -> #DIV/0! | E43: =nayak!E23 -> #DIV/0! | F43: =nayak!F23 -> #DIV/0! | G43: =nayak!G23 -> #DIV/0! | H43: =nayak!H23 -> #DIV/0!

Sheet cover page
D6: PROJECTIONS AND ESTIMATIONS
E8: OF
D9: =Assumptions.1!I3 -> 0
D12: =Assumptions.1!I5 -> 0
D16: =Assumptions.1!I8 -> 0
D20: =Assumptions.1!I6 -> 0
D24: Working capital Loan | H24: =Assumptions.1!I12 -> 0
D25: Term Loan | H25: =Assumptions.1!I64*100000 -> 0
D28: PREPARED BY
D30: FINVOIS OPEN BUSINESS SOLUTIONS LLP
D31: MSME & DPR Consultants
D32: Contact : 9618221011

Sheet PLBS
A1: =Assumptions.1!I3 -> 0
A2: =Assumptions.1!I5 -> 0
A3: =Assumptions.1!I6 -> 0
A4: TRADING, PROFIT & LOSS ACCOUNT FOR YEAR ENDED
A5: PARTICULARS | B5: Schedules | C5: =Assumptions.1!J18 -> Provisional / Audited | D5: =Assumptions.1!J19 -> Estimated | E5: =Assumptions.1!J20 -> Projected | F5: =Assumptions.1!J21 -> Projected | G5: =Assumptions.1!J23 -> Projected | H5: =Assumptions.1!J24 -> Projected | I5: =Assumptions.1!J24 -> Projected
C6: =Assumptions.1!I18 -> 0 | D6: ='Assumptions 1'!F18 -> 2025-26 | E6: =Assumptions.1!I20 -> 0 | F6: =Assumptions.1!I21 -> 0 | G6: 2028-29 | H6: 2029-30 | I6: =Assumptions.1!I24 -> 0
A9: Gross Revenue / Turnover:
A11: Revenue | C11: ='Working for PL & BS'!C10 -> 0 | D11: =ROUND('Final workings'!C9,-4) -> #DIV/0! | E11: =ROUND('Final workings'!D9,-4) -> #DIV/0! | F11: =ROUND('Final workings'!E9,-4) -> #DIV/0! | G11: =ROUND('Final workings'!F9,-4) -> #DIV/0! | H11: =ROUND('Final workings'!G9,-4) -> #DIV/0! | I11: =ROUND('Final workings'!H9,-4) -> #DIV/0!
C13: =SUM(C11:C12) -> 0 | D13: =SUM(D11:D12) -> #DIV/0! | E13: =SUM(E11:E12) -> #DIV/0! | F13: =SUM(F11:F12) -> #DIV/0! | G13: =SUM(G11:G12) -> #DIV/0! | H13: =SUM(H11:H12) -> #DIV/0! | I13: =SUM(I11:I12) -> #DIV/0!
A15: Cost of Goods Sold:
A17: Opening Stock | C17: ='Working for PL & BS'!C16 -> 0 | D17: =C19 -> 0 | E17: =D19 -> 0 | F17: =E19 -> 0 | G17: =F19 -> 0 | H17: =G19 -> 0 | I17: =H19 -> 0
A18: Direct Material & Expenses | C18: ='Working for PL & BS'!C17 -> 0 | D18: =ROUND('Final workings'!C10,-4) -> #DIV/0! | E18: =ROUND('Final workings'!D10,-4) -> #DIV/0! | F18: =ROUND('Final workings'!E10,-4) -> #DIV/0! | G18: =ROUND('Final workings'!F10,-4) -> #DIV/0! | H18: =ROUND('Final workings'!G10,-4) -> #DIV/0! | I18: =ROUND('Final workings'!H10,-4) -> #DIV/0!
A19: Closing Stock / WIP | C19: ='Working for PL & BS'!C18 -> 0 | D19: =ROUND('Final workings'!C11,-3) -> 0 | E19: =ROUND('Final workings'!D11,-3) -> 0 | F19: =ROUND('Final workings'!E11,-3) -> 0 | G19: =ROUND('Final workings'!F11,-3) -> 0 | H19: =ROUND('Final workings'!G11,-3) -> 0 | I19: =ROUND('Final workings'!H11,-3) -> 0
A20: Operating Expenses | C20: =C17+C18-C19 -> 0 | D20: =D17+D18-D19 -> #DIV/0! | E20: =E17+E18-E19 -> #DIV/0! | F20: =F17+F18-F19 -> #DIV/0! | G20: =G17+G18-G19 -> #DIV/0! | H20: =H17+H18-H19 -> #DIV/0! | I20: =I17+I18-I19 -> #DIV/0!
A22: Gross Profit | C22: =C13-C20 -> 0 | D22: =D13-D20 -> #DIV/0! | E22: =E13-E20 -> #DIV/0! | F22: =F13-F20 -> #DIV/0! | G22: =G13-G20 -> #DIV/0! | H22: =H13-H20 -> #DIV/0! | I22: =I13-I20 -> #DIV/0!
A24: Non Operating Income | C24: ='Working for PL & BS'!C23 -> 0 | D24: =ROUND('Final workings'!C12,-3) -> 0 | E24: =ROUND('Final workings'!D12,-3) -> 0 | F24: =ROUND('Final workings'!E12,-3) -> 0 | G24: =ROUND('Final workings'!F12,-3) -> 0 | H24: =ROUND('Final workings'!G12,-3) -> 0 | I24: =ROUND('Final workings'!H12,-3) -> 0
A26: Less :Admintrative & Selling Expenses | B26: Sch 1 | C26: =C90 -> 0 | D26: =D90 -> #DIV/0! | E26: =E90 -> #DIV/0! | F26: =F90 -> #DIV/0! | G26: =G90 -> #DIV/0! | H26: =H90 -> #DIV/0! | I26: =I90 -> #DIV/0!
A28: EBDIT | C28: =C22+C24-C26 -> 0 | D28: =D22+D24-D26 -> #DIV/0! | E28: =E22+E24-E26 -> #DIV/0! | F28: =F22+F24-F26 -> #DIV/0! | G28: =G22+G24-G26 -> #DIV/0! | H28: =H22+H24-H26 -> #DIV/0! | I28: =I22+I24-I26 -> #DIV/0!
A30: Less : Depreciation | C30: ='Working for PL & BS'!C29 -> 0 | D30: ='Working for PL & BS'!D29 -> 0 | E30: ='Working for PL & BS'!E29 -> 0 | F30: ='Working for PL & BS'!F29 -> 0 | G30: ='Working for PL & BS'!G29 -> 0 | H30: ='Working for PL & BS'!H29 -> 0 | I30: ='Working for PL & BS'!I29 -> 0
A32: EBIT | C32: =C28-C30 -> 0 | D32: =D28-D30 -> #DIV/0! | E32: =E28-E30 -> #DIV/0! | F32: =F28-F30 -> #DIV/0! | G32: =G28-G30 -> #DIV/0! | H32: =H28-H30 -> #DIV/0! | I32: =I28-I30 -> #DIV/0!
A34: Less: Interest | B34: Sch 2 | C34: =C99 -> 0 | D34: =D99 -> #DIV/0! | E34: =E99 -> #DIV/0! | F34: =F99 -> #DIV/0! | G34: =G99 -> #DIV/0! | H34: =H99 -> #DIV/0! | I34: =I99 -> #DIV/0!
A36: EBT | C36: =C32-C34 -> 0 | D36: =D32-D34 -> #DIV/0! | E36: =E32-E34 -> #DIV/0! | F36: =F32-F34 -> #DIV/0! | G36: =G32-G34 -> #DIV/0! | H36: =H32-H34 -> #DIV/0! | I36: =I32-I34 -> #DIV/0!
A40: =A1 -> 0
A41: =A2 -> 0
A42: =A3 -> 0
A44: BALANCE SHEET AS ON
A45: PARTICULARS | B45: Schedules | C45: =C5 -> Provisional / Audited | D45: =D5 -> Estimated | E45: =E5 -> Projected | F45: =F5 -> Projected | G45: =G5 -> Projected | H45: =Assumptions.1!J24 -> Projected | I45: =Assumptions.1!J24 -> Projected
C46: =C6 -> 0 | D46: =D6 -> 2025-26 | E46: =E6 -> 0 | F46: =F6 -> 0 | G46: =G6 -> 2028-29 | H46: =Assumptions.1!I24 -> 0 | I46: =Assumptions.1!I24 -> 0
A48: SOURCES OF FUNDS:
A50: Net Capital Including Net Reserves & Surplus | C50: =C60-SUM(C52:C59) -> 0 | D50: =D60-SUM(D52:D59) -> #DIV/0! | E50: =E60-SUM(E52:E59) -> #DIV/0! | F50: =F60-SUM(F52:F59) -> #DIV/0! | G50: =G60-SUM(G52:G59) -> #DIV/0! | H50: =H60-SUM(H52:H59) -> #DIV/0! | I50: =I60-SUM(I52:I59) -> #DIV/0!
A51: (Opening capital + Net profit -Drawings)
A52: TERM LOANS:
A53: Secured and Unsecured Loans(Existing) | C53: ='Final workings'!B23 -> 0 | D53: =ROUND('Final workings'!C23,-4) -> 0 | E53: =ROUND('Final workings'!D23,-4) -> 0 | F53: =ROUND('Final workings'!E23,-4) -> 0 | G53: =ROUND('Final workings'!F23,-4) -> 0 | H53: =ROUND('Final workings'!G23,-4) -> 0 | I53: =ROUND('Final workings'!H23,-4) -> 0
A54: ='Final workings'!A24 -> New Term Loan | C54: ='Final workings'!B24 -> 0 | D54: ='Final workings'!C24 -> #DIV/0! | E54: ='Final workings'!D24 -> #DIV/0! | F54: ='Final workings'!E24 -> #DIV/0! | G54: ='Final workings'!F24 -> #DIV/0! | H54: ='Final workings'!G24 -> #DIV/0! | I54: ='Final workings'!H24 -> #DIV/0!
A56: CURRENT LIABILITIES:
A57: Bank CC/OD loan | C57: =Assumptions.1!I42 -> 0 | D57: =Assumptions.1!I12 -> 0 | E57: =Assumptions.1!I12 -> 0 | F57: =Assumptions.1!I12 -> 0 | G57: =Assumptions.1!I12 -> 0 | H57: =Assumptions.1!I12 -> 0 | I57: =Assumptions.1!I12 -> 0
A58: Other Current liabilities | C58: ='Final workings'!B27 -> 0 | D58: ='Final workings'!C27 -> 10000000 | E58: ='Final workings'!D27 -> 10000000 | F58: ='Final workings'!E27 -> 10000000 | G58: ='Final workings'!F27 -> 10000000 | H58: ='Final workings'!G27 -> 10000000 | I58: ='Final workings'!H27 -> 10000000
A59: ='Working for PL & BS'!A58 -> Short Term Loan Outstanding | C59: ='Final workings'!B25 -> 0 | D59: ='Final workings'!C25 -> #DIV/0! | E59: ='Final workings'!D25 -> #DIV/0! | F59: ='Final workings'!E25 -> #DIV/0! | G59: ='Final workings'!F25 -> #DIV/0! | H59: ='Final workings'!G25 -> #DIV/0! | I59: ='Final workings'!H25 -> #DIV/0!
C60: =C74 -> 0 | D60: =D74 -> #DIV/0! | E60: =E74 -> #DIV/0! | F60: =F74 -> #DIV/0! | G60: =G74 -> #DIV/0! | H60: =H74 -> #DIV/0! | I60: =I74 -> #DIV/0!
A62: APPLICATION OF FUNDS:
...

Sheet RATIO
A1: =Assumptions.1!I3 -> 0
A2: =Assumptions.1!I5 -> 0
A3: =Assumptions.1!I6 -> 0
A5: RATIO ANALYSIS
A7: A . DEBT SERVICE COVERAGE RATIO
B8: IDEAL RATIO - 1.75 TO 3 Times
A9: Partiiculars | D9: =Assumptions.1!I19 -> 0 | E9: =Assumptions.1!I20 -> 0 | F9: =Assumptions.1!I21 -> 0 | G9: =Assumptions.1!I22 -> 0 | H9: =Assumptions.1!I23 -> 0 | I9: =Assumptions.1!I24 -> 0
A11: DSCR ( A / B ) | D11: =D16/D23 -> #DIV/0! | E11: =E16/E23 -> #DIV/0! | F11: =F16/F23 -> #DIV/0! | G11: =G16/G23 -> #DIV/0! | H11: =H16/H23 -> #DIV/0! | I11: =I16/I23 -> #DIV/0!
A13: Earnings before Interest,Depreciation
A14: Interest and Installment
A16: A .Earnings Before Interest ,Depreciation | D16: =PLBS!D28 -> #DIV/0! | E16: =PLBS!E28 -> #DIV/0! | F16: =PLBS!F28 -> #DIV/0! | G16: =PLBS!G28 -> #DIV/0! | H16: =PLBS!H28 -> #DIV/0! | I16: =PLBS!I28 -> #DIV/0!
A18: B .Total Interest and Installment
A20: Total Interest | D20: =PLBS!D99 -> #DIV/0! | E20: =PLBS!E99 -> #DIV/0! | F20: =PLBS!F99 -> #DIV/0! | G20: =PLBS!G99 -> #DIV/0! | H20: =PLBS!H99 -> #DIV/0! | I20: =PLBS!I99 -> #DIV/0!
A21: Installment | D21: ='Repayment sch'!B21+PLBS!C53-PLBS!D53 -> #DIV/0! | E21: ='Repayment sch'!C21+PLBS!D53-PLBS!E53 -> #DIV/0! | F21: ='Repayment sch'!D21+PLBS!E53-PLBS!F53 -> #DIV/0! | G21: ='Repayment sch'!E21+PLBS!F53-PLBS!G53 -> #DIV/0! | H21: ='Repayment sch'!F21+PLBS!G53-PLBS!H53 -> #DIV/0! | I21: ='Repayment sch'!G21+PLBS!H53-PLBS!I53 -> #DIV/0!
D23: =D20+D21 -> #DIV/0! | E23: =E20+E21 -> #DIV/0! | F23: =F20+F21 -> #DIV/0! | G23: =G20+G21 -> #DIV/0! | H23: =H20+H21 -> #DIV/0! | I23: =I20+I21 -> #DIV/0!
A25: NOTE : Indicates extent of current Earnings Available for meeting commitments towards interest and Instalment .
A27: B . CURRENT RATIO
H28: IDEAL RATIO > 1.33
A29: Particulars | C29: =C91 -> 0 | D29: =D91 -> 0 | E29: =E91 -> 0 | F29: =F91 -> 0 | G29: =G91 -> 0 | H29: =H91 -> 0 | I29: =I91 -> 0
A31: Current Assets / Current Liabilities | C31: =C33/C34 -> #DIV/0! | D31: =D33/D34 -> #DIV/0! | E31: =E33/E34 -> #DIV/0! | F31: =F33/F34 -> #DIV/0! | G31: =G33/G34 -> #DIV/0! | H31: =H33/H34 -> #DIV/0! | I31: =I33/I34 -> #DIV/0!
A33: Current Assets | C33: =SUM(PLBS!C69:C72) -> 0 | D33: =SUM(PLBS!D69:D72) -> #DIV/0! | E33: =SUM(PLBS!E69:E72) -> #DIV/0! | F33: =SUM(PLBS!F69:F72) -> #DIV/0! | G33: =SUM(PLBS!G69:G72) -> #DIV/0! | H33: =SUM(PLBS!H69:H72) -> #DIV/0! | I33: =SUM(PLBS!I69:I72) -> #DIV/0!
A34: Current Liabilities | C34: =SUM(PLBS!C57:C59) -> 0 | D34: =SUM(PLBS!D57:D59) -> #DIV/0! | E34: =SUM(PLBS!E57:E59) -> #DIV/0! | F34: =SUM(PLBS!F57:F59) -> #DIV/0! | G34: =SUM(PLBS!G57:G59) -> #DIV/0! | H34: =SUM(PLBS!H57:H59) -> #DIV/0! | I34: =SUM(PLBS!I57:I59) -> #DIV/0!
A36: NOTES : Indicates Ability to repay short term commitments promptly .
A38: C . GROSS PROFIT RATIO
A40: Particulars | C40: =C100 -> 0 | D40: =D100 -> 0 | E40: =E100 -> 0 | F40: =F100 -> 0 | G40: =G100 -> 0 | H40: =H100 -> 0 | I40: =I100 -> 0
A42: Gross profit / Sales * 100 | C42: =PLBS!C22/PLBS!C11*100 -> #DIV/0! | D42: =PLBS!D22/PLBS!D11*100 -> #DIV/0! | E42: =PLBS!E22/PLBS!E11*100 -> #DIV/0! | F42: =PLBS!F22/PLBS!F11*100 -> #DIV/0! | G42: =PLBS!G22/PLBS!G11*100 -> #DIV/0! | H42: =PLBS!H22/PLBS!H11*100 -> #DIV/0! | I42: =PLBS!I22/PLBS!I11*100 -> #DIV/0!
A44: NOTES : Indicates Basic Profitability of the Business.
A46: D . NETPROFIT RATIO
A48: Particulars | C48: =C40 -> 0 | D48: =D40 -> 0 | E48: =E40 -> 0 | F48: =F40 -> 0 | G48: =G40 -> 0 | H48: =H40 -> 0 | I48: =I40 -> 0
A50: Netprofit / Sales * 100 | C50: =PLBS!C36/PLBS!C11*100 -> #DIV/0! | D50: =PLBS!D36/PLBS!D11*100 -> #DIV/0! | E50: =PLBS!E36/PLBS!E11*100 -> #DIV/0! | F50: =PLBS!F36/PLBS!F11*100 -> #DIV/0! | G50: =PLBS!G36/PLBS!G11*100 -> #DIV/0! | H50: =PLBS!H36/PLBS!H11*100 -> #DIV/0! | I50: =PLBS!I36/PLBS!I11*100 -> #DIV/0!
A52: NOTES : Indicates overall Profitability of the Business.
A54: E . TOTAL OUTSIDE LIABILITIES TO TOTAL NETWORTH RATIO :
A56: Particulars | C56: =C29 -> 0 | D56: =D29 -> 0 | E56: =E29 -> 0 | F56: =F29 -> 0 | G56: =G29 -> 0 | H56: =H29 -> 0 | I56: =I29 -> 0
A58: TOL / TW | C58: =SUM(PLBS!C52:C59)/PLBS!C50 -> #DIV/0! | D58: =SUM(PLBS!D52:D59)/PLBS!D50 -> #DIV/0! | E58: =SUM(PLBS!E52:E59)/PLBS!E50 -> #DIV/0! | F58: =SUM(PLBS!F52:F59)/PLBS!F50 -> #DIV/0! | G58: =SUM(PLBS!G52:G59)/PLBS!G50 -> #DIV/0! | H58: =SUM(PLBS!H52:H59)/PLBS!H50 -> #DIV/0! | I58: =SUM(PLBS!I52:I59)/PLBS!I50 -> #DIV/0!
A60: NOTES : Indicates Extent of own funds used in business.
A64: F . STOCK TURNOVER RATIO
A66: Particulars | C66: =C111 -> 0 | D66: =D111 -> 0 | E66: =E111 -> 0 | F66: =F111 -> 0 | G66: =G111 -> 0 | H66: =H111 -> 0 | I66: =I111 -> 0
A68: COGS | C68: =PLBS!C20 -> 0 | D68: =PLBS!D20 -> #DIV/0! | E68: =PLBS!E20 -> #DIV/0! | F68: =PLBS!F20 -> #DIV/0! | G68: =PLBS!G20 -> #DIV/0! | H68: =PLBS!H20 -> #DIV/0! | I68: =PLBS!I20 -> #DIV/0!
A69: AVERAGE STOCK | C69: =(PLBS!C17+PLBS!C19)/2 -> 0 | D69: =(PLBS!D17+PLBS!D19)/2 -> 0 | E69: =(PLBS!E17+PLBS!E19)/2 -> 0 | F69: =(PLBS!F17+PLBS!F19)/2 -> 0 | G69: =(PLBS!G17+PLBS!G19)/2 -> 0 | H69: =(PLBS!H17+PLBS!H19)/2 -> 0 | I69: =(PLBS!I17+PLBS!I19)/2 -> 0
A70: STR = (COGS / AVRG STOCK) | C70: =C68/C69 -> #DIV/0! | D70: =D68/D69 -> #DIV/0! | E70: =E68/E69 -> #DIV/0! | F70: =F68/F69 -> #DIV/0! | G70: =G68/G69 -> #DIV/0! | H70: =H68/H69 -> #DIV/0! | I70: =I68/I69 -> #DIV/0!
...

Sheet CF's
A1: ='Working for PL & BS'!A1:F1 -> 0
A2: ='Working for PL & BS'!A2:F2 -> 0
A3: ='Working for PL & BS'!A3:F3 -> STEP 2 : BACK GROUND CALCULATION . NOT TO BE VISIBLE TO CUSTOMER
A5: PROJECTED CASH FLOW STATEMENTS:
A7: Particulars | B7: ='Working for PL & BS'!#REF! -> #REF! | C7: ='Working for PL & BS'!#REF! -> #REF! | D7: ='Working for PL & BS'!#REF! -> #REF! | E7: ='Working for PL & BS'!#REF! -> #REF! | F7: ='Working for PL & BS'!#REF! -> #REF!
A9: In flows:
A12: Profit before Interest & Tax but after Depreciation
B13: ='Working for PL & BS'!C31 -> 0 | C13: ='Working for PL & BS'!#REF! -> #REF! | D13: ='Working for PL & BS'!D31 -> #DIV/0! | E13: ='Working for PL & BS'!E31 -> #DIV/0! | F13: ='Working for PL & BS'!F31 -> #DIV/0!
A14: Depreciation | B14: ='Working for PL & BS'!C29 -> 0 | C14: ='Working for PL & BS'!#REF! -> #REF! | D14: ='Working for PL & BS'!D29 -> 0 | E14: ='Working for PL & BS'!E29 -> 0 | F14: ='Working for PL & BS'!F29 -> 0
A15: Decrease in debtors | B15: 0 | C15: 0 | D15: 0
A16: Increase in Unsecured loans | B16: 0 | C16: ='Working for PL & BS'!#REF!+'Working for PL & BS'!#REF!-'Working for PL & BS'!C52-'Working for PL & BS'!C117 -> #REF! | D16: 0
A17: Increase in Current liabilities | B17: 0 | C17: ='Working for PL & BS'!#REF!+'Working for PL & BS'!#REF!-'Working for PL & BS'!C58-'Working for PL & BS'!C57 -> #REF! | D17: ='Working for PL & BS'!D57+'Working for PL & BS'!D58-'Working for PL & BS'!#REF!-'Working for PL & BS'!#REF! -> #DIV/0! | E17: ='Working for PL & BS'!E57+'Working for PL & BS'!E58-'Working for PL & BS'!D58-'Working for PL & BS'!D57 -> #DIV/0! | F17: ='Working for PL & BS'!F57+'Working for PL & BS'!F58-'Working for PL & BS'!E58-'Working for PL & BS'!E57 -> #DIV/0!
A18: Increase in CC limit | B18: 0 | C18: 0 | D18: ='Working for PL & BS'!D56-'Working for PL & BS'!#REF! -> #DIV/0! | E18: ='Working for PL & BS'!E56-'Working for PL & BS'!D56 -> #DIV/0! | F18: ='Working for PL & BS'!F56-'Working for PL & BS'!E56 -> #DIV/0!
A19: Decrease in Other current assets | C19: ='Working for PL & BS'!C67-'Working for PL & BS'!#REF! -> #REF! | D19: 0 | E19: ='Working for PL & BS'!D67-'Working for PL & BS'!E67 -> 0 | F19: ='Working for PL & BS'!E67-'Working for PL & BS'!F67 -> 0
A21: Total Inflows | B21: =SUM(B11:B19) -> 0 | C21: =SUM(C11:C19) -> #REF! | D21: =SUM(D11:D19) -> #DIV/0! | E21: =SUM(E11:E19) -> #DIV/0! | F21: =SUM(F11:F19) -> #DIV/0!
A23: Outflows:
A25: Decrease in Unsecured Loans | B25: 0 | C25: 0 | D25: ='Working for PL & BS'!#REF!+'Working for PL & BS'!#REF!-'Working for PL & BS'!D117-'Working for PL & BS'!D52 -> #REF! | E25: ='Working for PL & BS'!D117+'Working for PL & BS'!D52-'Working for PL & BS'!E117-'Working for PL & BS'!E52 -> #DIV/0! | F25: ='Working for PL & BS'!E117+'Working for PL & BS'!E52-'Working for PL & BS'!F117-'Working for PL & BS'!F52 -> #DIV/0!
A26: Interest paid | B26: ='Working for PL & BS'!C33 -> 0 | C26: ='Working for PL & BS'!#REF! -> #REF! | D26: ='Working for PL & BS'!D33 -> #DIV/0! | E26: ='Working for PL & BS'!E33 -> #DIV/0! | F26: ='Working for PL & BS'!F33 -> #DIV/0!
A27: Increase in Debtors | B27: 0 | C27: ='Working for PL & BS'!#REF!-'Working for PL & BS'!C72 -> #REF! | D27: ='Working for PL & BS'!D72-'Working for PL & BS'!#REF! -> #DIV/0! | E27: ='Working for PL & BS'!E72-'Working for PL & BS'!D72 -> #DIV/0! | F27: ='Working for PL & BS'!F72-'Working for PL & BS'!E72 -> #DIV/0!
A28: Increase in Stock | B28: 0 | C28: ='Working for PL & BS'!#REF!-'Working for PL & BS'!C71 -> #REF! | D28: ='Working for PL & BS'!D71-'Working for PL & BS'!#REF! -> #REF! | E28: ='Working for PL & BS'!E71-'Working for PL & BS'!D71 -> 0 | F28: ='Working for PL & BS'!F71-'Working for PL & BS'!E71 -> 0
A29: Increase in Other Current assets | B29: 0 | C29: 0 | D29: ='Working for PL & BS'!D67-'Working for PL & BS'!#REF! -> #REF! | E29: 0 | F29: 0
A30: Decrease in current liabilities | B30: 0 | C30: 0 | D30: 0 | E30: 0 | F30: 0
A31: Decrease in Creditors | B31: 0 | C31: 0 | D31: 0 | E31: 0 | F31: 0
A32: Drawings
A34: Total Outflows | B34: 0 | C34: =SUM(C25:C32) -> #REF! | D34: =SUM(D25:D32) -> #REF! | E34: =SUM(E25:E32) -> #DIV/0! | F34: =SUM(F25:F32) -> #DIV/0!
A36: Opening balance of cash | B36: ='Working for PL & BS'!C73 -> 0 | C36: =+B38 -> 445186 | D36: =+C38 -> #REF! | E36: =+D38 -> #DIV/0! | F36: =+E38 -> #DIV/0!
A37: Surplus during the year | B37: =+B21-B34 -> 0 | C37: =+C21-C34 -> #REF! | D37: =+D21-D34 -> #DIV/0! | E37: =+E21-E34 -> #DIV/0! | F37: =+F21-F34 -> #DIV/0!
A38: Closing balance of cash | B38: 445186 | C38: =+C37+C36 -> #REF! | D38: =+D37+D36 -> #DIV/0! | E38: =+E37+E36 -> #DIV/0! | F38: =+F37+F36 -> #DIV/0!
B40: ='Working for PL & BS'!C73 -> 0 | C40: ='Working for PL & BS'!#REF! -> #REF! | D40: ='Working for PL & BS'!D73 -> #DIV/0! | E40: ='Working for PL & BS'!E73 -> #DIV/0! | F40: ='Working for PL & BS'!F73 -> #DIV/0!
B43: =B38-B40 -> 445186 | C43: =C38-C40 -> #REF! | D43: =D38-D40 -> #DIV/0! | E43: =E38-E40 -> #DIV/0! | F43: =F38-F40 -> #DIV/0!

Sheet MPBF 
A1: =Assumptions.1!I3 -> 0
A2: =Assumptions.1!I5 -> 0
A3: =Assumptions.1!I6 -> 0
A5: CALCULATION OF MAXIMUM PERMISSIBLE BANK FINANCE
A7: MPBF - Method 1 - 25% (Working Capital Gap)
A8: Particulars | B8: ='Working for PL & BS'!D5 -> Estimated | C8: ='Working for PL & BS'!E5 -> Projected | D8: ='Working for PL & BS'!F5 -> Projected | E8: ='Working for PL & BS'!G5 -> Projected | F8: ='Working for PL & BS'!H5 -> Projected | G8: ='Working for PL & BS'!I5 -> Projected
B9: ='Working for PL & BS'!D6 -> 0 | C9: ='Working for PL & BS'!E6 -> 0 | D9: ='Working for PL & BS'!F6 -> 0 | E9: ='Working for PL & BS'!G6 -> 0 | F9: ='Working for PL & BS'!H6 -> 0 | G9: ='Working for PL & BS'!I6 -> 0
A11: 1. Total current assets | B11: =SUM(PLBS!D68:D73) -> #DIV/0! | C11: =SUM(PLBS!E68:E73) -> #DIV/0! | D11: =SUM(PLBS!F68:F73) -> #DIV/0! | E11: =SUM(PLBS!G68:G73) -> #DIV/0! | F11: =SUM(PLBS!H68:H73) -> #DIV/0! | G11: =SUM(PLBS!I68:I73) -> #DIV/0!
A13: 2. Other current liabilities | B13: =PLBS!D58+PLBS!D59 -> #DIV/0! | C13: =PLBS!E58+PLBS!E59 -> #DIV/0! | D13: =PLBS!F58+PLBS!F59 -> #DIV/0! | E13: =PLBS!G58+PLBS!G59 -> #DIV/0! | F13: =PLBS!H58+PLBS!H59 -> #DIV/0! | G13: =PLBS!I58+PLBS!I59 -> #DIV/0!
A14: (Other than bank borrowings )
A16: 3. Working capital gap | B16: =+B11-B13 -> #DIV/0! | C16: =+C11-C13 -> #DIV/0! | D16: =+D11-D13 -> #DIV/0! | E16: =+E11-E13 -> #DIV/0! | F16: =+F11-F13 -> #DIV/0! | G16: =+G11-G13 -> #DIV/0!
A18: 4. Min. stipulated Networking capital
A19: (25% of WCG excluding export | B19: =+B16*0.25 -> #DIV/0! | C19: =+C16*0.25 -> #DIV/0! | D19: =+D16*0.25 -> #DIV/0! | E19: =+E16*0.25 -> #DIV/0! | F19: =+F16*0.25 -> #DIV/0! | G19: =+G16*0.25 -> #DIV/0!
A20: receivables)
A22: 5. Actual/projected net working capital | B22: =SUM(PLBS!D68:D73)-SUM(PLBS!D56:D59) -> #DIV/0! | C22: =SUM(PLBS!E68:E73)-SUM(PLBS!E56:E59) -> #DIV/0! | D22: =SUM(PLBS!F68:F73)-SUM(PLBS!F56:F59) -> #DIV/0! | E22: =SUM(PLBS!G68:G73)-SUM(PLBS!G56:G59) -> #DIV/0! | F22: =SUM(PLBS!H68:H73)-SUM(PLBS!H56:H59) -> #DIV/0! | G22: =SUM(PLBS!I68:I73)-SUM(PLBS!I56:I59) -> #DIV/0!
A24: 6.Item 3 minus item 4 | B24: =+B16-B19 -> #DIV/0! | C24: =+C16-C19 -> #DIV/0! | D24: =+D16-D19 -> #DIV/0! | E24: =+E16-E19 -> #DIV/0! | F24: =+F16-F19 -> #DIV/0! | G24: =+G16-G19 -> #DIV/0!
A26: 7.Item 3 minus item 5 | B26: =B16-B22 -> #DIV/0! | C26: =C16-C22 -> #DIV/0! | D26: =D16-D22 -> #DIV/0! | E26: =E16-E22 -> #DIV/0! | F26: =F16-F22 -> #DIV/0! | G26: =G16-G22 -> #DIV/0!
A28: 8. Maximum permissible bank | B28: =IF(B24<B26,B24,B26) -> #DIV/0! | C28: =IF(C24<C26,C24,C26) -> #DIV/0! | D28: =IF(D24<D26,D24,D26) -> #DIV/0! | E28: =IF(E24<E26,E24,E26) -> #DIV/0! | F28: =IF(F24<F26,F24,F26) -> #DIV/0! | G28: =IF(G24<G26,G24,G26) -> #DIV/0!
A29: finance(lower of 6 or 7 )
A32: MPBF - Method 2 - 25% (Current Assets)
A33: Particulars | B33: =B8 -> Estimated | C33: =C8 -> Projected | D33: =D8 -> Projected | E33: =E8 -> Projected | F33: =F8 -> Projected | G33: =G8 -> Projected
B34: =B9 -> 0 | C34: =C9 -> 0 | D34: =D9 -> 0 | E34: =E9 -> 0 | F34: =F9 -> 0 | G34: =G9 -> 0
A36: 1. Total current assets | B36: =B11 -> #DIV/0! | C36: =C11 -> #DIV/0! | D36: =D11 -> #DIV/0! | E36: =E11 -> #DIV/0! | F36: =F11 -> #DIV/0! | G36: =G11 -> #DIV/0!
A38: 2. Other current liabilities | B38: =B13 -> #DIV/0! | C38: =C13 -> #DIV/0! | D38: =D13 -> #DIV/0! | E38: =E13 -> #DIV/0! | F38: =F13 -> #DIV/0! | G38: =G13 -> #DIV/0!
A39: (Other than bank borrowings )
A41: 3. Working capital gap | B41: =+B36-B38 -> #DIV/0! | C41: =+C36-C38 -> #DIV/0! | D41: =+D36-D38 -> #DIV/0! | E41: =+E36-E38 -> #DIV/0! | F41: =+F36-F38 -> #DIV/0! | G41: =+G36-G38 -> #DIV/0!
A43: 4. Min. stipulated Networking capital
A44: (25% of Current Assets) | B44: =25%*B36 -> #DIV/0! | C44: =25%*C36 -> #DIV/0! | D44: =25%*D36 -> #DIV/0! | E44: =25%*E36 -> #DIV/0! | F44: =25%*F36 -> #DIV/0! | G44: =25%*G36 -> #DIV/0!
A46: 5. Actual/projected net working capital | B46: =B22 -> #DIV/0! | C46: =C22 -> #DIV/0! | D46: =D22 -> #DIV/0! | E46: =E22 -> #DIV/0! | F46: =F22 -> #DIV/0! | G46: =G22 -> #DIV/0!
A48: 6.Item 3 minus item 4 | B48: =+B41-B44 -> #DIV/0! | C48: =+C41-C44 -> #DIV/0! | D48: =+D41-D44 -> #DIV/0! | E48: =+E41-E44 -> #DIV/0! | F48: =+F41-F44 -> #DIV/0! | G48: =+G41-G44 -> #DIV/0!
A50: 7.Item 3 minus item 5 | B50: =B41-B46 -> #DIV/0! | C50: =C41-C46 -> #DIV/0! | D50: =D41-D46 -> #DIV/0! | E50: =E41-E46 -> #DIV/0! | F50: =F41-F46 -> #DIV/0! | G50: =G41-G46 -> #DIV/0!
A52: 8. Maximum permissible bank | B52: =IF(B48<B50,B48,B50) -> #DIV/0! | C52: =IF(C48<C50,C48,C50) -> #DIV/0! | D52: =IF(D48<D50,D48,D50) -> #DIV/0! | E52: =IF(E48<E50,E48,E50) -> #DIV/0! | F52: =IF(F48<F50,F48,F50) -> #DIV/0! | G52: =IF(G48<G50,G48,G50) -> #DIV/0!
A53: finance(lower of 6 or 7 )

Sheet Nayak Committee Recommandation
A1: ='Working for PL & BS'!A1:F1 -> 0
A2: ='Working for PL & BS'!A2:F2 -> 0
A3: ='Working for PL & BS'!A3:F3 -> STEP 2 : BACK GROUND CALCULATION . NOT TO BE VISIBLE TO CUSTOMER
A5: Working Capital Requirement as per Nayak Committee Recommandations
A6: TURNOVER METHOD
A7: Particulars
B8: ='Working for PL & BS'!#REF! -> #REF! | C8: ='Working for PL & BS'!#REF! -> #REF! | D8: ='Working for PL & BS'!#REF! -> #REF!
A9: A. Turnover | B9: ='Working for PL & BS'!D10 -> #DIV/0! | C9: ='Working for PL & BS'!E10 -> #DIV/0! | D9: ='Working for PL & BS'!F10 -> #DIV/0!
A10: B. 25% of (A) | B10: =B9*25% -> #DIV/0! | C10: =C9*25% -> #DIV/0! | D10: =D9*25% -> #DIV/0!
A11: C. Margin Required at 5% Turnover | B11: =B10*5% -> #DIV/0! | C11: =C10*5% -> #DIV/0! | D11: =D10*5% -> #DIV/0!
A12: D. Net Working Capital | B12: =RATIO!#REF!-RATIO!#REF! -> #REF! | C12: =RATIO!#REF!-RATIO!#REF! -> #REF! | D12: =RATIO!#REF!-RATIO!#REF! -> #REF!
A13: E. Eligible Bank Finance ( 20% of Turnover) | B13: =B9*20% -> #DIV/0! | C13: =C9*20% -> #DIV/0! | D13: =D9*20% -> #DIV/0!
A14: F. Maximum Permissable Bank Finance | B14: =IF(B12<B13,B12,B13) -> #REF! | C14: =IF(C12<C13,C12,C13) -> #REF! | D14: =IF(D12<D13,D12,D13) -> #REF!
A15: I. Actual Bank Borrowings Required | B15: ='Working for PL & BS'!D56 -> #DIV/0! | C15: ='Working for PL & BS'!E56 -> #DIV/0! | D15: ='Working for PL & BS'!F56 -> #DIV/0!
A16: H.Excess Borrowings ( I - H ) | B16: =B15-B14 -> #DIV/0! | C16: =C15-C14 -> #DIV/0! | D16: =D15-D14 -> #DIV/0!

Sheet nayak
A2: =Assumptions.1!I3 -> 0
A3: =Assumptions.1!I5 -> 0
A4: =Assumptions.1!I6 -> 0
A6: WORKING CAPITAL ASSESSMENT - TURNOVER METHOD
A8: NAYAK COMMITTEE RECOMONDATIONS
A10: PARTICULARS | C10: ='MPBF '!B8 -> Estimated | D10: ='MPBF '!C8 -> Projected | E10: ='MPBF '!D8 -> Projected | F10: ='MPBF '!E8 -> Projected | G10: ='MPBF '!F8 -> Projected | H10: ='MPBF '!G8 -> Projected
C11: ='MPBF '!B9 -> 0 | D11: ='MPBF '!C9 -> 0 | E11: ='MPBF '!D9 -> 0 | F11: ='MPBF '!E9 -> 0 | G11: ='MPBF '!F9 -> 0 | H11: ='MPBF '!G9 -> 0
A13: Turnover | C13: =PLBS!D11 -> #DIV/0! | D13: =PLBS!E11 -> #DIV/0! | E13: =PLBS!F11 -> #DIV/0! | F13: =PLBS!G11 -> #DIV/0! | G13: =PLBS!H11 -> #DIV/0! | H13: =PLBS!I11 -> #DIV/0!
A15: Working Capital Requirement | C15: =C13*25% -> #DIV/0! | D15: =D13*25% -> #DIV/0! | E15: =E13*25% -> #DIV/0! | F15: =F13*25% -> #DIV/0! | G15: =G13*25% -> #DIV/0! | H15: =H13*25% -> #DIV/0!
A16: (25% of Turnover)
A18: Minimum Working Capital Limit | C18: =C15*80% -> #DIV/0! | D18: =D15*80% -> #DIV/0! | E18: =E15*80% -> #DIV/0! | F18: =F15*80% -> #DIV/0! | G18: =G15*80% -> #DIV/0! | H18: =H15*80% -> #DIV/0!
A19: (80%of Working Capital Requirment)
A21: Drawing Power | C21: =Assumptions.1!I12 -> 0 | D21: =Assumptions.1!I12 -> 0 | E21: =D21 -> 0 | F21: =E21 -> 0 | G21: =F21 -> 0 | H21: =G21 -> 0
A23: Maximum Bank CC Loan | C23: =IF(C18<C21,C18,C21) -> #DIV/0! | D23: =IF(D18<D21,D18,D21) -> #DIV/0! | E23: =IF(E18<E21,E18,E21) -> #DIV/0! | F23: =IF(F18<F21,F18,F21) -> #DIV/0! | G23: =IF(G18<G21,G18,G21) -> #DIV/0! | H23: =IF(H18<H21,H18,H21) -> #DIV/0!
A27: Notes :
A28: 1. Maximum Working capital Limit Must not exceed Drawing power .
A29: 2. Four Operating cycles per Annum is Assumed.

Sheet Dep sch
A1: =Assumptions.1!I3 -> 0
A2: =Assumptions.1!I5 -> 0
A3: =Assumptions.1!I6 -> 0
A5: CALCULATION OF DEPRECIATION AS PER INCOME TAX ACT
M7: Amount in Rs
C9: =Assumptions.1!C52 -> Plant and Machinery | D9: =Assumptions.1!C122 -> Service Equipment | E9: =Assumptions.1!B155 -> Civil works & Shed Construction | F9: =Assumptions.1!B165 -> Land | G9: =Assumptions.1!B168 -> Electrical Items & fittings | H9: =Assumptions.1!B178 -> Electronic Items | I9: =Assumptions.1!B188 -> Furniture and Fittings | J9: =Assumptions.1!B198 -> Vehicles | K9: =Assumptions.1!B207 -> Live stock | L9: =Assumptions.1!B217 -> Other Assets | M9: =Assumptions.1!C131 -> Other Assets (Nil Depreciation)
N11: Total
C12: =Assumptions.1!E121 -> 0.15 | D12: =Assumptions.1!E122 -> 0.15 | E12: =Assumptions.1!E123 -> 0.1 | F12: =Assumptions.1!E124 -> 0 | G12: =Assumptions.1!E126 -> 0.15 | H12: =Assumptions.1!E127 -> 0.15 | I12: =Assumptions.1!E125 -> 0.1 | J12: =Assumptions.1!E128 -> 0.15 | K12: =Assumptions.1!E129 -> 0 | L12: =Assumptions.1!E130 -> 0.1 | M12: =Assumptions.1!E131 -> 0
A15: ='Working for PL & BS'!D46 -> 0
A16: WDV as on year beginning | C16: =Assumptions.1!I44 -> 0 | D16: 0 | E16: 0 | F16: 0 | G16: 0 | H16: 0 | I16: 0 | J16: 0 | K16: 0 | L16: 0 | M16: 0 | N16: =B16+C16+J16+M16 -> 0
A17: Add Additions | C17: =Assumptions.1!I52 -> 0 | D17: 0 | E17: 0 | F17: 0 | G17: 0 | H17: 0 | I17: 0 | J17: 0 | K17: 0 | L17: 0 | M17: 0 | N17: =B17+C17+J17+M17 -> 0
A18: Total | C18: =C16+C17 -> 0 | D18: =D16+D17 -> 0 | E18: =E16+E17 -> 0 | F18: =F16+F17 -> 0 | G18: =G16+G17 -> 0 | H18: =H16+H17 -> 0 | I18: =I16+I17 -> 0 | J18: =J16+J17 -> 0 | ... M18: =M16+M17 -> 0 | N18: =B18+C18+J18+M18 -> 0
A19: Depreciation | C19: =C18*C12 -> 0 | D19: =D18*D12 -> 0 | E19: =E18*E12 -> 0 | F19: =F18*F12 -> 0 | G19: =G18*G12 -> 0 | H19: =H18*H12 -> 0 | I19: =I18*I12 -> 0 | J19: =J18*J12 -> 0 | K19: =K18*K12*0.5 -> 0 | L19: =L18*L12 -> 0 | M19: =M18*M12*0.5 -> 0 | N19: =B19+C19+J19+M19 -> 0
A20: WDV as on Year End | C20: =C18-C19 -> 0 | D20: =D18-D19 -> 0 | E20: =E18-E19 -> 0 | F20: =F18-F19 -> 0 | G20: =G18-G19 -> 0 | H20: =H18-H19 -> 0 | I20: =I18-I19 -> 0 | J20: =J18-J19 -> 0 | ... M20: =M18-M19 -> 0 | N20: =B20+C20+J20+M20 -> 0
A22: ='Working for PL & BS'!E46 -> 0
A23: WDV as on year beginning | C23: =C20 -> 0 | D23: =D20 -> 0 | E23: =E20 -> 0 | F23: =F20 -> 0 | G23: =G20 -> 0 | H23: =H20 -> 0 | I23: =I20 -> 0 | J23: =J20 -> 0 | ... M23: =M20 -> 0 | N23: =B23+C23+J23+M23 -> 0
A24: Add Additions | C24: 0 | D24: 0 | E24: 0 | F24: 0 | G24: 0 | H24: 0 | I24: 0 | J24: 0 | K24: 0 | L24: 0 | M24: 0 | N24: =B24+C24+J24+M24 -> 0
A25: Total | C25: =C23+C24 -> 0 | D25: =D23+D24 -> 0 | E25: =E23+E24 -> 0 | F25: =F23+F24 -> 0 | G25: =G23+G24 -> 0 | H25: =H23+H24 -> 0 | I25: =I23+I24 -> 0 | J25: =J23+J24 -> 0 | ... M25: =M23+M24 -> 0 | N25: =B25+C25+J25+M25 -> 0
A26: Depreciation | C26: =C25*C12 -> 0 | D26: =D25*D12 -> 0 | E26: =E25*E12 -> 0 | F26: =F25*F12 -> 0 | G26: =G25*G12 -> 0 | H26: =H25*H12 -> 0 | I26: =I25*I12 -> 0 | J26: =J25*J12 -> 0 | ... M26: =M25*M12 -> 0 | N26: =B26+C26+J26+M26 -> 0
A27: WDV as on Year End | C27: =C25-C26 -> 0 | D27: =D25-D26 -> 0 | E27: =E25-E26 -> 0 | F27: =F25-F26 -> 0 | G27: =G25-G26 -> 0 | H27: =H25-H26 -> 0 | I27: =I25-I26 -> 0 | J27: =J25-J26 -> 0 | ... M27: =M25-M26 -> 0 | N27: =B27+C27+J27+M27 -> 0
A29: ='Working for PL & BS'!F46 -> 0
A30: WDV as on year beginning | C30: =C27 -> 0 | D30: =D27 -> 0 | E30: =E27 -> 0 | F30: =F27 -> 0 | G30: =G27 -> 0 | H30: =H27 -> 0 | I30: =I27 -> 0 | J30: =J27 -> 0 | ... M30: =M27 -> 0 | N30: =B30+C30+J30+M30 -> 0
A31: Add Additions | C31: 0 | D31: 0 | E31: 0 | F31: 0 | G31: 0 | H31: 0 | I31: 0 | J31: 0 | K31: 0 | L31: 0 | M31: 0 | N31: =B31+C31+J31+M31 -> 0
A32: Total | C32: =C30+C31 -> 0 | D32: =D30+D31 -> 0 | E32: =E30+E31 -> 0 | F32: =F30+F31 -> 0 | G32: =G30+G31 -> 0 | H32: =H30+H31 -> 0 | I32: =I30+I31 -> 0 | J32: =J30+J31 -> 0 | ... M32: =M30+M31 -> 0 | N32: =B32+C32+J32+M32 -> 0
A33: Depreciation | C33: =C32*C12 -> 0 | D33: =D32*D12 -> 0 | E33: =E32*E12 -> 0 | F33: =F32*F12 -> 0 | G33: =G32*G12 -> 0 | H33: =H32*H12 -> 0 | I33: =I32*I12 -> 0 | J33: =J32*J12 -> 0 | ... M33: =M32*M12 -> 0 | N33: =B33+C33+J33+M33 -> 0
A34: WDV as on Year End | C34: =C32-C33 -> 0 | D34: =D32-D33 -> 0 | E34: =E32-E33 -> 0 | F34: =F32-F33 -> 0 | G34: =G32-G33 -> 0 | H34: =H32-H33 -> 0 | I34: =I32-I33 -> 0 | J34: =J32-J33 -> 0 | ... M34: =M32-M33 -> 0 | N34: =B34+C34+J34+M34 -> 0
A36: =Assumptions.1!I22 -> 0
A37: WDV as on year beginning | C37: =C34 -> 0 | D37: =D34 -> 0 | E37: =E34 -> 0 | F37: =F34 -> 0 | G37: =G34 -> 0 | H37: =H34 -> 0 | I37: =I34 -> 0 | J37: =J34 -> 0 | ... M37: =M34 -> 0 | N37: =B37+C37+J37+M37 -> 0
A38: Add Additions | C38: 0 | D38: 0 | E38: 0 | F38: 0 | G38: 0 | H38: 0 | I38: 0 | J38: 0 | K38: 0 | L38: 0 | M38: 0 | N38: =B38+C38+J38+M38 -> 0
A39: Total | C39: =C37+C38 -> 0 | D39: =D37+D38 -> 0 | E39: =E37+E38 -> 0 | F39: =F37+F38 -> 0 | G39: =G37+G38 -> 0 | H39: =H37+H38 -> 0 | I39: =I37+I38 -> 0 | J39: =J37+J38 -> 0 | ... M39: =M37+M38 -> 0 | N39: =B39+C39+J39+M39 -> 0
A40: Depreciation | C40: =C39*C12 -> 0 | D40: =D39*D12 -> 0 | E40: =E39*E12 -> 0 | F40: =F39*F12 -> 0 | G40: =G39*G12 -> 0 | H40: =H39*H12 -> 0 | I40: =I39*I12 -> 0 | J40: =J39*J12 -> 0 | ... M40: =M39*M12 -> 0 | N40: =B40+C40+J40+M40 -> 0
A41: WDV as on Year End | C41: =C39-C40 -> 0 | D41: =D39-D40 -> 0 | E41: =E39-E40 -> 0 | F41: =F39-F40 -> 0 | G41: =G39-G40 -> 0 | H41: =H39-H40 -> 0 | I41: =I39-I40 -> 0 | J41: =J39-J40 -> 0 | ... M41: =M39-M40 -> 0 | N41: =B41+C41+J41+M41 -> 0
A43: =Assumptions.1!I23 -> 0
A44: WDV as on year beginning | C44: =C41 -> 0 | D44: =D41 -> 0 | E44: =E41 -> 0 | F44: =F41 -> 0 | G44: =G41 -> 0 | H44: =H41 -> 0 | I44: =I41 -> 0 | J44: =J41 -> 0 | ... M44: =M41 -> 0 | N44: =B44+C44+J44+M44 -> 0
A45: Add Additions | C45: 0 | D45: 0 | E45: 0 | F45: 0 | G45: 0 | H45: 0 | I45: 0 | J45: 0 | K45: 0 | L45: 0 | M45: 0 | N45: =B45+C45+J45+M45 -> 0
A46: Total | C46: =C44+C45 -> 0 | D46: =D44+D45 -> 0 | E46: =E44+E45 -> 0 | F46: =F44+F45 -> 0 | G46: =G44+G45 -> 0 | H46: =H44+H45 -> 0 | I46: =I44+I45 -> 0 | J46: =J44+J45 -> 0 | ... M46: =M44+M45 -> 0 | N46: =B46+C46+J46+M46 -> 0
A47: Depreciation | C47: =C46*C12 -> 0 | D47: =D46*D12 -> 0 | E47: =E46*E12 -> 0 | F47: =F46*F12 -> 0 | G47: =G46*G12 -> 0 | H47: =H46*H12 -> 0 | I47: =I46*I12 -> 0 | J47: =J46*J12 -> 0 | ... M47: =M46*M12 -> 0 | N47: =B47+C47+J47+M47 -> 0
A48: WDV as on Year End | C48: =C46-C47 -> 0 | D48: =D46-D47 -> 0 | E48: =E46-E47 -> 0 | F48: =F46-F47 -> 0 | G48: =G46-G47 -> 0 | H48: =H46-H47 -> 0 | I48: =I46-I47 -> 0 | J48: =J46-J47 -> 0 | ... M48: =M46-M47 -> 0 | N48: =B48+C48+J48+M48 -> 0
A50: =Assumptions.1!I24 -> 0
A51: WDV as on year beginning | C51: =C48 -> 0 | D51: =D48 -> 0 | E51: =E48 -> 0 | F51: =F48 -> 0 | G51: =G48 -> 0 | H51: =H48 -> 0 | I51: =I48 -> 0 | J51: =J48 -> 0 | ... M51: =M48 -> 0 | N51: =B51+C51+J51+M51 -> 0
...

Sheet Sheet3

Sheet Sheet2

Sheet Loan Sch
A1: =Assumptions.1!I3 -> 0
A2: =Assumptions.1!I5 -> 0
A3: =Assumptions.1!I6 -> 0
B5: EMI STATEMENT
B8: LOAN AMOUNT | E8: =Assumptions.1!I64*100000 -> 0
B10: RATE OF INTEREST PER ANNUM | E10: =Assumptions.1!I66 -> 0
B12: RATE OF INTEREST PER MONTH | E12: =E10/12 -> 0
B14: NO OF INSTALLMENT | E14: =Assumptions.1!I67-Assumptions.1!I69 -> 0
E15: 62
B18: =Assumptions.1!I68 -> 0
B20: CALCULATION OF DETAILS OF EMI
B22: MONTHS | C22: MONTH | D22: EMI | E22: INTEREST | F22: PRINCIPAL REPAYMENT | G22: OUTSTANDING PRINCIPAL
B23: =Assumptions.1!I69+0 -> 0 | G23: =E8 -> 0
B24: =B23+1 -> 1 | C24: =Assumptions.1!I72 -> 0 | D24: =E24+F24 -> #DIV/0! | E24: =G23*E12 -> 0 | F24: =E8/E14 -> #DIV/0! | G24: =G23-F24 -> #DIV/0!
B25: =B24+1 -> 2 | C25: =EDATE(C24,1) -> 31 | D25: =E25+F25 -> #DIV/0! | E25: =G24*E12 -> #DIV/0! | F25: =F24 -> #DIV/0! | G25: =G24-F25 -> #DIV/0!
B26: =B25+1 -> 3 | C26: =EDATE(C25,1) -> 59 | D26: =E26+F26 -> #DIV/0! | E26: =G25*E12 -> #DIV/0! | F26: =F25 -> #DIV/0! | G26: =G25-F26 -> #DIV/0!
B27: =B26+1 -> 4 | C27: =EDATE(C26,1) -> 88 | D27: =E27+F27 -> #DIV/0! | E27: =G26*E12 -> #DIV/0! | F27: =F26 -> #DIV/0! | G27: =G26-F27 -> #DIV/0!
B28: =B27+1 -> 5 | C28: =EDATE(C27,1) -> 119 | D28: =E28+F28 -> #DIV/0! | E28: =G27*E12 -> #DIV/0! | F28: =F27 -> #DIV/0! | G28: =G27-F28 -> #DIV/0!
B29: =B28+1 -> 6 | C29: =EDATE(C28,1) -> 149 | D29: =E29+F29 -> #DIV/0! | E29: =G28*E12 -> #DIV/0! | F29: =F28 -> #DIV/0! | G29: =G28-F29 -> #DIV/0!
B30: =B29+1 -> 7 | C30: =EDATE(C29,1) -> 180 | D30: =E30+F30 -> #DIV/0! | E30: =G29*E12 -> #DIV/0! | F30: =F29 -> #DIV/0! | G30: =G29-F30 -> #DIV/0!
B31: =B30+1 -> 8 | C31: =EDATE(C30,1) -> 210 | D31: =E31+F31 -> #DIV/0! | E31: =G30*E12 -> #DIV/0! | F31: =F30 -> #DIV/0! | G31: =G30-F31 -> #DIV/0!
