Workbook

Sheet Assumptions.1
B2: Section | C2: Question | D2: Question Type | E2: Editable | F2: Options | G2: Min - Max | H2: Details which are required to be given by Customer | I2: Answer | J2: Particulars
B3: General Information | C3: Name of Firm | D3: Manual entry | E3: No
C4: Status of Concern | D4: Dropdown options to be provided | E4: No | F4: Soleproprietorship,Partnership,LLP,Company
C5: Proprietor / MP / MD Name | D5: Manual entry | E5: No
C6: Firm address | D6: Manual entry | E6: No
C7: Sector | D7: Dropdown Options to be provided | E7: No | F7: Manufacturing sector / Service sector (with stock) / Trading sector
C8: Nature of Business | D8: Manual entry | E8: No
B10: Means of Finance details | C10: Do you have working capital limit at present ? | D10: Dropdown Options to be provided | F10: Yes,No
C11: Working capital Loan requirement | D11: Manual entry | E11: Yes | J11: Loan amount
C12: Working capital loan interest | D12: Manual entry | E12: Yes | I12: =H12*1/100 -> 0 | J12: per annum
C13: Processing fees (Including GST) | D13: Manual entry | E13: Yes | I13: =(H13+H13*18/100)*1/100 -> 0 | J13: of loan amount
C14: Working capital (% on Turnover) | D14: Manual entry | E14: Yes | G14: 15% or more than 15% | I14: =H14*1/100 -> 0 | J14: on Sales
B16: Financial Year | C16: 1st Financial year | D16: Dropdown options to be provided | E16: Yes | F16: 2024 - 25 to provide 10 years with Start Month to End Month | J16: Audited
C17: 2nd Financial year | D17: Dropdown options to be provided | E17: Yes | F17: 2024 - 25 to provide 10 years with Start Month to End Month | J17: Provisional
C18: 3rd Financial year | D18: Dropdown options to be provided | E18: Yes | F18: 2024 - 25 to provide 10 years with Start Month to End Month | J18: Estimated
C19: 4th Financial year | D19: Dropdown options to be provided | E19: Yes | F19: 2024 - 25 to provide 10 years with Start Month to End Month | J19: Projected
C20: 5th Financial year | D20: Dropdown options to be provided | E20: Yes | F20: 2024 - 25 to provide 10 years with Start Month to End Month | J20: Projected
C21: =I16 -> 0
B22: Audited financial Statements | C22: Turnover | D22: Manual entry | E22: Yes
C23: Opening Stock | D23: Manual entry | E23: Yes
C24: Direct Material & Expenses | D24: Manual entry | E24: Yes
C25: Closing Stock | D25: Manual entry | E25: Yes
C26: Non Operating Income | D26: Manual entry | E26: Yes
C27: Depreciation | D27: Manual entry | E27: Yes
C28: Electricity | D28: Manual entry | E28: Yes
C29: Rent | D29: Manual entry | E29: Yes
C30: Salaries & Wages | D30: Manual entry | E30: Yes
C31: Interest on Other loans | D31: Manual entry | E31: Yes
C32: Net Profit Before Tax | D32: Manual entry | E32: Yes
C33: Office Admin, Marketing and Miscelleneous Expenses | D33: Autogenerated | E33: NA | I33: =I22-I23-I24+I25+I26-I27-I28-I29-I30-I31-I32 -> 0
C34: Net Capital (Opening capital +Net Profit -Drawings) | D34: Manual entry | E34: Yes
C35: Term Loans (Secured and Unsecured Loans Total) | D35: Manual entry | E35: Yes
C36: Current Liabilities | D36: Manual entry | E36: Yes
C37: Net Total Fixed Assets | D37: Manual entry | E37: Yes | F37: Autogenerated from Schedule for FIXED ASSETS
C38: Depreciation | D38: Autogenerated | E38: NA | I38: =I27 -> 0
A39: STEP 1 | C39: Gross Total Fixed Assets | D39: Autogenerated | E39: NA | I39: =I37+I38 -> 0
C40: Investments | D40: Manual entry | E40: Yes
C41: Debtors | D41: Manual entry | E41: Yes
C42: Cash and Cash Equivalents | D42: Manual entry | E42: Yes
C43: Other Current Assets if any | D43: Manual entry | E43: Yes
...

Sheet wp
A3: STEP 2 : BACK GROUND CALCULATION . NOT TO BE VISIBLE TO CUSTOMER
A4: WORKINGS FOR PROFIT AND LOSS ACCOUNT
A5: PARTICULARS | B5: Schedules | C5: =Assumptions.1!J16 -> Audited | D5: =Assumptions.1!J17 -> Provisional | E5: =Assumptions.1!J18 -> Estimated | F5: =Assumptions.1!J19 -> Projected | G5: =Assumptions.1!J20 -> Projected
C6: =Assumptions.1!I16 -> 0 | D6: =Assumptions.1!I17 -> 0 | E6: =Assumptions.1!I18 -> 0 | F6: =Assumptions.1!I19 -> 0 | G6: =Assumptions.1!I20 -> 0
A8: Gross Reciepts:
A10: Turnover (A1) | C10: =Assumptions.1!I22 -> 0 | D10: =Assumptions.1!I46 -> 0 | E10: =Assumptions.1!I95 -> #DIV/0! | F10: =E10*Assumptions.1!I70 -> #DIV/0! | G10: =F10*Assumptions.1!I70 -> #DIV/0!
C12: =SUM(C10:C11) -> 0 | D12: =SUM(D10:D11) -> 0 | E12: =SUM(E10:E11) -> #DIV/0! | F12: =SUM(F10:F11) -> #DIV/0! | G12: =SUM(G10:G11) -> #DIV/0!
A14: Cost of Goods Sold:
A16: Opening Stock | C16: =Assumptions.1!I23 -> 0 | D16: =Assumptions.1!I47 -> 0 | E16: =C18 -> 0 | F16: =E18 -> 0 | G16: =F18 -> 0
A17: Direct Material & Expenses | C17: =Assumptions.1!I24 -> 0 | D17: =Assumptions.1!I48 -> 0 | E17: =E19-E16+E18 -> #DIV/0! | F17: =F19-F16+F18 -> #DIV/0! | G17: =G19-G16+G18 -> #DIV/0!
A18: Closing Stock | C18: =Assumptions.1!I25 -> 0 | D18: =Assumptions.1!I49 -> 0 | E18: =Assumptions.1!I99 -> 0 | F18: =E18*Assumptions.1!I75 -> 0 | G18: =F18*Assumptions.1!I75 -> 0
A19: Operating Expenses | C19: =C16+C17-C18 -> 0 | D19: =D16+D17-D18 -> 0 | E19: =E10-E21 -> #DIV/0! | F19: =F12-F21 -> #DIV/0! | G19: =G12-G21 -> #DIV/0!
A21: Gross Profit (D = A1-A-B+C) | C21: =C12-C19 -> 0 | D21: =D12-D19 -> 0 | E21: =E10*Assumptions.1!I88 -> #DIV/0! | F21: =F10*Assumptions.1!I89 -> #DIV/0! | G21: =G10*Assumptions.1!I90 -> #DIV/0!
A23: Non Operating Income (E) | C23: =Assumptions.1!I26 -> 0 | D23: =Assumptions.1!I50 -> 0 | E23: =D23*Assumptions.1!I76/Assumptions.1!I45*Assumptions.1!I73 -> #DIV/0! | F23: =E23*Assumptions.1!I73 -> #DIV/0! | G23: =F23*Assumptions.1!I73 -> #DIV/0!
A25: Adm & Selling Expenses(F) | C25: =C88 -> 0 | D25: =D88 -> 0 | E25: =E88 -> #DIV/0! | F25: =F88 -> #DIV/0! | G25: =G88 -> #DIV/0!
A27: EBDIT(G = D+E-F) | C27: =C21+C23-C25 -> 0 | D27: =D21+D23-D25 -> 0 | E27: =E21+E23-E25 -> #DIV/0! | F27: =F21+F23-F25 -> #DIV/0! | G27: =G21+G23-G25 -> #DIV/0!
A29: Less : Depreciation (H) | C29: =Assumptions.1!I27 -> 0 | D29: =Assumptions.1!I51 -> 0 | E29: =Depsch!M19 -> 54948.2 | F29: =Depsch!M26 -> 49453.38 | G29: =Depsch!M33 -> 44508.042
A31: EBIT( I = G - H ) | C31: =C27-C29 -> 0 | D31: =D27-D29 -> 0 | E31: =E27-E29 -> #DIV/0! | F31: =F27-F29 -> #DIV/0! | G31: =G27-G29 -> #DIV/0!
A33: Less: Interest (J) | C33: =C100 -> 0 | D33: =D100 -> 0 | E33: =E100 -> #DIV/0! | F33: =F100 -> 0 | G33: =G100 -> 0
A35: EBT(K = I - J) | C35: =C31-C33 -> 0 | D35: =D31-D33 -> 0 | E35: =E31-E33 -> #DIV/0! | F35: =F31-F33 -> #DIV/0! | G35: =G31-G33 -> #DIV/0!
C37: When ever editing is done , this totally must be calculated automatically
A40: STEP 2 : BACK GROUND CALCULATION . NOT TO BE VISIBLE TO CUSTOMER
A41: WORKINGS FOR BALANCESHEET
A42: Particulars | B42: Schedules | C42: =C5 -> Audited | D42: =D5 -> Provisional | E42: =E5 -> Estimated | F42: =F5 -> Projected | G42: =G5 -> Projected
C43: =C6 -> 0 | D43: =D6 -> 0 | E43: =E6 -> 0 | F43: =F6 -> 0 | G43: =G6 -> 0
A44: SOURCES OF FUNDS:
A46: Net Capital | C46: =Assumptions.1!I34 -> 0 | D46: =Assumptions.1!I58 -> 0 | E46: =E56-E54-E53-E52-E49 -> #DIV/0! | F46: =F56-F54-F53-F52-F49 -> #DIV/0! | G46: =G56-G54-G53-G52-G49 -> #DIV/0!
A47: (Opening capital + Net profit -Drawings)
A48: TERM LOANS:
A49: Secured and Unsecured Loans | C49: =Assumptions.1!I35 -> 0 | D49: =Assumptions.1!I59 -> 0 | E49: =D49-Assumptions.1!I103 -> 0 | F49: =E49-Assumptions.1!I103 -> 0 | G49: =F49-Assumptions.1!I103 -> 0
A51: CURRENT LIABILITIES:
A52: Bank CC/OD loan | C52: 0 | D52: 0 | E52: =IF(E112<E107,E112,Assumptions.1!I11) -> #DIV/0! | F52: =IF(F112<F107,F112,Assumptions.1!I11) -> #DIV/0! | G52: =IF(G112<G107,G112,Assumptions.1!I11) -> #DIV/0!
A53: Other current liabilities | C53: =Assumptions.1!I36 -> 0 | D53: =Assumptions.1!I60 -> 0 | E53: 0 | F53: 0 | G53: 0
C56: =SUM(C46:C54) -> 0 | D56: =SUM(D46:D54) -> 0 | E56: =E71 -> #DIV/0! | F56: =F71 -> #DIV/0! | G56: =G71 -> #DIV/0!
C58: When ever editing is done , this totally must be calculated automatically
A59: APPLICATION OF FUNDS:
A61: FIXED ASSETS: | C61: =Assumptions.1!I37 -> 0 | D61: =Assumptions.1!I63 -> 549482 | E61: =Depsch!M20 -> 494533.8 | F61: =Depsch!M27 -> 445080.42 | G61: =Depsch!M34 -> 400572.38
A63: INVESTMENTS: | C63: =Assumptions.1!I40 -> 0 | D63: =Assumptions.1!I64 -> 0 | E63: =D63 -> 0 | F63: =E63 -> 0 | G63: =F63 -> 0
A65: CURRENT ASSETS:
A66: Other current Assets | C66: =Assumptions.1!I43 -> 0 | D66: =Assumptions.1!I67 -> 0 | E66: 0 | F66: 0 | G66: 0
...

Sheet FinalWorkings
A3: STEP 3 : DISPLAY TO CUSTOMER FOR MAKING EDITING
A4: Financials and Ratios at a Glance
A5: PARTICULARS | B5: =Assumptions.1!J16 -> Audited | C5: =Assumptions.1!J17 -> Provisional | D5: =Assumptions.1!J18 -> Estimated | E5: =Assumptions.1!J19 -> Projected | F5: =Assumptions.1!J20 -> Projected
B6: =Assumptions.1!I16 -> 0 | C6: =Assumptions.1!I17 -> 0 | D6: =Assumptions.1!I18 -> 0 | E6: =Assumptions.1!I19 -> 0 | F6: =Assumptions.1!I20 -> 0
B7: Audited, Hence Not editable | C7: Provisional , Hence Not editable | D7: All Items Editable | E7: All Items Editable | F7: All Items Editable
A8: Profit and Loss Items at a Glance :
A9: Gross Revenue / Turnover | B9: =wp!C10 -> 0 | C9: =wp!D10 -> 0 | D9: =wp!E10 -> #DIV/0! | E9: =wp!F10 -> #DIV/0! | F9: =wp!G10 -> #DIV/0!
A10: Direct Material & Expenses | B10: =wp!C17 -> 0 | C10: =wp!D17 -> 0 | D10: =wp!E17 -> #DIV/0! | E10: =wp!F17 -> #DIV/0! | F10: =wp!G17 -> #DIV/0!
A11: Closing Stock / WIP | B11: =wp!C18 -> 0 | C11: =wp!D18 -> 0 | D11: =wp!E18 -> 0 | E11: =wp!F18 -> 0 | F11: =wp!G18 -> 0
A12: Non Operating Income | B12: =wp!C23 -> 0 | C12: =wp!D23 -> 0 | D12: =wp!E23 -> #DIV/0! | E12: =wp!F23 -> #DIV/0! | F12: =wp!G23 -> #DIV/0!
A13: Electricity | B13: =wp!C80 -> 0 | C13: =wp!D80 -> 0 | D13: =wp!E80 -> #DIV/0! | E13: =wp!F80 -> #DIV/0! | F13: =wp!G80 -> #DIV/0!
A14: Rent | B14: =wp!C81 -> 0 | C14: =wp!D81 -> 0 | D14: =wp!E81 -> #DIV/0! | E14: =wp!F81 -> #DIV/0! | F14: =wp!G81 -> #DIV/0!
A15: Salaries & Wages | B15: =wp!C82 -> 0 | C15: =wp!D82 -> 0 | D15: =wp!E82 -> #DIV/0! | E15: =wp!F82 -> #DIV/0! | F15: =wp!G82 -> #DIV/0!
A16: Off Admin and Marketing Expenses | B16: =wp!C84 -> 0 | C16: =wp!D84 -> 0 | D16: =wp!E84 -> #DIV/0! | E16: =wp!F84 -> #DIV/0! | F16: =wp!G84 -> #DIV/0!
A17: Interest on Other loans | B17: =wp!C96 -> 0 | C17: =wp!D96 -> 0 | D17: =wp!E96 -> #DIV/0! | E17: =IF(D22=0,0,D17*E22/D22) -> 0 | F17: =IF(E22=0,0,E17*F22/E22) -> 0
A18: Interest on CC/OD | B18: =wp!C97 -> 0 | C18: =wp!D97 -> 0 | D18: =wp!E97 -> #DIV/0! | E18: =wp!F97 -> 0 | F18: =wp!G97 -> 0
A19: Earnings Before Tax (Not Editable) | B19: =PLBS!C35 -> 0 | C19: =PLBS!D35 -> 0 | D19: =PLBS!E35 -> #DIV/0! | E19: =PLBS!F35 -> #DIV/0! | F19: =PLBS!G35 -> #DIV/0!
A21: Balance Sheet Items at a Glance:
A22: Term Loans(Secured and Unsecured) | B22: =wp!C49 -> 0 | C22: =wp!D49 -> 0 | D22: =wp!E49 -> 0 | E22: =wp!F49 -> 0 | F22: =wp!G49 -> 0
A23: Other current liabilities | B23: =wp!C53 -> 0 | C23: =wp!D53 -> 0 | D23: =wp!E53 -> 0 | E23: =wp!F53 -> 0 | F23: =wp!G53 -> 0
A24: Investments | B24: =wp!C63 -> 0 | C24: =wp!D63 -> 0 | D24: =wp!E63 -> 0 | E24: =wp!F63 -> 0 | F24: =wp!G63 -> 0
A25: Other current Assets | B25: =wp!C66 -> 0 | C25: =wp!D66 -> 0 | D25: =wp!E66 -> 0 | E25: =wp!F66 -> 0 | F25: =wp!G66 -> 0
A26: Debtors | B26: =wp!C68 -> 0 | C26: =wp!D68 -> 0 | D26: =wp!E68 -> #DIV/0! | E26: =wp!F68 -> #DIV/0! | F26: =wp!G68 -> #DIV/0!
A27: Cash and Cash Equivalents | B27: =wp!C69 -> 0 | C27: =wp!D69 -> 0 | D27: =wp!E69 -> #DIV/0! | E27: =wp!F69 -> #DIV/0! | F27: =wp!G69 -> #DIV/0!
A29: RATIO ANALYSIS at a Glance: (Not Editable but displayed)
A30: Gross profit ratio (%) | B30: =RATIO!C37 -> #DIV/0! | C30: =RATIO!D37 -> #DIV/0! | D30: =RATIO!E37 -> #DIV/0! | E30: =RATIO!F37 -> #DIV/0! | F30: =RATIO!G37 -> #DIV/0!
A31: Net Profit Ratio (%) | B31: =RATIO!C51 -> #DIV/0! | C31: =RATIO!D51 -> #DIV/0! | D31: =RATIO!E51 -> #DIV/0! | E31: =RATIO!F51 -> #DIV/0! | F31: =RATIO!G51 -> #DIV/0!
A32: Debtors Turonver Ratio (Days) | B32: =RATIO!C27 -> #DIV/0! | C32: =RATIO!D27 -> #DIV/0! | D32: =RATIO!E27 -> #DIV/0! | E32: =RATIO!F27 -> #DIV/0! | F32: =RATIO!G27 -> #DIV/0!
A33: Current Ratio | B33: =RATIO!C11 -> #DIV/0! | C33: =RATIO!D11 -> #DIV/0! | D33: =RATIO!E11 -> #DIV/0! | E33: =RATIO!F11 -> #DIV/0! | F33: =RATIO!G11 -> #DIV/0!
A34: Total outside Liabilities to Total Networth | B34: =RATIO!C59 -> #DIV/0! | C34: =RATIO!D59 -> #DIV/0! | D34: =RATIO!E59 -> #DIV/0! | E34: =RATIO!F59 -> #DIV/0! | F34: =RATIO!G59 -> #DIV/0!
A36: MAXIMUM PERMISSABLE BANK FINANCE:
A37: Method 1 : Working capital Method | D37: ='MPBF '!B28 -> #DIV/0! | E37: ='MPBF '!C28 -> #DIV/0! | F37: ='MPBF '!D28 -> #DIV/0!
A38: Method 1 : Current Assets Method | D38: ='MPBF '!B65 -> #DIV/0! | E38: ='MPBF '!C65 -> #DIV/0! | F38: ='MPBF '!D65 -> #DIV/0!
A39: Method 3 : Nayak Committee | D39: =nayak!C23 -> #DIV/0! | E39: =nayak!D23 -> #DIV/0! | F39: =nayak!E23 -> #DIV/0!

Sheet coverpage
D6: PROJECTIONS AND ESTIMATIONS | T6: Please use "IF" function in following cases
D9: OF | T9: In case of | U9: Designation
D11: =Assumptions.1!I3 -> 0 | T11: Companies | U11: Managing Director
T12: LLP | U12: Designated Partner
T13: Soleproprietor | U13: Proprietor
D14: =Assumptions.1!I5 -> 0 | T14: Partnership firm | U14: Managing Partner
D19: =Assumptions.1!I8 -> 0
D23: =Assumptions.1!I6 -> 0
D29: Working capital (CC) Loan | I29: =Assumptions.1!I11 -> 0
D33: PREPARED BY
D35: FINVOIS OPEN BUSINESS SOLUTIONS LLP
D36: MSME & DPR Consultants
D37: Contact : 9618221011

Sheet PLBS
A1: =Assumptions.1!I3 -> 0
A2: =Assumptions.1!I5 -> 0
A3: =Assumptions.1!I6 -> 0
A4: TRADING, PROFIT & LOSS ACCOUNT FOR YEAR ENDED
A5: PARTICULARS | B5: Schedules | C5: =Assumptions.1!J16 -> Audited | D5: =Assumptions.1!J17 -> Provisional | E5: =Assumptions.1!J18 -> Estimated | F5: =Assumptions.1!J19 -> Projected | G5: =Assumptions.1!J20 -> Projected
C6: =Assumptions.1!I16 -> 0 | D6: =Assumptions.1!I17 -> 0 | E6: =Assumptions.1!I18 -> 0 | F6: =Assumptions.1!I19 -> 0 | G6: =Assumptions.1!I20 -> 0
A8: Gross Revenue / Turnover:
A10: Revenue | C10: =FinalWorkings!B9 -> 0 | D10: =FinalWorkings!C9 -> 0 | E10: =ROUND(FinalWorkings!D9,-4) -> #DIV/0! | F10: =ROUND(FinalWorkings!E9,-4) -> #DIV/0! | G10: =ROUND(FinalWorkings!F9,-4) -> #DIV/0!
C12: =SUM(C10:C11) -> 0 | D12: =SUM(D10:D11) -> 0 | E12: =SUM(E10:E11) -> #DIV/0! | F12: =SUM(F10:F11) -> #DIV/0! | G12: =SUM(G10:G11) -> #DIV/0!
A14: Cost of Goods Sold:
A16: Opening Stock | C16: =wp!C16 -> 0 | D16: =wp!D16 -> 0 | E16: =C18 -> 0 | F16: =E18 -> 0 | G16: =F18 -> 0
A17: Direct Material & Expenses | C17: =FinalWorkings!B10 -> 0 | D17: =FinalWorkings!C10 -> 0 | E17: =ROUND(FinalWorkings!D10,-4) -> #DIV/0! | F17: =ROUND(FinalWorkings!E10,-4) -> #DIV/0! | G17: =ROUND(FinalWorkings!F10,-4) -> #DIV/0!
A18: Closing Stock / WIP | C18: =FinalWorkings!B11 -> 0 | D18: =FinalWorkings!C11 -> 0 | E18: =ROUND(FinalWorkings!D11,-3) -> 0 | F18: =ROUND(FinalWorkings!E11,-3) -> 0 | G18: =ROUND(FinalWorkings!F11,-3) -> 0
A19: Operating Expenses | C19: =C16+C17-C18 -> 0 | D19: =D16+D17-D18 -> 0 | E19: =E16+E17-E18 -> #DIV/0! | F19: =F16+F17-F18 -> #DIV/0! | G19: =G16+G17-G18 -> #DIV/0!
A21: Gross Profit | C21: =C12-C19 -> 0 | D21: =D12-D19 -> 0 | E21: =E12-E19 -> #DIV/0! | F21: =F12-F19 -> #DIV/0! | G21: =G12-G19 -> #DIV/0!
A23: Non Operating Income | C23: =wp!C23 -> 0 | D23: =wp!D23 -> 0 | E23: =ROUND(FinalWorkings!D12,-3) -> #DIV/0! | F23: =ROUND(FinalWorkings!E12,-3) -> #DIV/0! | G23: =ROUND(FinalWorkings!F12,-3) -> #DIV/0!
A25: Less :Admintrative & Selling Expenses | B25: Sch 1 | C25: =C86 -> 0 | D25: =D86 -> 0 | E25: =E86 -> #DIV/0! | F25: =F86 -> #DIV/0! | G25: =G86 -> #DIV/0!
A27: EBDIT | C27: =C21+C23-C25 -> 0 | D27: =D21+D23-D25 -> 0 | E27: =E21+E23-E25 -> #DIV/0! | F27: =F21+F23-F25 -> #DIV/0! | G27: =G21+G23-G25 -> #DIV/0!
A29: Less : Depreciation | C29: =wp!C29 -> 0 | D29: =wp!D29 -> 0 | E29: =wp!E29 -> 54948.2 | F29: =wp!F29 -> 49453.38 | G29: =wp!G29 -> 44508.042
A31: EBIT | C31: =C27-C29 -> 0 | D31: =D27-D29 -> 0 | E31: =E27-E29 -> #DIV/0! | F31: =F27-F29 -> #DIV/0! | G31: =G27-G29 -> #DIV/0!
A33: Less: Interest | B33: Sch 2 | C33: =C95 -> 0 | D33: =D95 -> 0 | E33: =E95 -> #DIV/0! | F33: =F95 -> 0 | G33: =G95 -> 0
A35: EBT | C35: =C31-C33 -> 0 | D35: =D31-D33 -> 0 | E35: =E31-E33 -> #DIV/0! | F35: =F31-F33 -> #DIV/0! | G35: =G31-G33 -> #DIV/0!
A39: =A1 -> 0
A40: =A2 -> 0
A41: =A3 -> 0
A43: BALANCE SHEET AS ON
A44: Particulars | B44: Schedules | C44: =C5 -> Audited | D44: =D5 -> Provisional | E44: =E5 -> Estimated | F44: =F5 -> Projected | G44: =G5 -> Projected
C45: =C6 -> 0 | D45: =D6 -> 0 | E45: =E6 -> 0 | F45: =F6 -> 0 | G45: =G6 -> 0
A46: SOURCES OF FUNDS:
A48: Net Capital Including Net Reserves & Surplus | C48: =wp!C46 -> 0 | D48: =wp!D46 -> 0 | E48: =E57-SUM(E49:E56) -> #DIV/0! | F48: =F57-SUM(F49:F56) -> #DIV/0! | G48: =G57-SUM(G49:G56) -> #DIV/0!
A49: (Opening capital + Net profit -Drawings)
A50: TERM LOANS:
A51: Secured and Unsecured Loans | C51: =FinalWorkings!B22 -> 0 | D51: =FinalWorkings!C22 -> 0 | E51: =ROUND(FinalWorkings!D22,-4) -> 0 | F51: =ROUND(FinalWorkings!E22,-4) -> 0 | G51: =ROUND(FinalWorkings!F22,-4) -> 0
A53: CURRENT LIABILITIES:
A54: Bank CC/OD loan | C54: =wp!C52 -> 0 | D54: =wp!D52 -> 0 | E54: =wp!E52 -> #DIV/0! | F54: =wp!F52 -> #DIV/0! | G54: =wp!G52 -> #DIV/0!
A55: Other Current liabilities | C55: =wp!C53 -> 0 | D55: =wp!D53 -> 0 | E55: =ROUND(FinalWorkings!D23,-3) -> 0 | F55: =ROUND(FinalWorkings!E23,-3) -> 0 | G55: =ROUND(FinalWorkings!F23,-3) -> 0
C57: =C70 -> 0 | D57: =D70 -> 549482 | E57: =E70 -> #DIV/0! | F57: =F70 -> #DIV/0! | G57: =G70 -> #DIV/0!
A58: APPLICATION OF FUNDS:
A60: FIXED ASSETS: | C60: =wp!C61 -> 0 | D60: =wp!D61 -> 549482 | E60: =wp!E61 -> 494533.8 | F60: =wp!F61 -> 445080.42 | G60: =wp!G61 -> 400572.38
A62: INVESTMENTS: | C62: =FinalWorkings!B24 -> 0 | D62: =FinalWorkings!C24 -> 0 | E62: =ROUND(FinalWorkings!D24,-4) -> 0 | F62: =ROUND(FinalWorkings!E24,-4) -> 0 | G62: =ROUND(FinalWorkings!F24,-4) -> 0
...

Sheet RATIO
A1: =Assumptions.1!I3 -> 0
A2: =Assumptions.1!I5 -> 0
A3: =Assumptions.1!I6 -> 0
A5: RATIO ANALYSIS
A7: A . CURRENT RATIO
E8: IDEAL RATIO > 1.33
A9: Particulars | C9: =C99 -> 0 | D9: =D99 -> 0 | E9: =E99 -> 0 | F9: =F99 -> 0 | G9: =G99 -> 0
A11: Current Assets / Current Liabilities | C11: =C13/C14 -> #DIV/0! | D11: =D13/D14 -> #DIV/0! | E11: =E13/E14 -> #DIV/0! | F11: =F13/F14 -> #DIV/0! | G11: =G13/G14 -> #DIV/0!
A13: Current Assets | C13: =SUM(PLBS!C65:C68) -> 0 | D13: =SUM(PLBS!D65:D68) -> 0 | E13: =SUM(PLBS!E65:E68) -> #DIV/0! | F13: =SUM(PLBS!F65:F68) -> #DIV/0! | G13: =SUM(PLBS!G65:G68) -> #DIV/0!
A14: Current Liabilities | C14: =SUM(PLBS!C54:C56) -> 0 | D14: =SUM(PLBS!D54:D56) -> 0 | E14: =SUM(PLBS!E54:E56) -> #DIV/0! | F14: =SUM(PLBS!F54:F56) -> #DIV/0! | G14: =SUM(PLBS!G54:G56) -> #DIV/0!
C15: =C13-C14 -> 0 | D15: =D13-D14 -> 0 | E15: =E13-E14 -> #DIV/0! | F15: =F13-F14 -> #DIV/0! | G15: =G13-G14 -> #DIV/0!
A16: NOTES : Indicates Ability to repay short term commitments promptly .
A18: B . DEBTORS TURNOVER RATIO
A19: Particulars | C19: =C75 -> 0 | D19: =D75 -> 0 | E19: =E75 -> 0 | F19: =F75 -> 0 | G19: =G75 -> 0
A21: Credit sales / Average debtors | C21: =PLBS!C12/PLBS!C67 -> #DIV/0! | D21: =PLBS!D12/PLBS!D67 -> #DIV/0! | E21: =PLBS!E12/PLBS!E67 -> #DIV/0! | F21: =PLBS!F12/PLBS!F67 -> #DIV/0! | G21: =PLBS!G12/PLBS!G67 -> #DIV/0!
A22: *Sales assumed as credit sales
A24: NOTES : It indicates velocity of debt collection. Higer the DTR indicates good vellocity of debt
A25: collection.
A27: DEBTORS COLLECTION PERIOD : | C27: =B30/C21 -> #DIV/0! | D27: =B30/D21 -> #DIV/0! | E27: =B30/E21 -> #DIV/0! | F27: =B30/F21 -> #DIV/0! | G27: =B30/G21 -> #DIV/0!
A28: (No of days/debtor turnover ratio)
A30: * No. of Days Assumed as | B30: 365
A33: C . GROSS PROFIT RATIO
A35: Particulars | C35: =C88 -> 0 | D35: =D88 -> 0 | E35: =E88 -> 0 | F35: =F88 -> 0 | G35: =G88 -> 0
A37: Gross profit / Sales * 100 | C37: =PLBS!C21/PLBS!C12*100 -> #DIV/0! | D37: =PLBS!D21/PLBS!D12*100 -> #DIV/0! | E37: =PLBS!E21/PLBS!E12*100 -> #DIV/0! | F37: =PLBS!F21/PLBS!F12*100 -> #DIV/0! | G37: =PLBS!G21/PLBS!G12*100 -> #DIV/0!
A39: NOTES : Indicates Basic Profitability of the Business.
A47: D . NETPROFIT RATIO
A49: Particulars | C49: =C35 -> 0 | D49: =D35 -> 0 | E49: =E35 -> 0 | F49: =F35 -> 0 | G49: =G35 -> 0
A51: Netprofit / Sales * 100 | C51: =PLBS!C35/PLBS!C12*100 -> #DIV/0! | D51: =PLBS!D35/PLBS!D12*100 -> #DIV/0! | E51: =PLBS!E35/PLBS!E12*100 -> #DIV/0! | F51: =PLBS!F35/PLBS!F12*100 -> #DIV/0! | G51: =PLBS!G35/PLBS!G12*100 -> #DIV/0!
A53: NOTES : Indicates overall Profitability of the Business.
A55: E . TOTAL OUTSIDE LIABILITIES TO TOTAL NETWORTH RATIO :
A57: Particulars | C57: =C9 -> 0 | D57: =D9 -> 0 | E57: =E9 -> 0 | F57: =F9 -> 0 | G57: =G9 -> 0
A59: TOL / TW | C59: =SUM(PLBS!C50:C56)/PLBS!C48 -> #DIV/0! | D59: =SUM(PLBS!D50:D56)/PLBS!D48 -> #DIV/0! | E59: =SUM(PLBS!E50:E56)/PLBS!E48 -> #DIV/0! | F59: =SUM(PLBS!F50:F56)/PLBS!F48 -> #DIV/0! | G59: =SUM(PLBS!G50:G56)/PLBS!G48 -> #DIV/0!
A61: NOTES : Indicates Extent of own funds used in business.
A63: F . WORKING CAPITAL TURNOVER RATIO :
A65: Particulars | C65: =C49 -> 0 | D65: =D49 -> 0 | E65: =E49 -> 0 | F65: =F49 -> 0 | G65: =G49 -> 0
A67: Networking capital (CA - CL) | C67: =C13-C14 -> 0 | D67: =D13-D14 -> 0 | E67: =E13-E14 -> #DIV/0! | F67: =F13-F14 -> #DIV/0! | G67: =G13-G14 -> #DIV/0!
A69: Sales / Networking Capital | C69: =PLBS!C10/RATIO!C67 -> #DIV/0! | D69: =PLBS!D10/RATIO!D67 -> #DIV/0! | E69: =PLBS!E10/RATIO!E67 -> #DIV/0! | F69: =PLBS!F10/RATIO!F67 -> #DIV/0! | G69: =PLBS!G10/RATIO!G67 -> #DIV/0!
A71: NOTE : Ability to generate sales per Rupee of Working Capital
A73: G . STOCK TURNOVER RATIO
A75: Particulars | C75: =C65 -> 0 | D75: =D65 -> 0 | E75: =E65 -> 0 | F75: =F65 -> 0 | G75: =G65 -> 0
...

Sheet MPBF 
A1: =Assumptions.1!I3 -> 0
A2: =Assumptions.1!I5 -> 0
A3: =Assumptions.1!I6 -> 0
A5: CALCULATION OF MAXIMUM PERMISSIBLE BANK FINANCE
A7: MPBF - Method 1 - 25%(Working Capital Gap)
A8: Particulars | B8: =wp!E5 -> Estimated | C8: =wp!F5 -> Projected | D8: =wp!G5 -> Projected
B9: =wp!E6 -> 0 | C9: =wp!F6 -> 0 | D9: =wp!G6 -> 0
A11: 1. Total current assets | B11: =SUM(PLBS!E64:E69) -> #DIV/0! | C11: =SUM(PLBS!F64:F69) -> #DIV/0! | D11: =SUM(PLBS!G64:G69) -> #DIV/0!
A13: 2. Other current liabilities | B13: =RATIO!E14-PLBS!E54 -> #DIV/0! | C13: =RATIO!F14-PLBS!F54 -> #DIV/0! | D13: =RATIO!G14-PLBS!G54 -> #DIV/0!
A14: (Other than bank borrowings )
A16: 3. Working capital gap | B16: =+B11-B13 -> #DIV/0! | C16: =+C11-C13 -> #DIV/0! | D16: =+D11-D13 -> #DIV/0!
A18: 4. Min. stipulated Networking capital
A19: (25% of WCG excluding export | B19: =+B16*0.25 -> #DIV/0! | C19: =+C16*0.25 -> #DIV/0! | D19: =+D16*0.25 -> #DIV/0!
A20: receivables)
A22: 5. Actual/projected net working capital | B22: =RATIO!E15 -> #DIV/0! | C22: =RATIO!F15 -> #DIV/0! | D22: =RATIO!G15 -> #DIV/0!
A24: 6.Item 3 minus item 4 | B24: =+B16-B19 -> #DIV/0! | C24: =+C16-C19 -> #DIV/0! | D24: =+D16-D19 -> #DIV/0!
A26: 7.Item 3 minus item 5 | B26: =B16-B22 -> #DIV/0! | C26: =C16-C22 -> #DIV/0! | D26: =D16-D22 -> #DIV/0!
A28: 8. Maximum permissible bank | B28: =IF(B24<B26,B24,B26) -> #DIV/0! | C28: =IF(C24<C26,C24,C26) -> #DIV/0! | D28: =IF(D24<D26,D24,D26) -> #DIV/0!
A29: finance(lower of 6 or 7 )
A43: =A5 -> CALCULATION OF MAXIMUM PERMISSIBLE BANK FINANCE
A45: MPBF - Method 2 - 25%(Current Assets)
A46: Particulars | B46: =B8 -> Estimated | C46: =C8 -> Projected | D46: =D8 -> Projected
B47: =B9 -> 0 | C47: =C9 -> 0 | D47: =D9 -> 0
A49: 1. Total current assets | B49: =B11 -> #DIV/0! | C49: =C11 -> #DIV/0! | D49: =D11 -> #DIV/0!
A51: 2. Other current liabilities | B51: =B13 -> #DIV/0! | C51: =C13 -> #DIV/0! | D51: =D13 -> #DIV/0!
A52: (Other than bank borrowings )
A54: 3. Working capital gap | B54: =+B49-B51 -> #DIV/0! | C54: =+C49-C51 -> #DIV/0! | D54: =+D49-D51 -> #DIV/0!
A56: 4. Min. stipulated Networking capital
A57: (25% of Current Assets) | B57: =25/100*B49 -> #DIV/0! | C57: =25/100*C49 -> #DIV/0! | D57: =25/100*D49 -> #DIV/0!
A59: 5. Actual/projected net working capital | B59: =B22 -> #DIV/0! | C59: =C22 -> #DIV/0! | D59: =D22 -> #DIV/0!
A61: 6.Item 3 minus item 4 | B61: =+B54-B57 -> #DIV/0! | C61: =+C54-C57 -> #DIV/0! | D61: =+D54-D57 -> #DIV/0!
A63: 7.Item 3 minus item 5 | B63: =B54-B59 -> #DIV/0! | C63: =C54-C59 -> #DIV/0! | D63: =D54-D59 -> #DIV/0!
A65: 8. Maximum permissible bank | B65: =IF(B61<B63,B61,B63) -> #DIV/0! | C65: =IF(C61<C63,C61,C63) -> #DIV/0! | D65: =IF(D61<D63,D61,D63) -> #DIV/0!
A66: finance(lower of 6 or 7 )

Sheet nayak
A2: =Assumptions.1!I3 -> 0
A3: =Assumptions.1!I5 -> 0
A4: =Assumptions.1!I6 -> 0
A6: WORKING CAPITAL ASSESSMENT - TURNOVER METHOD
A8: NAYAK COMMITTEE RECOMONDATIONS
A10: PARTICULARS | C10: ='MPBF '!B8 -> Estimated | D10: ='MPBF '!C8 -> Projected | E10: ='MPBF '!D8 -> Projected
C11: ='MPBF '!B9 -> 0 | D11: ='MPBF '!C9 -> 0 | E11: ='MPBF '!D9 -> 0
A13: Turnover | C13: =PLBS!E12 -> #DIV/0! | D13: =PLBS!F12 -> #DIV/0! | E13: =PLBS!G12 -> #DIV/0!
A15: Working Capital Requirement | C15: =C13*25/100 -> #DIV/0! | D15: =D13*25/100 -> #DIV/0! | E15: =E13*25/100 -> #DIV/0!
A16: (25% of Turnover)
A18: Minimum Working Capital Limit | C18: =C15*80/100 -> #DIV/0! | D18: =D15*80/100 -> #DIV/0! | E18: =E15*80/100 -> #DIV/0!
A19: (80% of Working Capital Requirment)
A21: Drawing Power | C21: =Assumptions.1!I11 -> 0 | D21: =C21 -> 0 | E21: =D21 -> 0
A23: Maximum Bank CC Loan | C23: =IF(C18<C21,C18,C21) -> #DIV/0! | D23: =IF(D18<D21,D18,D21) -> #DIV/0! | E23: =IF(E18<E21,E18,E21) -> #DIV/0!
A27: Notes :
A28: 1. Maximum Working capital Limit Must not exceed Drawing power .
A29: 2. Four Operating cycles per Annum is Assumed.

Sheet Depsch
A1: =Assumptions.1!I3 -> 0
A2: =Assumptions.1!I5 -> 0
A3: =Assumptions.1!I6 -> 0
A5: CALCULATION OF DEPRECIATION AS PER INCOME TAX ACT
M7: Rs in lacs
B9: =Assumptions.1!B121 -> Plant and Machinery | C9: =Assumptions.1!B131 -> Service Equipment | D9: =Assumptions.1!B141 -> Shed and Civil works | E9: =Assumptions.1!B151 -> Land | F9: =Assumptions.1!B154 -> Electrical Items | G9: =Assumptions.1!B163 -> Electronic items | H9: =Assumptions.1!B173 -> Furniture and Fittings | I9: =Assumptions.1!B183 -> Vehicles | J9: =Assumptions.1!B193 -> Live stock | K9: =Assumptions.1!B202 -> Other Assets | L9: =Assumptions.1!B212 -> Other Assets (Nil Depreciation)
M11: Total
B12: =Assumptions.1!I105 -> 0.15 | C12: =Assumptions.1!I106 -> 0.15 | D12: =Assumptions.1!I107 -> 0.1 | E12: =Assumptions.1!I108 -> 0 | F12: =Assumptions.1!I110 -> 0.15 | G12: =Assumptions.1!I111 -> 0.15 | H12: =Assumptions.1!I109 -> 0.1 | I12: =Assumptions.1!I112 -> 0.15 | J12: =Assumptions.1!I113 -> 0 | K12: =Assumptions.1!I115 -> 0.1 | L12: =Assumptions.1!I114 -> 0
A15: =wp!D6 -> 0
A16: WDV (31.03.2026) | B16: =Assumptions.1!F121 -> 0 | C16: =Assumptions.1!F131 -> 0 | D16: =Assumptions.1!F141 -> 0 | E16: =Assumptions.1!F151 -> 0 | F16: =Assumptions.1!F154 -> 0 | G16: =Assumptions.1!F163 -> 0 | H16: =Assumptions.1!F173 -> 549482 | I16: =Assumptions.1!F183 -> 0 | J16: =Assumptions.1!F193 -> 0 | K16: =Assumptions.1!F202 -> 0 | L16: =Assumptions.1!F212 -> 0 | M16: =B16+C16+D16+E16+F16+G16+H16+I16+J16+K16+L16 -> 549482
A17: Add Additions | B17: 0 | C17: 0 | D17: 0 | E17: 0 | F17: 0 | G17: 0 | H17: 0 | I17: 0 | J17: 0 | K17: 0 | L17: 0 | M17: =B17+C17+D17+E17+F17+G17+H17+I17+J17+K17+L17 -> 0
A18: Total | B18: =B16+B17 -> 0 | C18: =C16+C17 -> 0 | D18: =D16+D17 -> 0 | E18: =E16+E17 -> 0 | F18: =F16+F17 -> 0 | G18: =G16+G17 -> 0 | H18: =H16+H17 -> 549482 | I18: =I16+I17 -> 0 | ... L18: =L16+L17 -> 0 | M18: =B18+C18+D18+E18+F18+G18+H18+I18+J18+K18+L18 -> 549482
A19: Depreciation | B19: =B18*B12 -> 0 | C19: =C18*C12 -> 0 | D19: =D18*D12 -> 0 | E19: =E18*E12 -> 0 | F19: =F18*F12 -> 0 | G19: =G18*G12 -> 0 | H19: =H18*H12 -> 54948.2 | I19: =I18*I12 -> 0 | ... L19: =L18*L12 -> 0 | M19: =B19+C19+D19+E19+F19+G19+H19+I19+J19+K19+L19 -> 54948.2
A20: WDVat the end of 1st Year | B20: =B18-B19 -> 0 | C20: =C18-C19 -> 0 | D20: =D18-D19 -> 0 | E20: =E18-E19 -> 0 | F20: =F18-F19 -> 0 | G20: =G18-G19 -> 0 | H20: =H18-H19 -> 494533.8 | I20: =I18-I19 -> 0 | ... L20: =L18-L19 -> 0 | M20: =B20+C20+D20+E20+F20+G20+H20+I20+J20+K20+L20 -> 494533.8
A22: =wp!F6 -> 0
A23: WDV | B23: =B20 -> 0 | C23: =C20 -> 0 | D23: =D20 -> 0 | E23: =E20 -> 0 | F23: =F20 -> 0 | G23: =G20 -> 0 | H23: =H20 -> 494533.8 | I23: =I20 -> 0 | ... L23: =L20 -> 0 | M23: =B23+C23+D23+E23+F23+G23+H23+I23+J23+K23+L23 -> 494533.8
A24: Add Additions | B24: 0 | C24: 0 | D24: 0 | E24: 0 | F24: 0 | G24: 0 | H24: 0 | I24: 0 | J24: 0 | K24: 0 | L24: 0 | M24: =B24+C24+D24+E24+F24+G24+H24+I24+J24+K24+L24 -> 0
A25: Total | B25: =B23+B24 -> 0 | C25: =C23+C24 -> 0 | D25: =D23+D24 -> 0 | E25: =E23+E24 -> 0 | F25: =F23+F24 -> 0 | G25: =G23+G24 -> 0 | H25: =H23+H24 -> 494533.8 | I25: =I23+I24 -> 0 | ... L25: =L23+L24 -> 0 | M25: =B25+C25+D25+E25+F25+G25+H25+I25+J25+K25+L25 -> 494533.8
A26: Depreciation | B26: =B25*B12 -> 0 | C26: =C25*C12 -> 0 | D26: =D25*D12 -> 0 | E26: =E25*E12 -> 0 | F26: =F25*F12 -> 0 | G26: =G25*G12 -> 0 | H26: =H25*H12 -> 49453.38 | I26: =I25*I12 -> 0 | ... L26: =L25*L12 -> 0 | M26: =B26+C26+D26+E26+F26+G26+H26+I26+J26+K26+L26 -> 49453.38
A27: WDVat the end of 2nd Year | B27: =B25-B26 -> 0 | C27: =C25-C26 -> 0 | D27: =D25-D26 -> 0 | E27: =E25-E26 -> 0 | F27: =F25-F26 -> 0 | G27: =G25-G26 -> 0 | H27: =H25-H26 -> 445080.42 | I27: =I25-I26 -> 0 | ... L27: =L25-L26 -> 0 | M27: =B27+C27+D27+E27+F27+G27+H27+I27+J27+K27+L27 -> 445080.42
A29: =wp!G6 -> 0
A30: WDV | B30: =B27 -> 0 | C30: =C27 -> 0 | D30: =D27 -> 0 | E30: =E27 -> 0 | F30: =F27 -> 0 | G30: =G27 -> 0 | H30: =H27 -> 445080.42 | I30: =I27 -> 0 | ... L30: =L27 -> 0 | M30: =B30+C30+D30+E30+F30+G30+H30+I30+J30+K30+L30 -> 445080.42
A31: Add Additions | B31: 0 | C31: 0 | D31: 0 | E31: 0 | F31: 0 | G31: 0 | H31: 0 | I31: 0 | J31: 0 | K31: 0 | L31: 0 | M31: =B31+C31+D31+E31+F31+G31+H31+I31+J31+K31+L31 -> 0
A32: Total | B32: =B30+B31 -> 0 | C32: =C30+C31 -> 0 | D32: =D30+D31 -> 0 | E32: =E30+E31 -> 0 | F32: =F30+F31 -> 0 | G32: =G30+G31 -> 0 | H32: =H30+H31 -> 445080.42 | I32: =I30+I31 -> 0 | ... L32: =L30+L31 -> 0 | M32: =B32+C32+D32+E32+F32+G32+H32+I32+J32+K32+L32 -> 445080.42
A33: Depreciation | B33: =B32*B12 -> 0 | C33: =C32*C12 -> 0 | D33: =D32*D12 -> 0 | E33: =E32*E12 -> 0 | F33: =F32*F12 -> 0 | G33: =G32*G12 -> 0 | H33: =H32*H12 -> 44508.042 | I33: =I32*I12 -> 0 | ... L33: =L32*L12 -> 0 | M33: =B33+C33+D33+E33+F33+G33+H33+I33+J33+K33+L33 -> 44508.042
A34: WDVat the end of 3rd Year | B34: =B32-B33 -> 0 | C34: =C32-C33 -> 0 | D34: =D32-D33 -> 0 | E34: =E32-E33 -> 0 | F34: =F32-F33 -> 0 | G34: =G32-G33 -> 0 | H34: =H32-H33 -> 400572.38 | I34: =I32-I33 -> 0 | ... L34: =L32-L33 -> 0 | M34: =B34+C34+D34+E34+F34+G34+H34+I34+J34+K34+L34 -> 400572.38
A36: =wp!F6 -> 0
A37: WDV | B37: =B34 -> 0 | C37: =C34 -> 0 | D37: =D34 -> 0 | E37: =E34 -> 0 | F37: =F34 -> 0 | G37: =G34 -> 0 | H37: =H34 -> 400572.38 | I37: =I34 -> 0 | ... L37: =L34 -> 0 | M37: =B37+C37+D37+E37+F37+G37+H37+I37+J37+K37+L37 -> 400572.38
A38: Add Additions | B38: 0 | C38: 0 | D38: 0 | E38: 0 | F38: 0 | G38: 0 | H38: 0 | I38: 0 | J38: 0 | K38: 0 | L38: 0 | M38: =B38+C38+D38+E38+F38+G38+H38+I38+J38+K38+L38 -> 0
A39: Total | B39: =B37+B38 -> 0 | C39: =C37+C38 -> 0 | D39: =D37+D38 -> 0 | E39: =E37+E38 -> 0 | F39: =F37+F38 -> 0 | G39: =G37+G38 -> 0 | H39: =H37+H38 -> 400572.38 | I39: =I37+I38 -> 0 | ... L39: =L37+L38 -> 0 | M39: =B39+C39+D39+E39+F39+G39+H39+I39+J39+K39+L39 -> 400572.38
A40: Depreciation | B40: =B39*B12 -> 0 | C40: =C39*C12 -> 0 | D40: =D39*D12 -> 0 | E40: =E39*E12 -> 0 | F40: =F39*F12 -> 0 | G40: =G39*G12 -> 0 | H40: =H39*H12 -> 40057.238 | I40: =I39*I12 -> 0 | ... L40: =L39*L12 -> 0 | M40: =B40+C40+D40+E40+F40+G40+H40+I40+J40+K40+L40 -> 40057.238
A41: WDVat the end of 4th Year | B41: =B39-B40 -> 0 | C41: =C39-C40 -> 0 | D41: =D39-D40 -> 0 | E41: =E39-E40 -> 0 | F41: =F39-F40 -> 0 | G41: =G39-G40 -> 0 | H41: =H39-H40 -> 360515.14 | I41: =I39-I40 -> 0 | ... L41: =L39-L40 -> 0 | M41: =B41+C41+D41+E41+F41+G41+H41+I41+J41+K41+L41 -> 360515.14
A43: =wp!G6 -> 0
A44: WDV | B44: =B41 -> 0 | C44: =C41 -> 0 | D44: =D41 -> 0 | E44: =E41 -> 0 | F44: =F41 -> 0 | G44: =G41 -> 0 | H44: =H41 -> 360515.14 | I44: =I41 -> 0 | ... L44: =L41 -> 0 | M44: =B44+C44+D44+E44+F44+G44+H44+I44+J44+K44+L44 -> 360515.14
A45: Add Additions | B45: 0 | C45: 0 | D45: 0 | E45: 0 | F45: 0 | G45: 0 | H45: 0 | I45: 0 | J45: 0 | K45: 0 | L45: 0 | M45: =B45+C45+D45+E45+F45+G45+H45+I45+J45+K45+L45 -> 0
A46: Total | B46: =B44+B45 -> 0 | C46: =C44+C45 -> 0 | D46: =D44+D45 -> 0 | E46: =E44+E45 -> 0 | F46: =F44+F45 -> 0 | G46: =G44+G45 -> 0 | H46: =H44+H45 -> 360515.14 | I46: =I44+I45 -> 0 | ... L46: =L44+L45 -> 0 | M46: =B46+C46+D46+E46+F46+G46+H46+I46+J46+K46+L46 -> 360515.14
A47: Depreciation | B47: =B46*B12 -> 0 | C47: =C46*C12 -> 0 | D47: =D46*D12 -> 0 | E47: =E46*E12 -> 0 | F47: =F46*F12 -> 0 | G47: =G46*G12 -> 0 | H47: =H46*H12 -> 36051.514 | I47: =I46*I12 -> 0 | ... L47: =L46*L12 -> 0 | M47: =B47+C47+D47+E47+F47+G47+H47+I47+J47+K47+L47 -> 36051.514
A48: WDVat the end of 5th Year | B48: =B46-B47 -> 0 | C48: =C46-C47 -> 0 | D48: =D46-D47 -> 0 | E48: =E46-E47 -> 0 | F48: =F46-F47 -> 0 | G48: =G46-G47 -> 0 | H48: =H46-H47 -> 324463.63 | I48: =I46-I47 -> 0 | ... L48: =L46-L47 -> 0 | M48: =B48+C48+D48+E48+F48+G48+H48+I48+J48+K48+L48 -> 324463.63
