Workbook

Sheet Assumptions.1
B3: Sections | C3: Question | D3: Question type | E3: Editable | F3: Options | G3: Min - Max | H3: Details which are required to be given by customer | I3: Answers
B4: General Information | C4: Name of Firm | D4: Manual Entry | E4: No
C5: Status of Concern | D5: Dropdown options to be provided | E5: No | F5: Soleproprietorship,Partnership,LLP,Company
C6: Proprietor / MP / MD Name | D6: Manual Entry | E6: No
C7: Firm address | D7: Manual Entry | E7: No
C8: Sector | D8: Drop Down options to be provided | E8: No | F8: Manufacturing sector / Service sector (with stock) / Trading sector
C9: Nature of Business | D9: Manual Entry | E9: No
B11: Means of Finance | C11: Do you have working capital limit at present ? | D11: Dropdown Options to be provided | E11: No | F11: Yes,No
C12: Working capital Loan requirement | D12: Manual Entry | E12: Yes | J12: Loan amount
C13: Working capital loan interest | D13: Manual Entry | E13: Yes | I13: =H13*1/100 -> 0 | J13: per annum | K13: =12% -> 0.12
C14: processing fees (Including GST) | D14: Manual Entry | E14: Yes | I14: =(H14+H14*18/100)*1/100 -> 0 | K14: =1.18% -> 0.0118
C15: Working capital (% of Turnover) | D15: Manual Entry | E15: Yes | G15: 15% or more than 15% | I15: =H15*1/100 -> 0 | J15: of Turnover | K15: =20% -> 0.2
B17: Financial years | C17: 1st Financial year | D17: Dropdown options to be provided | E17: Yes | F17: 2024 - 25 to provide 10 years with Start Month to End Month | J17: Estimated
C18: 2nd Financial year | D18: Dropdown options to be provided | E18: Yes | F18: 2024 - 25 to provide 10 years with Start Month to End Month | J18: Projected
C19: 3rd Financial year | D19: Dropdown options to be provided | E19: Yes | F19: 2024 - 25 to provide 10 years with Start Month to End Month | J19: Projected
C20: 4th Financial year | D20: Dropdown options to be provided | E20: Yes | F20: 2024 - 25 to provide 10 years with Start Month to End Month | J20: Projected
C21: 5th Financial year | D21: Dropdown options to be provided | E21: Yes | F21: 2024 - 25 to provide 10 years with Start Month to End Month | J21: Projected
I22: No of Employees | J22: Salary per month per employee
B23: Salaries and Wages | C23: Skilled | D23: Manual Entry | E23: Yes
C24: Unskilled | D24: Manual Entry | E24: Yes
A25: STEP 1 | C25: Semi Skilled | D25: Manual Entry | E25: Yes
B27: Assumptions | C27: Salaries and Wages per month | D27: Auto generated | E27: NA | I27: =I25*J25+I24*J24+I23*J23 -> 0
C28: Salaries Increment | D28: Manual Entry | E28: Yes | I28: =1+1*H28/100 -> 1 | J28: of previous year
C29: Rent per month | D29: Manual Entry | E29: Yes | J29: per month
C30: Rental increment | D30: Manual Entry | E30: Yes | I30: =1+1*H30*1/100 -> 1 | J30: every year
C31: Power charges per month | D31: Manual Entry | E31: Yes | J31: per month
C32: Power charges increament | D32: Manual Entry | E32: Yes | I32: =1+1*H32*1/100 -> 1 | J32: of previous year power charges
C33: Sales growth | D33: Manual Entry | E33: Yes | I33: =1+1*H33*1/100 -> 1 | J33: of previous year
C34: No of Months Interest will be paid in first year | D34: Manual Entry | E34: Yes | J34: Months
C35: No of Months Turnover will be done in first year | D35: Manual Entry | E35: Yes | J35: Months
F36: Depreciation rates | I36: During the first financial year
B37: Fixed Assets Schedule | C37: Plant and Machinery | D37: Manual Entry | E37: Yes | F37: 0.15 | I37: =F99 -> 0
C38: Service Equipment | D38: Manual Entry | E38: Yes | F38: 0.15 | I38: =F109 -> 0
C39: Shed and Civil works | D39: Manual Entry | E39: Yes | F39: 0.1 | I39: =F119 -> 0
C40: Land | D40: Manual Entry | E40: Yes | F40: 0 | I40: =F129 -> 0
C41: Electrical Items | D41: Manual Entry | E41: Yes | F41: 0.15 | I41: =F132 -> 0
C42: Electronic Items | D42: Manual Entry | E42: Yes | F42: 0.15 | I42: =F141 -> 0
C43: Vehicles | D43: Manual Entry | E43: Yes | F43: 0.15 | I43: =F151 -> 0
C44: Live stock | D44: Manual Entry | E44: Yes | F44: 0 | I44: =F161 -> 0
C45: Other Assets | D45: Manual Entry | E45: Yes | F45: 0 | I45: =F180 -> 0
...

Sheet wc
A3: STEP 2 : BACK GROUND CALCULATION . NOT TO BE VISIBLE TO CUSTOMER
A4: WORKINGS FOR PROFIT AND LOSS ACCOUNT
A5: PARTICULARS | B5: Schedules | C5: =Assumptions.1!J17 -> Estimated | D5: =Assumptions.1!J18 -> Projected | E5: =Assumptions.1!J19 -> Projected | F5: =Assumptions.1!J20 -> Projected | G5: =Assumptions.1!J21 -> Projected
C6: =Assumptions.1!I17 -> 0 | D6: =Assumptions.1!I18 -> 0 | E6: =Assumptions.1!I19 -> 0 | F6: =Assumptions.1!I20 -> 0 | G6: =Assumptions.1!I21 -> 0
A8: Turnover | C8: =Assumptions.1!I12*Assumptions.1!F71*Assumptions.1!I35/Assumptions.1!F69 -> #DIV/0! | D8: =Assumptions.1!I12*Assumptions.1!F71*Assumptions.1!I33 -> #DIV/0! | E8: =D8*Assumptions.1!I33 -> #DIV/0! | F8: =E8*Assumptions.1!I33 -> #DIV/0! | G8: =F8*Assumptions.1!I33 -> #DIV/0! | I8: =Assumptions.1!I12*Assumptions.1!F71*Assumptions.1!I33 -> #DIV/0!
A10: Opening Stock | C10: =Assumptions.1!F77 -> 0 | D10: =C12 -> 0 | E10: =D12 -> 0 | F10: =E12 -> 0 | G10: =F12 -> 0
A11: Direct Material & Expenses | C11: =C13-C10+C12 -> #DIV/0! | D11: =D13-D10+D12 -> #DIV/0! | E11: =E13-E10+E12 -> #DIV/0! | F11: =F13-F10+F12 -> #DIV/0! | G11: =G13-G10+G12 -> #DIV/0!
A12: Closing Stock | C12: =Assumptions.1!I12*Assumptions.1!F78 -> 0 | D12: =Assumptions.1!I12*Assumptions.1!F79 -> 0 | E12: =D12*Assumptions.1!F80 -> 0 | F12: =E12*Assumptions.1!F80 -> 0 | G12: =F12*Assumptions.1!F80 -> 0
A13: Operating Expenses | C13: =C8-C15 -> #DIV/0! | D13: =D8-D15 -> #DIV/0! | E13: =E8-E15 -> #DIV/0! | F13: =F8-F15 -> #DIV/0! | G13: =G8-G15 -> #DIV/0!
A15: Gross Profit (A) | C15: =C8*Assumptions.1!F57 -> #DIV/0! | D15: =D8*Assumptions.1!F58 -> #DIV/0! | E15: =E8*Assumptions.1!F59 -> #DIV/0! | F15: =F8*Assumptions.1!F60 -> #DIV/0! | G15: =G8*Assumptions.1!F61 -> #DIV/0!
A17: Non Operating Income (B) | C17: =Assumptions.1!F72*wc!C8 -> #DIV/0! | D17: =Assumptions.1!F72*wc!D8 -> #DIV/0! | E17: =Assumptions.1!F72*wc!E8 -> #DIV/0! | F17: =F8*Assumptions.1!F72 -> #DIV/0! | G17: =G8*Assumptions.1!F72 -> #DIV/0!
A19: Adm & Selling Expenses ( C ) | C19: =Assumptions.1!F76*wc!C8 -> #DIV/0! | D19: =Assumptions.1!F76*wc!D8 -> #DIV/0! | E19: =Assumptions.1!F76*wc!E8 -> #DIV/0! | F19: =F8*Assumptions.1!F76 -> #DIV/0! | G19: =G8*Assumptions.1!F76 -> #DIV/0!
A21: EBDIT(D=A+B-C) | C21: =C15+C17-C19 -> #DIV/0! | D21: =D15+D17-D19 -> #DIV/0! | E21: =E15+E17-E19 -> #DIV/0! | F21: =F15+F17-F19 -> #DIV/0! | G21: =G15+G17-G19 -> #DIV/0!
A23: Less : Depreciation (E) | C23: =Depsch!N17 -> 0 | D23: =Depsch!N24 -> 0 | E23: =Depsch!N31 -> 0 | F23: =Depsch!N38 -> 0 | G23: =Depsch!N45 -> 0
A25: EBIT (F = D - E) | C25: =C21-C23 -> #DIV/0! | D25: =D21-D23 -> #DIV/0! | E25: =E21-E23 -> #DIV/0! | F25: =F21-F23 -> #DIV/0! | G25: =G21-G23 -> #DIV/0!
A27: Less: Interest (G) | C27: =Assumptions.1!I12*Assumptions.1!I13*Assumptions.1!I35/Assumptions.1!F69 -> 0 | D27: =Assumptions.1!I12*Assumptions.1!I13*Assumptions.1!F69/Assumptions.1!F69 -> 0 | E27: =D27*Assumptions.1!F70 -> 0 | F27: =E27*Assumptions.1!F70 -> 0 | G27: =F27*Assumptions.1!F70 -> 0
A29: EBT (H=F-G) | C29: =C25-C27 -> #DIV/0! | D29: =D25-D27 -> #DIV/0! | E29: =E25-E27 -> #DIV/0! | F29: =F25-F27 -> #DIV/0! | G29: =G25-G27 -> #DIV/0!
C30: When ever editing is done , this totally must be calculated automatically
A31: WORKINGS FOR BALANCE SHEET
A32: Particulars | B32: Schedules | C32: =C5 -> Estimated | D32: =D5 -> Projected | E32: =D32 -> Projected | F32: =E32 -> Projected | G32: =F32 -> Projected
C33: =C6 -> 0 | D33: =D6 -> 0 | E33: =E6 -> 0 | F33: =F6 -> 0 | G33: =G6 -> 0
A34: SOURCES OF FUNDS:
A36: Net Capital | C36: =C58-SUM(C37:C41) -> #DIV/0! | D36: =D58-SUM(D37:D41) -> #DIV/0! | E36: =E58-SUM(E37:E41) -> #DIV/0! | F36: =F58-SUM(F37:F41) -> #DIV/0! | G36: =G58-SUM(G37:G41) -> #DIV/0!
A37: (Opening capital + Net profit -Drawings)
A38: CURRENT LIABILITIES:
A39: Bank CC/OD Loan | C39: =IF(C83<C78,C83,Assumptions.1!I12) -> #DIV/0! | D39: =IF(D83<D78,D83,Assumptions.1!I12) -> #DIV/0! | E39: =IF(E83<E78,E83,E78) -> #DIV/0! | F39: =IF(F83<F78,F83,F78) -> #DIV/0! | G39: =IF(G83<G78,G83,G78) -> #DIV/0!
A40: Other Current Liabilities | C40: 0 | D40: 0 | E40: 0 | F40: 0 | G40: 0
C42: =C58 -> #DIV/0! | D42: =D58 -> #DIV/0! | E42: =SUM(E36:E41) -> #DIV/0! | F42: =SUM(F36:F41) -> #DIV/0! | G42: =SUM(G36:G41) -> #DIV/0!
C45: When ever editing is done , this totally must be calculated automatically
A46: APPLICATION OF FUNDS:
A48: FIXED ASSETS: | C48: =Depsch!N18 -> 0 | D48: =Depsch!N25 -> 0 | E48: =Depsch!N32 -> 0 | F48: =Depsch!N39 -> 0 | G48: =Depsch!N46 -> 0
A50: NON CURRENT ASSETS:
A52: CURRENT ASSETS:
A53: =A12 -> Closing Stock | C53: =C12 -> 0 | D53: =D12 -> 0 | E53: =E12 -> 0 | F53: =F12 -> 0 | G53: =G12 -> 0
A54: Debtors /Recievables | C54: =C8*Assumptions.1!F63 -> #DIV/0! | D54: =D8*Assumptions.1!F64 -> #DIV/0! | E54: =E8*Assumptions.1!F65 -> #DIV/0! | F54: =F8*Assumptions.1!F66 -> #DIV/0! | G54: =G8*Assumptions.1!F67 -> #DIV/0!
A55: Other Current Assets | C55: 0 | D55: 0 | E55: 0 | F55: 0 | G55: 0
A56: Cash and Cash Equivalents | C56: =Assumptions.1!F51*wc!C39 -> #DIV/0! | D56: =Assumptions.1!F52*wc!D39 -> #DIV/0! | E56: =Assumptions.1!F53*wc!E39 -> #DIV/0! | F56: =Assumptions.1!F54*wc!F39 -> #DIV/0! | G56: =Assumptions.1!F55*wc!G39 -> #DIV/0!
C58: =SUM(C48:C56) -> #DIV/0! | D58: =SUM(D48:D56) -> #DIV/0! | E58: =SUM(E47:E57) -> #DIV/0! | F58: =SUM(F47:F57) -> #DIV/0! | G58: =SUM(G47:G57) -> #DIV/0!
C59: When ever editing is done , this totally must be calculated automatically
A61: WORKINGS FOR ADMINSTRATIVE AND SELLING EXPENSE
...

Sheet FinalWorkings
A3: Step 3 : Display to Customer for Editing
A4: Financials and Ratios at a Glance
A5: PARTICULARS | C5: =Assumptions.1!J17 -> Estimated | D5: =Assumptions.1!J18 -> Projected | E5: =Assumptions.1!J19 -> Projected | F5: =Assumptions.1!J20 -> Projected | G5: =Assumptions.1!J21 -> Projected
C6: =Assumptions.1!I17 -> 0 | D6: =Assumptions.1!I18 -> 0 | E6: =Assumptions.1!I19 -> 0 | F6: =Assumptions.1!I20 -> 0 | G6: =Assumptions.1!I21 -> 0
C7: All Items Editable | D7: All Items Editable | E7: All Items Editable | F7: All Items Editable | G7: All Items Editable
A8: Profit and Loss Items at a Glance :
A9: Gross Revenue / Turnover | C9: =wc!C8 -> #DIV/0! | D9: =wc!D8 -> #DIV/0! | E9: =wc!E8 -> #DIV/0! | F9: =wc!F8 -> #DIV/0! | G9: =wc!G8 -> #DIV/0!
A10: Direct Material & Expenses | C10: =wc!C11 -> #DIV/0! | D10: =wc!D11 -> #DIV/0! | E10: =wc!E11 -> #DIV/0! | F10: =wc!F11 -> #DIV/0! | G10: =wc!G11 -> #DIV/0!
A11: Closing Stock / WIP | C11: =wc!C12 -> 0 | D11: =wc!D12 -> 0 | E11: =wc!E12 -> 0 | F11: =wc!F12 -> 0 | G11: =wc!G12 -> 0
A12: Non Operating Income | C12: =wc!C17 -> #DIV/0! | D12: =wc!D17 -> #DIV/0! | E12: =wc!E17 -> #DIV/0! | F12: =wc!F17 -> #DIV/0! | G12: =wc!G17 -> #DIV/0!
A13: Electricity | C13: =wc!C64 -> 0 | D13: =wc!D64 -> 0 | E13: =wc!E64 -> 0 | F13: =wc!F64 -> 0 | G13: =wc!G64 -> 0
A14: Salaries & Wages | C14: =wc!C65 -> 0 | D14: =wc!D65 -> 0 | E14: =wc!E65 -> 0 | F14: =wc!F65 -> 0 | G14: =wc!G65 -> 0
A15: Rent | C15: =wc!C66 -> 0 | D15: =wc!D66 -> 0 | E15: =wc!E66 -> 0 | F15: =wc!F66 -> 0 | G15: =wc!G66 -> 0
A16: Miscellenious expenses | C16: =wc!C68 -> #DIV/0! | D16: =wc!D68 -> #DIV/0! | E16: =wc!E68 -> #DIV/0! | F16: =wc!F68 -> #DIV/0! | G16: =wc!G68 -> #DIV/0!
A17: Off Admin and Marketing expenses | C17: =wc!C69 -> #DIV/0! | D17: =wc!D69 -> #DIV/0! | E17: =wc!E69 -> #DIV/0! | F17: =wc!F69 -> #DIV/0! | G17: =wc!G69 -> #DIV/0!
A18: Interest on Working capital Loan | C18: =wc!C27 -> 0 | D18: =wc!D27 -> 0 | E18: =wc!E27 -> 0 | F18: =wc!F27 -> 0 | G18: =wc!G27 -> 0
A19: Earnings Before Tax (Not Editable) | C19: =plbs!C35 -> #DIV/0! | D19: =plbs!D35 -> #DIV/0! | E19: =plbs!E35 -> #DIV/0! | F19: =plbs!F35 -> #DIV/0! | G19: =plbs!G35 -> #DIV/0!
A21: Balance Sheet Items at a Glance:
A22: Other Current Liabilities | C22: =wc!C40 -> 0 | D22: =wc!D40 -> 0 | E22: =wc!E40 -> 0 | F22: =wc!F40 -> 0 | G22: =wc!G40 -> 0
A23: Debtors /Recievables | C23: =wc!C54 -> #DIV/0! | D23: =wc!D54 -> #DIV/0! | E23: =wc!E54 -> #DIV/0! | F23: =wc!F54 -> #DIV/0! | G23: =wc!G54 -> #DIV/0!
A24: NON CURRENT ASSETS: | C24: =SUM(Depsch!C18:I18) -> 0 | D24: =SUM(Depsch!C25:I25) -> 0 | E24: =SUM(Depsch!C32:I32) -> 0 | F24: =SUM(Depsch!C39:I39) -> 0 | G24: =SUM(Depsch!C46:I46) -> 0
A25: Other Current Assets | C25: =wc!C55 -> 0 | D25: =wc!D55 -> 0 | E25: =wc!E55 -> 0 | F25: =wc!F55 -> 0 | G25: =wc!G55 -> 0
A26: Cash and Cash Equivalents | C26: =wc!C56 -> #DIV/0! | D26: =wc!D56 -> #DIV/0! | E26: =wc!E56 -> #DIV/0! | F26: =wc!F56 -> #DIV/0! | G26: =wc!G56 -> #DIV/0!
A28: RATIO ANALYSIS at a Glance: (Not Editable but displayed)
A29: Gross profit ratio (%) | C29: =IFERROR(RATIO!C36, "N/A") -> N/A | D29: =IFERROR(RATIO!D36, "N/A") -> N/A | E29: =IFERROR(RATIO!E36, "N/A") -> N/A | F29: =IFERROR(RATIO!F36, "N/A") -> N/A | G29: =IFERROR(RATIO!G36, "N/A") -> N/A
A30: Net Profit Ratio (%) | C30: =IFERROR(RATIO!C44, "N/A") -> N/A | D30: =IFERROR(RATIO!D44, "N/A") -> N/A | E30: =IFERROR(RATIO!E44, "N/A") -> N/A | F30: =IFERROR(RATIO!F44, "N/A") -> N/A | G30: =IFERROR(RATIO!G44, "N/A") -> N/A
A31: Debtors Turonver Ratio (Days) | C31: =IFERROR(RATIO!C27, "N/A") -> N/A | D31: =IFERROR(RATIO!D27, "N/A") -> N/A | E31: =IFERROR(RATIO!E27, "N/A") -> N/A | F31: =IFERROR(RATIO!F27, "N/A") -> N/A | G31: =IFERROR(RATIO!G27, "N/A") -> N/A
A32: Current Ratio | C32: =IFERROR(RATIO!C11, "N/A") -> N/A | D32: =IFERROR(RATIO!D11, "N/A") -> N/A | E32: =IFERROR(RATIO!E11, "N/A") -> N/A | F32: =IFERROR(RATIO!F11, "N/A") -> N/A | G32: =IFERROR(RATIO!G11, "N/A") -> N/A
A33: Total outside Liabilities to Total Networth | C33: =IFERROR(RATIO!C87, "N/A") -> N/A | D33: =IFERROR(RATIO!D87, "N/A") -> N/A | E33: =IFERROR(RATIO!E87, "N/A") -> N/A | F33: =IFERROR(RATIO!F87, "N/A") -> N/A | G33: =IFERROR(RATIO!G87, "N/A") -> N/A
A35: MAXIMUM PERMISSABLE BANK FINANCE:
A36: Method 1 : Working capital Method | C36: ='MPBF '!B27 -> #DIV/0! | D36: ='MPBF '!C27 -> #DIV/0! | E36: ='MPBF '!D27 -> #DIV/0! | F36: ='MPBF '!E27 -> #DIV/0! | G36: ='MPBF '!F27 -> #DIV/0!
A37: Method 1 : Current Assets Method | C37: ='MPBF '!B50 -> #DIV/0! | D37: ='MPBF '!C50 -> #DIV/0! | E37: ='MPBF '!D50 -> #DIV/0! | F37: ='MPBF '!E50 -> #DIV/0! | G37: ='MPBF '!F50 -> #DIV/0!
A38: Method 3 : Nayak Committee | C38: =Nayak!C23 -> #DIV/0! | D38: =Nayak!D23 -> #DIV/0! | E38: =Nayak!E23 -> #DIV/0! | F38: =Nayak!F23 -> #DIV/0! | G38: =Nayak!G23 -> #DIV/0!

Sheet Coverpage
D6: PROJECTIONS AND ESTIMATIONS
E8: OF
D9: =Assumptions.1!I4 -> 0
D12: =Assumptions.1!I6 -> 0
D16: =Assumptions.1!I9 -> 0
D20: =Assumptions.1!I7 -> 0
D24: Working (CC) Capital Loan | H24: =Assumptions.1!I12 -> 0
E28: PREPARED BY
D30: FINVOICE OPEN BUSINESS SOLUTIONS LLP
D31: MSME & DPR Consultants
D32: Contact : 9618221011

Sheet plbs
A1: =Assumptions.1!I4 -> 0
A2: =Assumptions.1!I6 -> 0
A3: =Assumptions.1!I7 -> 0
A4: TRADING, PROFIT & LOSS ACCOUNT FOR YEAR ENDED
A5: PARTICULARS | B5: Schedules | C5: =Assumptions.1!J17 -> Estimated | D5: =Assumptions.1!J18 -> Projected | E5: =Assumptions.1!J19 -> Projected | F5: =Assumptions.1!J20 -> Projected | G5: =Assumptions.1!J21 -> Projected
C6: =Assumptions.1!I17 -> 0 | D6: =Assumptions.1!I18 -> 0 | E6: =Assumptions.1!I19 -> 0 | F6: =Assumptions.1!I20 -> 0 | G6: =Assumptions.1!I21 -> 0
A8: Gross Revenue / Turnover:
A10: Revenue | C10: =ROUND(FinalWorkings!C9,-4) -> #DIV/0! | D10: =ROUND(FinalWorkings!D9,-4) -> #DIV/0! | E10: =ROUND(FinalWorkings!E9,-4) -> #DIV/0! | F10: =ROUND(FinalWorkings!F9,-4) -> #DIV/0! | G10: =ROUND(FinalWorkings!G9,-4) -> #DIV/0!
C12: =SUM(C10:C11) -> #DIV/0! | D12: =SUM(D10:D11) -> #DIV/0! | E12: =SUM(E10:E11) -> #DIV/0! | F12: =SUM(F10:F11) -> #DIV/0! | G12: =SUM(G10:G11) -> #DIV/0!
A14: Cost of Goods Sold:
A16: Opening Stock | C16: =Assumptions.1!F77 -> 0 | D16: =wc!D10 -> 0 | E16: =wc!E10 -> 0 | F16: =wc!F10 -> 0 | G16: =wc!G10 -> 0
A17: Direct Material & Expenses | C17: =ROUND(FinalWorkings!C10,-4) -> #DIV/0! | D17: =ROUND(FinalWorkings!D10,-4) -> #DIV/0! | E17: =ROUND(FinalWorkings!E10,-4) -> #DIV/0! | F17: =ROUND(FinalWorkings!F10,-4) -> #DIV/0! | G17: =ROUND(FinalWorkings!G10,-4) -> #DIV/0!
A18: Closing Stock / WIP | C18: =ROUND(FinalWorkings!C11,-3) -> 0 | D18: =ROUND(FinalWorkings!D11,-3) -> 0 | E18: =ROUND(FinalWorkings!E11,-3) -> 0 | F18: =ROUND(FinalWorkings!F11,-3) -> 0 | G18: =ROUND(FinalWorkings!G11,-3) -> 0
A19: Operating Expenses | C19: =C16+C17-C18 -> #DIV/0! | D19: =D16+D17-D18 -> #DIV/0! | E19: =E16+E17-E18 -> #DIV/0! | F19: =F16+F17-F18 -> #DIV/0! | G19: =G16+G17-G18 -> #DIV/0!
A21: Gross Profit | C21: =C12-C19 -> #DIV/0! | D21: =D12-D19 -> #DIV/0! | E21: =E12-E19 -> #DIV/0! | F21: =F12-F19 -> #DIV/0! | G21: =G12-G19 -> #DIV/0!
A23: Add : Non Operating Income | C23: =ROUND(FinalWorkings!C12,-3) -> #DIV/0! | D23: =ROUND(FinalWorkings!D12,-3) -> #DIV/0! | E23: =ROUND(FinalWorkings!E12,-3) -> #DIV/0! | F23: =ROUND(FinalWorkings!F12,-3) -> #DIV/0! | G23: =ROUND(FinalWorkings!G12,-3) -> #DIV/0!
A25: Less :Admintrative & Selling Expenses | B25: Sch 1 | C25: =C86 -> #DIV/0! | D25: =D86 -> #DIV/0! | E25: =E86 -> #DIV/0! | F25: =F86 -> #DIV/0! | G25: =G86 -> #DIV/0!
A27: EBDIT | C27: =C21+C23-C25 -> #DIV/0! | D27: =D21+D23-D25 -> #DIV/0! | E27: =E21+E23-E25 -> #DIV/0! | F27: =F21+F23-F25 -> #DIV/0! | G27: =G21+G23-G25 -> #DIV/0!
A29: Less : Depreciation | C29: =Depsch!N17 -> 0 | D29: =Depsch!N24 -> 0 | E29: =Depsch!N31 -> 0 | F29: =Depsch!N38 -> 0 | G29: =Depsch!N45 -> 0
A31: EBIT | C31: =C27-C29 -> #DIV/0! | D31: =D27-D29 -> #DIV/0! | E31: =E27-E29 -> #DIV/0! | F31: =F27-F29 -> #DIV/0! | G31: =G27-G29 -> #DIV/0!
A33: Less: Interest | C33: =ROUND(wc!C27,-3) -> 0 | D33: =ROUND(wc!D27,-3) -> 0 | E33: =ROUND(wc!E27,-3) -> 0 | F33: =ROUND(wc!F27,-3) -> 0 | G33: =ROUND(wc!G27,-3) -> 0
A35: EBT | C35: =C31-C33 -> #DIV/0! | D35: =D31-D33 -> #DIV/0! | E35: =E31-E33 -> #DIV/0! | F35: =F31-F33 -> #DIV/0! | G35: =G31-G33 -> #DIV/0!
A38: =A1 -> 0
A39: =A2 -> 0
A40: =A3 -> 0
A42: BALANCE SHEET AS ON
A43: Particulars | B43: Schedules | C43: =C5 -> Estimated | D43: =D5 -> Projected | E43: =D43 -> Projected | F43: =E43 -> Projected | G43: =F43 -> Projected
C44: =C6 -> 0 | D44: =D6 -> 0 | E44: =E6 -> 0 | F44: =F6 -> 0 | G44: =G6 -> 0
A45: SOURCES OF FUNDS:
A47: Net Capital Including Net Reserves & Surplus | C47: =C55-SUM(C49:C54) -> #DIV/0! | D47: =D55-SUM(D49:D54) -> #DIV/0! | E47: =E55-SUM(E49:E54) -> #DIV/0! | F47: =F55-SUM(F49:F54) -> #DIV/0! | G47: =G55-SUM(G49:G54) -> #DIV/0!
A48: (Opening capital + Net profit -Drawings)
A50: CURRENT LIABILITIES:
A51: Bank CC/OD Loan | C51: =ROUND(wc!C39,-5) -> #DIV/0! | D51: =wc!D39 -> #DIV/0! | E51: =wc!E39 -> #DIV/0! | F51: =wc!F39 -> #DIV/0! | G51: =wc!G39 -> #DIV/0!
A52: =FinalWorkings!A22 -> Other Current Liabilities | C52: =ROUND(FinalWorkings!C22,-4) -> 0 | D52: =ROUND(FinalWorkings!D22,-4) -> 0 | E52: =ROUND(FinalWorkings!E22,-4) -> 0 | F52: =ROUND(FinalWorkings!F22,-4) -> 0 | G52: =ROUND(FinalWorkings!G22,-4) -> 0
C55: =C71 -> #DIV/0! | D55: =D71 -> #DIV/0! | E55: =E71 -> #DIV/0! | F55: =F71 -> #DIV/0! | G55: =G71 -> #DIV/0!
A59: APPLICATION OF FUNDS:
A61: FIXED ASSETS: | C61: =Depsch!N18 -> 0 | D61: =Depsch!N25 -> 0 | E61: =Depsch!N32 -> 0 | F61: =Depsch!N39 -> 0 | G61: =Depsch!N46 -> 0
A63: =IF(FinalWorkings!C24=0,"",FinalWorkings!A24) | C63: =IF(FinalWorkings!C24=0,"",FinalWorkings!C24) | D63: =IF(FinalWorkings!D24=0,"",FinalWorkings!D24) | E63: =IF(FinalWorkings!E24=0,"",FinalWorkings!E24) | F63: =IF(FinalWorkings!F24=0,"",FinalWorkings!F24) | G63: =IF(FinalWorkings!G24=0,"",FinalWorkings!G24)
A65: CURRENT ASSETS:
A66: =A18 -> Closing Stock / WIP | C66: =C18 -> 0 | D66: =D18 -> 0 | E66: =E18 -> 0 | F66: =F18 -> 0 | G66: =G18 -> 0
...

Sheet RATIO
A1: =Assumptions.1!I4 -> 0
A2: =Assumptions.1!I6 -> 0
A3: =Assumptions.1!I7 -> 0
A5: RATIO ANALYSIS
A7: A . CURRENT RATIO
C8: IDEAL RATIO > 1.33
A9: Particulars | C9: =wc!C6 -> 0 | D9: =wc!D6 -> 0 | E9: =wc!E6 -> 0 | F9: =wc!F6 -> 0 | G9: =wc!G6 -> 0
A11: Current Assets / Current Liabilities | C11: =IFERROR(C13/C14, "N/A") -> N/A | D11: =IFERROR(D13/D14, "N/A") -> N/A | E11: =IFERROR(E13/E14, "N/A") -> N/A | F11: =IFERROR(F13/F14, "N/A") -> N/A | G11: =IFERROR(G13/G14, "N/A") -> N/A
A13: Current Assets | C13: =SUM(plbs!C66:C70) -> #DIV/0! | D13: =SUM(plbs!D66:D70) -> #DIV/0! | E13: =SUM(plbs!E66:E70) -> #DIV/0! | F13: =SUM(plbs!F66:F70) -> #DIV/0! | G13: =SUM(plbs!G66:G70) -> #DIV/0!
A14: Current Liabilities | C14: =SUM(plbs!C51:C54) -> #DIV/0! | D14: =SUM(plbs!D51:D54) -> #DIV/0! | E14: =SUM(plbs!E51:E54) -> #DIV/0! | F14: =SUM(plbs!F51:F54) -> #DIV/0! | G14: =SUM(plbs!G51:G54) -> #DIV/0!
C15: =C13-C14 -> #DIV/0! | D15: =D13-D14 -> #DIV/0! | E15: =E13-E14 -> #DIV/0! | F15: =F13-F14 -> #DIV/0! | G15: =G13-G14 -> #DIV/0!
A16: NOTES : Indicates Ability to repay short term commitments promptly .
A18: B . DEBTORS / RECIEVABLES TURNOVER RATIO
A19: Particulars | C19: =wc!C6 -> 0 | D19: =wc!D6 -> 0 | E19: =wc!E6 -> 0 | F19: =wc!F6 -> 0 | G19: =wc!G6 -> 0
A21: Credit sales / Average debtors | C21: =IFERROR(plbs!C10/plbs!C67, "N/A") -> N/A | D21: =IFERROR(plbs!D10/plbs!D67, "N/A") -> N/A | E21: =IFERROR(plbs!E10/plbs!E67, "N/A") -> N/A | F21: =IFERROR(plbs!F10/plbs!F67, "N/A") -> N/A | G21: =IFERROR(plbs!G10/plbs!G67, "N/A") -> N/A
A22: *Sales assumed as credit sales
A24: NOTES : It indicates velocity of debt collection. Higer the DTR indicates good vellocity of debt
A25: collection.
A27: DEBTORS COLLECTION PERIOD : | C27: =IFERROR(B30/C21, "N/A") -> N/A | D27: =IFERROR(B30/D21, "N/A") -> N/A | E27: =IFERROR(B30/E21, "N/A") -> N/A | F27: =IFERROR(B30/F21, "N/A") -> N/A | G27: =IFERROR(B30/G21, "N/A") -> N/A
A28: (No of days/debtor turnover ratio)
A30: * No. of Days Assumed as | B30: 365
A32: C . GROSS PROFIT RATIO
A34: Particulars | C34: =wc!C6 -> 0 | D34: =wc!D6 -> 0 | E34: =wc!E6 -> 0 | F34: =wc!F6 -> 0 | G34: =wc!G6 -> 0
A36: Gross profit / Sales * 100 | C36: =IFERROR(plbs!C21/plbs!C12*100, "N/A") -> N/A | D36: =IFERROR(plbs!D21/plbs!D12*100, "N/A") -> N/A | E36: =IFERROR(plbs!E21/plbs!E12*100, "N/A") -> N/A | F36: =IFERROR(plbs!F21/plbs!F12*100, "N/A") -> N/A | G36: =IFERROR(plbs!G21/plbs!G12*100, "N/A") -> N/A
A38: NOTES : Indicates Basic Profitability of the Business.
A40: D . NETPROFIT RATIO
A42: Particulars | C42: =wc!C6 -> 0 | D42: =wc!D6 -> 0 | E42: =wc!E6 -> 0 | F42: =wc!F6 -> 0 | G42: =wc!G6 -> 0
A44: Netprofit / Sales * 100 | C44: =IFERROR(plbs!C35/plbs!C12*100, "N/A") -> N/A | D44: =IFERROR(plbs!D35/plbs!D12*100, "N/A") -> N/A | E44: =IFERROR(plbs!E35/plbs!E12*100, "N/A") -> N/A | F44: =IFERROR(plbs!F35/plbs!F12*100, "N/A") -> N/A | G44: =IFERROR(plbs!G35/plbs!G12*100, "N/A") -> N/A
A46: NOTES : Indicates overall Profitability of the Business.
A48: E . INTEREST COVERAGE RATIO
D49: IDEAL RATIO - > 1
A50: Partiiculars | C50: =wc!C6 -> 0 | D50: =wc!D6 -> 0 | E50: =wc!E6 -> 0 | F50: =wc!F6 -> 0 | G50: =wc!G6 -> 0
A52: E B I / Interest | C52: =IFERROR(C54/C55, "N/A") -> N/A | D52: =IFERROR(D54/D55, "N/A") -> N/A | E52: =IFERROR(E54/E55, "N/A") -> N/A | F52: =IFERROR(F54/F55, "N/A") -> N/A | G52: =IFERROR(G54/G55, "N/A") -> N/A
A54: EBI | C54: =plbs!C31 -> #DIV/0! | D54: =plbs!D31 -> #DIV/0! | E54: =plbs!E31 -> #DIV/0! | F54: =plbs!F31 -> #DIV/0! | G54: =plbs!G31 -> #DIV/0!
A55: Interest | C55: =plbs!C33 -> 0 | D55: =plbs!D33 -> 0 | E55: =plbs!E33 -> 0 | F55: =plbs!F33 -> 0 | G55: =plbs!G33 -> 0
A57: NOTE : Indicates ability to meet Interest Obligation of the current year .
A60: F . WORKING CAPITAL TURNOVER RATIO :
A62: Particulars | C62: =wc!C6 -> 0 | D62: =wc!D6 -> 0 | E62: =wc!E6 -> 0 | F62: =wc!F6 -> 0 | G62: =wc!G6 -> 0
A64: Networking capital (CA - CL) | C64: =C13-C14 -> #DIV/0! | D64: =D13-D14 -> #DIV/0! | E64: =E13-E14 -> #DIV/0! | F64: =F13-F14 -> #DIV/0! | G64: =G13-G14 -> #DIV/0!
A66: Sales / Networking Capital | C66: =plbs!C10/RATIO!C64 -> #DIV/0! | D66: =plbs!D10/RATIO!D64 -> #DIV/0! | E66: =plbs!E10/RATIO!E64 -> #DIV/0! | F66: =plbs!F10/RATIO!F64 -> #DIV/0! | G66: =plbs!G10/RATIO!G64 -> #DIV/0!
...

Sheet MPBF 
A1: =Assumptions.1!I4 -> 0
A2: =Assumptions.1!I6 -> 0
A3: =Assumptions.1!I7 -> 0
A5: CALCULATION OF MAXIMUM PERMISSIBLE BANK FINANCE
A7: MPBF - Method 1 - 25%(Working Capital Gap)
A8: PARTICULARS | B8: =wc!C6 -> 0 | C8: =wc!D6 -> 0 | D8: =wc!E6 -> 0 | E8: =wc!F6 -> 0 | F8: =wc!G6 -> 0
A10: 1. Total current assets | B10: =SUM(plbs!C65:C70) -> #DIV/0! | C10: =SUM(plbs!D65:D70) -> #DIV/0! | D10: =SUM(plbs!E65:E70) -> #DIV/0! | E10: =SUM(plbs!F65:F70) -> #DIV/0! | F10: =SUM(plbs!G65:G70) -> #DIV/0!
A12: 2. Other current liabilities | B12: =plbs!C52+plbs!C53+plbs!C54 -> 0 | C12: =plbs!D52+plbs!D53+plbs!D54 -> 0 | D12: =plbs!E52+plbs!E53+plbs!E54 -> 0 | E12: =plbs!F52+plbs!F53+plbs!F54 -> 0 | F12: =plbs!G52+plbs!G53+plbs!G54 -> 0
A13: (Other than bank borrowings )
A15: 3. Working capital gap | B15: =+B10-B12 -> #DIV/0! | C15: =+C10-C12 -> #DIV/0! | D15: =+D10-D12 -> #DIV/0! | E15: =+E10-E12 -> #DIV/0! | F15: =+F10-F12 -> #DIV/0!
A17: 4. Min. stipulated Networking capital
A18: (25% of WCG excluding export | B18: =+B15*0.25 -> #DIV/0! | C18: =+C15*0.25 -> #DIV/0! | D18: =+D15*0.25 -> #DIV/0! | E18: =+E15*0.25 -> #DIV/0! | F18: =+F15*0.25 -> #DIV/0!
A19: receivables)
A21: 5. Actual/projected net working capital | B21: =RATIO!C15 -> #DIV/0! | C21: =RATIO!D15 -> #DIV/0! | D21: =RATIO!E15 -> #DIV/0! | E21: =RATIO!F15 -> #DIV/0! | F21: =RATIO!G15 -> #DIV/0!
A23: 6.Item 3 minus item 4 | B23: =+B15-B18 -> #DIV/0! | C23: =+C15-C18 -> #DIV/0! | D23: =+D15-D18 -> #DIV/0! | E23: =+E15-E18 -> #DIV/0! | F23: =+F15-F18 -> #DIV/0!
A25: 7.Item 3 minus item 5 | B25: =B15-B21 -> #DIV/0! | C25: =C15-C21 -> #DIV/0! | D25: =D15-D21 -> #DIV/0! | E25: =E15-E21 -> #DIV/0! | F25: =F15-F21 -> #DIV/0!
A27: 8. Maximum permissible bank | B27: =IF(B23<B25,B23,B25) -> #DIV/0! | C27: =IF(C23<C25,C23,C25) -> #DIV/0! | D27: =IF(D23<D25,D23,D25) -> #DIV/0! | E27: =IF(E23<E25,E23,E25) -> #DIV/0! | F27: =IF(F23<F25,F23,F25) -> #DIV/0!
A28: finance(lower of 6 or 7 )
A31: MPBF - Method 2 - 25%(Current Assets)
A32: PARTICULARS | B32: =B8 -> 0 | C32: =C8 -> 0 | D32: =D8 -> 0 | E32: =E8 -> 0 | F32: =F8 -> 0
A34: 1. Total current assets | B34: =B10 -> #DIV/0! | C34: =C10 -> #DIV/0! | D34: =D10 -> #DIV/0! | E34: =E10 -> #DIV/0! | F34: =F10 -> #DIV/0!
A36: 2. Other current liabilities | B36: =B12 -> 0 | C36: =C12 -> 0 | D36: =D12 -> 0 | E36: =E12 -> 0 | F36: =F12 -> 0
A37: (Other than bank borrowings )
A39: 3. Working capital gap | B39: =+B34-B36 -> #DIV/0! | C39: =+C34-C36 -> #DIV/0! | D39: =+D34-D36 -> #DIV/0! | E39: =+E34-E36 -> #DIV/0! | F39: =+F34-F36 -> #DIV/0!
A41: 4. Min. stipulated Networking capital
A42: (25% of Current Assets) | B42: =25/100*B34 -> #DIV/0! | C42: =25/100*C34 -> #DIV/0! | D42: =25/100*D34 -> #DIV/0! | E42: =25/100*E34 -> #DIV/0! | F42: =25/100*F34 -> #DIV/0!
A44: 5. Actual/projected net working capital | B44: =B21 -> #DIV/0! | C44: =C21 -> #DIV/0! | D44: =D21 -> #DIV/0! | E44: =E21 -> #DIV/0! | F44: =F21 -> #DIV/0!
A46: 6.Item 3 minus item 4 | B46: =+B39-B42 -> #DIV/0! | C46: =+C39-C42 -> #DIV/0! | D46: =+D39-D42 -> #DIV/0! | E46: =+E39-E42 -> #DIV/0! | F46: =+F39-F42 -> #DIV/0!
A48: 7.Item 3 minus item 5 | B48: =B39-B44 -> #DIV/0! | C48: =C39-C44 -> #DIV/0! | D48: =D39-D44 -> #DIV/0! | E48: =E39-E44 -> #DIV/0! | F48: =F39-F44 -> #DIV/0!
A50: 8. Maximum permissible bank | B50: =IF(B46<B48,B46,B48) -> #DIV/0! | C50: =IF(C46<C48,C46,C48) -> #DIV/0! | D50: =IF(D46<D48,D46,D48) -> #DIV/0! | E50: =IF(E46<E48,E46,E48) -> #DIV/0! | F50: =IF(F46<F48,F46,F48) -> #DIV/0!
A51: finance(lower of 6 or 7 )

Sheet Nayak
A2: =Assumptions.1!I4 -> 0
A3: =Assumptions.1!I6 -> 0
A4: =Assumptions.1!I7 -> 0
A6: WORKING CAPITAL ASSESSMENT - TURNOVER METHOD
A8: NAYAK COMMITTEE RECOMONDATIONS
A10: PARTICULARS | C10: =wc!C6 -> 0 | D10: =wc!D6 -> 0 | E10: =wc!E6 -> 0 | F10: =wc!F6 -> 0 | G10: =wc!G6 -> 0
A12: Turnover | C12: =plbs!C12 -> #DIV/0! | D12: =plbs!D12 -> #DIV/0! | E12: =plbs!E12 -> #DIV/0! | F12: =plbs!F12 -> #DIV/0! | G12: =plbs!G12 -> #DIV/0!
A14: Working Capital Requirement | C14: =C12*25/100 -> #DIV/0! | D14: =D12*25/100 -> #DIV/0! | E14: =E12*25/100 -> #DIV/0! | F14: =F12*25/100 -> #DIV/0! | G14: =G12*25/100 -> #DIV/0!
A15: (25% of Turnover)
A17: Minimum Working Capital Limit | C17: =C14*80/100 -> #DIV/0! | D17: =D14*80/100 -> #DIV/0! | E17: =E14*80/100 -> #DIV/0! | F17: =F14*80/100 -> #DIV/0! | G17: =G14*80/100 -> #DIV/0!
A18: (80% of Working Capital Requirment)
A20: Drawing Power | C20: =Assumptions.1!I12 -> 0 | D20: =Assumptions.1!I12 -> 0 | E20: =D20 -> 0 | F20: =E20 -> 0 | G20: =F20 -> 0
A22: Maximum Permisable Working capital Limit
C23: =IF(C17<C20,C17,C20) -> #DIV/0! | D23: =IF(D17<D20,D17,D20) -> #DIV/0! | E23: =IF(E17<E20,E17,E20) -> #DIV/0! | F23: =IF(F17<F20,F17,F20) -> #DIV/0! | G23: =IF(G17<G20,G17,G20) -> #DIV/0!
A27: Notes :
A28: 1. Maximum Working capital Limit Must not exceed Drawing power .
A29: 2. Four Operating cycles per Annum is Assumed.

Sheet Depsch
A1: =Assumptions.1!I4 -> 0
A2: =Assumptions.1!I6 -> 0
A3: =Assumptions.1!I7 -> 0
A5: CALCULATION OF DEPRECIATION AS PER INCOME TAX ACT
N7: Rs in lacs
C8: =Assumptions.1!B99 -> Plant and Machinery | D8: =Assumptions.1!B109 -> Service Equipment | E8: =Assumptions.1!B119 -> Shed and Civil works | F8: =Assumptions.1!B129 -> Land | G8: =Assumptions.1!B132 -> Electrical Items | H8: =Assumptions.1!B141 -> Electronic items | I8: =Assumptions.1!B151 -> Furniture and Fittings | J8: =Assumptions.1!B161 -> Vehicles | K8: =Assumptions.1!B171 -> Live stock | L8: =Assumptions.1!B180 -> Other Assets | M8: =Assumptions.1!B190 -> Other Assets (Nil Depreciation)
N9: Total
C10: =Assumptions.1!F82 -> 0.15 | D10: =Assumptions.1!F83 -> 0.15 | E10: =Assumptions.1!F84 -> 0.1 | F10: =Assumptions.1!F85 -> 0 | G10: =Assumptions.1!F86 -> 0.15 | H10: =Assumptions.1!F87 -> 0.15 | I10: =Assumptions.1!F88 -> 0.1 | J10: =Assumptions.1!F89 -> 0.15 | K10: =Assumptions.1!F90 -> 0 | L10: =Assumptions.1!F91 -> 0.1 | M10: =Assumptions.1!F92 -> 0
A13: =wc!C33 -> 0
A14: WDV | C14: =Assumptions.1!F99 -> 0 | D14: =Assumptions.1!F109 -> 0 | E14: =Assumptions.1!F119 -> 0 | F14: =Assumptions.1!F129 -> 0 | G14: =Assumptions.1!F132 -> 0 | H14: =Assumptions.1!F141 -> 0 | I14: =Assumptions.1!F151 -> 0 | J14: =Assumptions.1!F161 -> 0 | K14: =Assumptions.1!F171 -> 0 | L14: =Assumptions.1!F180 -> 0 | M14: =Assumptions.1!F190 -> 0 | N14: =C14+D14+E14+F14+G14+H14+I14+J14+K14+L14+M14 -> 0
A15: Add Additions | C15: 0 | D15: 0 | E15: 0 | F15: 0 | G15: 0 | H15: 0 | I15: 0 | J15: 0 | K15: 0 | L15: 0 | N15: =C15+D15+E15+F15+G15+H15+I15+J15+K15+L15+M15 -> 0
A16: Total | C16: =C14+C15 -> 0 | D16: =D14+D15 -> 0 | E16: =E14+E15 -> 0 | F16: =F14+F15 -> 0 | G16: =G14+G15 -> 0 | H16: =H14+H15 -> 0 | I16: =I14+I15 -> 0 | J16: =J14+J15 -> 0 | ... M16: =M14+M15 -> 0 | N16: =C16+D16+E16+F16+G16+H16+I16+J16+K16+L16+M16 -> 0
A17: Depreciation | C17: =C16*C10*Assumptions.1!I35/Assumptions.1!F69 -> 0 | D17: =D16*D10*Assumptions.1!I35/Assumptions.1!F69 -> 0 | E17: =E16*E10*Assumptions.1!I35/Assumptions.1!F69 -> 0 | F17: =F16*F10*Assumptions.1!I35/Assumptions.1!F69 -> 0 | G17: =G16*G10*Assumptions.1!I35/Assumptions.1!F69 -> 0 | H17: =H16*H10*Assumptions.1!I35/Assumptions.1!F69 -> 0 | I17: =I16*I10*Assumptions.1!I35/Assumptions.1!F69 -> 0 | J17: =J16*J10*Assumptions.1!I35/Assumptions.1!F69 -> 0 | K17: =K16*K10*Assumptions.1!I35/Assumptions.1!F69 -> 0 | L17: =L16*L10*Assumptions.1!I35/Assumptions.1!F69 -> 0 | M17: =M16*M10*Assumptions.1!I35/Assumptions.1!F69 -> 0 | N17: =C17+D17+E17+F17+G17+H17+I17+J17+K17+L17+M17 -> 0
A18: WDVat the end of 1st Year | C18: =C16-C17 -> 0 | D18: =D16-D17 -> 0 | E18: =E16-E17 -> 0 | F18: =F16-F17 -> 0 | G18: =G16-G17 -> 0 | H18: =H16-H17 -> 0 | I18: =I16-I17 -> 0 | J18: =J16-J17 -> 0 | ... M18: =M16-M17 -> 0 | N18: =C18+D18+E18+F18+G18+H18+I18+J18+K18+L18+M18 -> 0
A20: =wc!D33 -> 0
A21: WDV | C21: =C18 -> 0 | D21: =D18 -> 0 | E21: =E18 -> 0 | F21: =F18 -> 0 | G21: =G18 -> 0 | H21: =H18 -> 0 | I21: =I18 -> 0 | J21: =J18 -> 0 | ... M21: =M18 -> 0 | N21: =C21+D21+E21+F21+G21+H21+I21+J21+K21+L21+M21 -> 0
A22: Add Additions | C22: 0 | D22: 0 | E22: 0 | F22: 0 | G22: 0 | H22: 0 | I22: 0 | J22: 0 | K22: 0 | L22: 0 | M22: 0 | N22: =C22+D22+E22+F22+G22+H22+I22+J22+K22+L22+M22 -> 0
A23: Total | C23: =C21+C22 -> 0 | D23: =D21+D22 -> 0 | E23: =E21+E22 -> 0 | F23: =F21+F22 -> 0 | G23: =G21+G22 -> 0 | H23: =H21+H22 -> 0 | I23: =I21+I22 -> 0 | J23: =J21+J22 -> 0 | ... M23: =M21+M22 -> 0 | N23: =C23+D23+E23+F23+G23+H23+I23+J23+K23+L23+M23 -> 0
A24: Depreciation | C24: =C23*C10 -> 0 | D24: =D23*D10 -> 0 | E24: =E23*E10 -> 0 | F24: =F23*F10 -> 0 | G24: =G23*G10 -> 0 | H24: =H23*H10 -> 0 | I24: =I23*I10 -> 0 | J24: =J23*J10 -> 0 | ... M24: =M23*M10 -> 0 | N24: =C24+D24+E24+F24+G24+H24+I24+J24+K24+L24+M24 -> 0
A25: WDVat the end of 2nd Year | C25: =C23-C24 -> 0 | D25: =D23-D24 -> 0 | E25: =E23-E24 -> 0 | F25: =F23-F24 -> 0 | G25: =G23-G24 -> 0 | H25: =H23-H24 -> 0 | I25: =I23-I24 -> 0 | J25: =J23-J24 -> 0 | ... M25: =M23-M24 -> 0 | N25: =C25+D25+E25+F25+G25+H25+I25+J25+K25+L25+M25 -> 0
A27: =wc!E33 -> 0
A28: WDV | C28: =C25 -> 0 | D28: =D25 -> 0 | E28: =E25 -> 0 | F28: =F25 -> 0 | G28: =G25 -> 0 | H28: =H25 -> 0 | I28: =I25 -> 0 | J28: =J25 -> 0 | ... M28: =M25 -> 0 | N28: =C28+D28+E28+F28+G28+H28+I28+J28+K28+L28+M28 -> 0
A29: Add Additions | C29: 0 | D29: 0 | E29: 0 | F29: 0 | G29: 0 | H29: 0 | I29: 0 | J29: 0 | K29: 0 | L29: 0 | M29: 0 | N29: =C29+D29+E29+F29+G29+H29+I29+J29+K29+L29+M29 -> 0
A30: Total | C30: =C28+C29 -> 0 | D30: =D28+D29 -> 0 | E30: =E28+E29 -> 0 | F30: =F28+F29 -> 0 | G30: =G28+G29 -> 0 | H30: =H28+H29 -> 0 | I30: =I28+I29 -> 0 | J30: =J28+J29 -> 0 | ... M30: =M28+M29 -> 0 | N30: =C30+D30+E30+F30+G30+H30+I30+J30+K30+L30+M30 -> 0
A31: Depreciation | C31: =C30*C10 -> 0 | D31: =D30*D10 -> 0 | E31: =E30*E10 -> 0 | F31: =F30*F10 -> 0 | G31: =G30*G10 -> 0 | H31: =H30*H10 -> 0 | I31: =I30*I10 -> 0 | J31: =J30*J10 -> 0 | ... M31: =M30*M10 -> 0 | N31: =C31+D31+E31+F31+G31+H31+I31+J31+K31+L31+M31 -> 0
A32: WDVat the end of 3rd Year | C32: =C30-C31 -> 0 | D32: =D30-D31 -> 0 | E32: =E30-E31 -> 0 | F32: =F30-F31 -> 0 | G32: =G30-G31 -> 0 | H32: =H30-H31 -> 0 | I32: =I30-I31 -> 0 | J32: =J30-J31 -> 0 | ... M32: =M30-M31 -> 0 | N32: =C32+D32+E32+F32+G32+H32+I32+J32+K32+L32+M32 -> 0
A34: =wc!F33 -> 0
A35: WDV | C35: =C32 -> 0 | D35: =D32 -> 0 | E35: =E32 -> 0 | F35: =F32 -> 0 | G35: =G32 -> 0 | H35: =H32 -> 0 | I35: =I32 -> 0 | J35: =J32 -> 0 | ... M35: =M32 -> 0 | N35: =C35+D35+E35+F35+G35+H35+I35+J35+K35+L35+M35 -> 0
A36: Add Additions | C36: 0 | D36: 0 | E36: 0 | F36: 0 | G36: 0 | H36: 0 | I36: 0 | J36: 0 | K36: 0 | L36: 0 | M36: 0 | N36: =C36+D36+E36+F36+G36+H36+I36+J36+K36+L36+M36 -> 0
A37: Total | C37: =C35+C36 -> 0 | D37: =D35+D36 -> 0 | E37: =E35+E36 -> 0 | F37: =F35+F36 -> 0 | G37: =G35+G36 -> 0 | H37: =H35+H36 -> 0 | I37: =I35+I36 -> 0 | J37: =J35+J36 -> 0 | ... M37: =M35+M36 -> 0 | N37: =C37+D37+E37+F37+G37+H37+I37+J37+K37+L37+M37 -> 0
A38: Depreciation | C38: =C37*C10 -> 0 | D38: =D37*D10 -> 0 | E38: =E37*E10 -> 0 | F38: =F37*F10 -> 0 | G38: =G37*G10 -> 0 | H38: =H37*H10 -> 0 | I38: =I37*I10 -> 0 | J38: =J37*J10 -> 0 | ... M38: =M37*M10 -> 0 | N38: =C38+D38+E38+F38+G38+H38+I38+J38+K38+L38+M38 -> 0
A39: WDVat the end of 4th Year | C39: =C37-C38 -> 0 | D39: =D37-D38 -> 0 | E39: =E37-E38 -> 0 | F39: =F37-F38 -> 0 | G39: =G37-G38 -> 0 | H39: =H37-H38 -> 0 | I39: =I37-I38 -> 0 | J39: =J37-J38 -> 0 | ... M39: =M37-M38 -> 0 | N39: =C39+D39+E39+F39+G39+H39+I39+J39+K39+L39+M39 -> 0
A41: =wc!G33 -> 0
A42: WDV | C42: =C39 -> 0 | D42: =D39 -> 0 | E42: =E39 -> 0 | F42: =F39 -> 0 | G42: =G39 -> 0 | H42: =H39 -> 0 | I42: =I39 -> 0 | J42: =J39 -> 0 | ... M42: =M39 -> 0 | N42: =C42+D42+E42+F42+G42+H42+I42+J42+K42+L42+M42 -> 0
A43: Add Additions | C43: 0 | D43: 0 | E43: 0 | F43: 0 | G43: 0 | H43: 0 | I43: 0 | J43: 0 | K43: 0 | L43: 0 | M43: 0 | N43: =C43+D43+E43+F43+G43+H43+I43+J43+K43+L43+M43 -> 0
A44: Total | C44: =C42+C43 -> 0 | D44: =D42+D43 -> 0 | E44: =E42+E43 -> 0 | F44: =F42+F43 -> 0 | G44: =G42+G43 -> 0 | H44: =H42+H43 -> 0 | I44: =I42+I43 -> 0 | J44: =J42+J43 -> 0 | ... M44: =M42+M43 -> 0 | N44: =C44+D44+E44+F44+G44+H44+I44+J44+K44+L44+M44 -> 0
A45: Depreciation | C45: =C44*C10 -> 0 | D45: =D44*D10 -> 0 | E45: =E44*E10 -> 0 | F45: =F44*F10 -> 0 | G45: =G44*G10 -> 0 | H45: =H44*H10 -> 0 | I45: =I44*I10 -> 0 | J45: =J44*J10 -> 0 | ... M45: =M44*M10 -> 0 | N45: =C45+D45+E45+F45+G45+H45+I45+J45+K45+L45+M45 -> 0
A46: WDVat the end of 5th Year | C46: =C44-C45 -> 0 | D46: =D44-D45 -> 0 | E46: =E44-E45 -> 0 | F46: =F44-F45 -> 0 | G46: =G44-G45 -> 0 | H46: =H44-H45 -> 0 | I46: =I44-I45 -> 0 | J46: =J44-J45 -> 0 | ... M46: =M44-M45 -> 0 | N46: =C46+D46+E46+F46+G46+H46+I46+J46+K46+L46+M46 -> 0

Sheet Fixed assets sch
B7: SCHEDULES TO FIXED ASSETS
B9: Furniture and Fixtures Schedule:
B10: 1.Computer tables | C10: 150000
B11: 2.Wooden wardrobe | C11: 150000
B12: 3.Conference room furniture | C12: 200000
C14: =SUM(C10:C13) -> 500000
B16: Plant and Machinery Schedule:
B17: 1.Moulds
B18: 2.Dyes
B19: 3.Generator
B20: 4.Invertor
B21: 5.CCw B machinery
