Workbook

Sheet Assumptions.1
B2: Section | C2: Question | D2: Question Type | E2: Editable | F2: Options | G2: Min - Max | H2: Details which are required to be given by Customer | I2: Answer | J2: Particulars
B3: General Information | C3: Name of Firm | D3: Manual entry | E3: No
C4: Status of Concern | D4: Dropdown options to be provided | E4: No | F4: Soleproprietorship,Partnership,LLP,Company
C5: Proprietor / MP / MD Name | D5: Manual entry | E5: No
C6: Firm address | D6: Manual entry | E6: No
C7: Sector | D7: Dropdown options to be provided | E7: No | F7: Manufacturing sector / Service sector (with stock) / Trading sector
C8: Nature of Business | D8: Manual entry | E8: No
B10: Means of Finance details | C10: Do you have existing working capital limit ? | D10: Options to be provided | E10: Yes | F10: Yes,No
C11: Are you going for Working capital limit Topup from present limit? | D11: Options to be provided | E11: Yes | F11: Yes,No
C12: Working capital Loan requirement (Existing) | D12: Manual entry | E12: Yes | J12: Loan amount
C13: Working capital Loan requirement (Top up) | D13: Manual entry | E13: Yes
C14: Working capital loan interest | D14: Manual entry | E14: Yes | H14: 0 | I14: =H14*1/100 -> 0 | J14: per annum
C15: Processing fees (Inclusing GST) | D15: Manual entry | E15: Yes | H15: 0 | I15: =(H15+H15*18/100)*1/100 -> 0 | J15: of loan amount
C16: Working capital (% on Turnover) | D16: Options to be provided | E16: Yes | G16: 15% or more than 15% | H16: 0 | I16: =H16*1/100 -> 0 | J16: on Sales
B18: Financial Year | C18: 1st Financial year | D18: Dropdown options to be provided | E18: Yes | F18: 2024 - 25 to provide 10 years with Start Month to End Month | J18: Audited | L18: Audited or Provisional
C19: 2nd Financial year | D19: Dropdown options to be provided | E19: Yes | F19: 2024 - 25 to provide 10 years with Start Month to End Month | J19: Estimated
C20: 3rd Financial year | D20: Dropdown options to be provided | E20: Yes | F20: 2024 - 25 to provide 10 years with Start Month to End Month | J20: Projected
C21: 4th Financial year | D21: Dropdown options to be provided | E21: Yes | F21: 2024 - 25 to provide 10 years with Start Month to End Month | J21: Projected
C22: =I18 -> 0
B23: Audited / Provisional financial statements figures | C23: Turnover | D23: Manual entry | E23: Yes
C24: Opening Stock | D24: Manual entry | E24: Yes
A25: STEP 1 | C25: Direct Material & Expenses | D25: Manual entry | E25: Yes
C26: Closing Stock | D26: Manual entry | E26: Yes
C27: Non Operating Income | D27: Manual entry | E27: Yes
C28: Electricity | D28: Manual entry | E28: Yes
C29: Depreciation | D29: Manual entry | E29: Yes
C30: Rent | D30: Manual entry | E30: Yes
C31: Salaries & Wages | D31: Manual entry | E31: Yes
C32: Processing fees (Inclusing GST) | D32: Manual entry | E32: Yes
C33: Interest on CC / OD Loan | D33: Manual entry | E33: Yes
C34: Interest on Other loans | D34: Manual entry | E34: Yes
C35: Net Profit Before Tax | D35: Manual entry | E35: Yes
C36: Office Admin, Marketing and Miscelleneous Expenses | D36: Autogenerated | E36: NA | I36: =I23+I26-I24-I25+I27-I28-I29-I30-I31-I32-I33-I34-I35 -> 0
C37: Net Capital (Opening capital +Net Profit -Drawings) | D37: Manual entry | E37: Yes
C38: Term Loans (Secured and Unsecured Loans Total) | D38: Manual entry | E38: Yes
C39: CC Loan Outstanding | D39: Manual entry | E39: Yes
C40: Other Current Liabilities | D40: Manual entry | E40: Yes
C41: Net Total Fixed Assets | D41: Autogenerated | E41: NA | F41: Autogenerated from Schedule for FIXED ASSETS | I41: =F200 -> 0
C42: Depreciation | D42: Autogenerated | E42: NA | I42: =I29 -> 0
C43: Gross Total Fixed Assets | D43: Autogenerated | E43: NA | I43: =I42+I41 -> 0
...

Sheet wp
A3: STEP 2 : BACK GROUND CALCULATION . NOT TO BE VISIBLE TO CUSTOMER
A4: WORKINGS FOR PROFIT AND LOSS ACCOUNT
A5: PARTICULARS | B5: Schedules | C5: =Assumptions.1!J18 -> Audited | D5: =Assumptions.1!J19 -> Estimated | E5: =Assumptions.1!J20 -> Projected | F5: =Assumptions.1!J21 -> Projected
C6: =Assumptions.1!I18 -> 0 | D6: =Assumptions.1!I19 -> 0 | E6: =Assumptions.1!I20 -> 0 | F6: =Assumptions.1!I21 -> 0
A8: Gross Reciepts:
A10: Turnover (A1) | C10: =Assumptions.1!I23 -> 0 | D10: =Assumptions.1!I59 -> #DIV/0! | E10: =D10*Assumptions.1!I50 -> #DIV/0! | F10: =E10*Assumptions.1!I50 -> #DIV/0!
C12: =SUM(C10:C11) -> 0 | D12: =SUM(D10:D11) -> #DIV/0! | E12: =SUM(E10:E11) -> #DIV/0! | F12: =SUM(F10:F11) -> #DIV/0!
A14: Cost of Goods Sold:
A16: Opening Stock | C16: =Assumptions.1!I24 -> 0 | D16: =C18 -> 0 | E16: =D18 -> 0 | F16: =E18 -> 0
A17: Direct Material & Expenses | C17: =Assumptions.1!I25 -> 0 | D17: =D19-D16+D18 -> #DIV/0! | E17: =E19-E16+E18 -> #DIV/0! | F17: =F19-F16+F18 -> #DIV/0!
A18: Closing Stock | C18: =Assumptions.1!I26 -> 0 | D18: =Assumptions.1!I63 -> 0 | E18: =D18*Assumptions.1!I54 -> 0 | F18: =E18*Assumptions.1!I54 -> 0
A19: Operating Expenses | C19: =C16+C17-C18 -> 0 | D19: =D10-D21 -> #DIV/0! | E19: =E12-E21 -> #DIV/0! | F19: =F12-F21 -> #DIV/0!
A21: Gross Profit ( D = A1- A- B+ C) | C21: =C12-C19 -> 0 | D21: =D10*Assumptions.1!I87 -> #DIV/0! | E21: =E10*Assumptions.1!I88 -> #DIV/0! | F21: =F10*Assumptions.1!I89 -> #DIV/0!
A23: Non Operating Income (E) | C23: =Assumptions.1!I27 -> 0 | D23: =C23*Assumptions.1!I52 -> 0 | E23: =D23*Assumptions.1!I52 -> 0 | F23: =E23*Assumptions.1!I52 -> 0
A25: Adm & Selling Expenses(F) | C25: =C91 -> 0 | D25: =D91 -> #DIV/0! | E25: =E91 -> #DIV/0! | F25: =F91 -> #DIV/0!
A27: EBDIT(G = D+ E- F) | C27: =C21+C23-C25 -> 0 | D27: =D21+D23-D25 -> #DIV/0! | E27: =E21+E23-E25 -> #DIV/0! | F27: =F21+F23-F25 -> #DIV/0!
A29: Less : Depreciation (H) | C29: =Assumptions.1!I29 -> 0 | D29: =Depsch!M19 -> 0 | E29: =Depsch!M26 -> 0 | F29: =Depsch!M33 -> 0
A31: EBIT( I = G - H ) | C31: =C27-C29 -> 0 | D31: =D27-D29 -> #DIV/0! | E31: =E27-E29 -> #DIV/0! | F31: =F27-F29 -> #DIV/0!
A33: Less: Interest (J) | C33: =C102 -> 0 | D33: =D102 -> #DIV/0! | E33: =E102 -> #DIV/0! | F33: =F102 -> #DIV/0!
A35: EBT(K = I - J) | C35: =C31-C33 -> 0 | D35: =D31-D33 -> #DIV/0! | E35: =E31-E33 -> #DIV/0! | F35: =F31-F33 -> #DIV/0!
C37: When ever editing is done , this totally must be calculated automatically
A41: =A3 -> STEP 2 : BACK GROUND CALCULATION . NOT TO BE VISIBLE TO CUSTOMER
A43: WORKINGS FOR BALANCESHEET
A44: Particulars | B44: Schedules | C44: =C5 -> Audited | D44: =D5 -> Estimated | E44: =E5 -> Projected | F44: =F5 -> Projected
C45: =C6 -> 0 | D45: =D6 -> 0 | E45: =E6 -> 0 | F45: =F6 -> 0
A46: SOURCES OF FUNDS:
A48: Net Capital | C48: =Assumptions.1!I37 -> 0 | D48: =D59-SUM(D50:D57) -> #DIV/0! | E48: =E59-SUM(E50:E57) -> #DIV/0! | F48: =F59-SUM(F50:F57) -> #DIV/0!
A49: (Opening capital + Net profit -Drawings)
A50: TERM LOANS:
A51: Secured and Unsecured Loans | C51: =Assumptions.1!I38 -> 0 | D51: =C51-Assumptions.1!I67 -> 0 | E51: =D51-Assumptions.1!I67 -> 0 | F51: =E51-Assumptions.1!I67 -> 0
A54: CURRENT LIABILITIES:
A55: Bank CC/OD loan | C55: =Assumptions.1!I39 -> 0 | D55: =IF(D114<D109,D114,D109) -> #DIV/0! | E55: =IF(E114<E109,E114,E109) -> #DIV/0! | F55: =IF(F114<F109,F114,F109) -> #DIV/0!
A56: Other current liabilities | C56: =Assumptions.1!I40 -> 0 | D56: 0 | E56: 0 | F56: 0
C59: =SUM(C48:C57) -> 0 | D59: =D74 -> #DIV/0! | E59: =E74 -> #DIV/0! | F59: =F74 -> #DIV/0!
C61: When ever editing is done , this totally must be calculated automatically
A62: APPLICATION OF FUNDS:
A64: FIXED ASSETS: | C64: =Assumptions.1!I41 -> 0 | D64: =Depsch!M20 -> 0 | E64: =Depsch!M27 -> 0 | F64: =Depsch!M34 -> 0
A66: INVESTMENTS: | C66: =Assumptions.1!I44 -> 0 | D66: =C66 -> 0 | E66: =D66 -> 0 | F66: =E66 -> 0
A68: CURRENT ASSETS:
A69: Other current Assets | C69: =Assumptions.1!I47 -> 0 | D69: 0 | E69: 0 | F69: 0
...

Sheet FinalWorkings
A3: STEP 3 : DISPLAY TO CUSTOMER FOR MAKING EDITING
A4: FINANCIAL(In Brief) and Ratios at a Glance
A5: PARTICULARS | B5: =wp!C44 -> Audited | C5: =wp!D44 -> Estimated | D5: =wp!E44 -> Projected | E5: =wp!F44 -> Projected
B6: =wp!C45 -> 0 | C6: =wp!D45 -> 0 | D6: =wp!E45 -> 0 | E6: =wp!F45 -> 0
B7: Audited, Hence Not editable | C7: All Items Editable | D7: All Items Editable | E7: All Items Editable
A8: Profit and Loss Items at a Glance :
A9: Gross Revenue / Turnover | B9: =wp!C10 -> 0 | C9: =wp!D10 -> #DIV/0! | D9: =wp!E10 -> #DIV/0! | E9: =wp!F10 -> #DIV/0!
A10: Direct Material & Expenses | B10: =wp!C17 -> 0 | C10: =wp!D17 -> #DIV/0! | D10: =wp!E17 -> #DIV/0! | E10: =wp!F17 -> #DIV/0!
A11: Closing Stock / WIP | B11: =wp!C18 -> 0 | C11: =wp!D18 -> 0 | D11: =wp!E18 -> 0 | E11: =wp!F18 -> 0
A12: Non Operating Income | B12: =wp!C23 -> 0 | C12: =wp!D23 -> 0 | D12: =wp!E23 -> 0 | E12: =wp!F23 -> 0
A13: Rent | B13: =wp!C83 -> 0 | C13: =wp!D83 -> 0 | D13: =wp!E83 -> 0 | E13: =wp!F83 -> 0
A14: Salaries & Wages | B14: =wp!C84 -> 0 | C14: =wp!D84 -> #DIV/0! | D14: =wp!E84 -> #DIV/0! | E14: =wp!F84 -> #DIV/0!
A15: Electricity | B15: =wp!C85 -> 0 | C15: =wp!D85 -> #DIV/0! | D15: =wp!E85 -> #DIV/0! | E15: =wp!F85 -> #DIV/0!
A16: Off Admin and Marketing Expenses | B16: =wp!C87 -> 0 | C16: =wp!D87 -> #DIV/0! | D16: =wp!E87 -> #DIV/0! | E16: =wp!F87 -> #DIV/0!
A17: Interest on Other loans | B17: =wp!C98 -> 0 | C17: =B17*C22/B22 -> #DIV/0! | D17: =IF(C22=0,0,C17*D22/C22) -> 0 | E17: =IF(D22=0,0,D17*E22/D22) -> 0
A18: Interest on CC/OD | B18: =wp!C99 -> 0 | C18: =wp!D99 -> #DIV/0! | D18: =wp!E99 -> #DIV/0! | E18: =wp!F99 -> #DIV/0!
A19: Earnings Before Tax (Not Editable) | B19: =PLBS!C35 -> 0 | C19: =PLBS!D35 -> #DIV/0! | D19: =PLBS!E35 -> #DIV/0! | E19: =PLBS!F35 -> #DIV/0!
A21: Balancesheet Items at a Glance:
A22: Term Loans(Secured and Unsecured) | B22: =wp!C51 -> 0 | C22: =wp!D51 -> 0 | D22: =wp!E51 -> 0 | E22: =wp!F51 -> 0
A23: Bank CC/OD loan | B23: =wp!C55 -> 0 | C23: =wp!D55 -> #DIV/0! | D23: =wp!E55 -> #DIV/0! | E23: =wp!F55 -> #DIV/0!
A24: Other current liabilities | B24: =wp!C56 -> 0 | C24: =wp!D56 -> 0 | D24: =wp!E56 -> 0 | E24: =wp!F56 -> 0
A25: Investments | B25: =wp!C66 -> 0 | C25: =wp!D66 -> 0 | D25: =wp!E66 -> 0 | E25: =wp!F66 -> 0
A26: Other current Assets | B26: =wp!C69 -> 0 | C26: =wp!D69 -> 0 | D26: =wp!E69 -> 0 | E26: =wp!F69 -> 0
A27: Debtors | B27: =wp!C71 -> 0 | C27: =wp!D71 -> #DIV/0! | D27: =wp!E71 -> #DIV/0! | E27: =wp!F71 -> #DIV/0!
A28: Cash and Cash Equivalents | B28: =wp!C72 -> 0 | C28: =wp!D72 -> #DIV/0! | D28: =wp!E72 -> #DIV/0! | E28: =wp!F72 -> #DIV/0!
A30: RATIO ANALYSIS at a Glance: (Not Editable but displayed)
A31: Gross profit ratio (%) | B31: =RATIO!C22 -> #DIV/0! | C31: =RATIO!D22 -> #DIV/0! | D31: =RATIO!E22 -> #DIV/0! | E31: =RATIO!F22 -> #DIV/0!
A32: Net Profit Ratio (%) | B32: =RATIO!C30 -> #DIV/0! | C32: =RATIO!D30 -> #DIV/0! | D32: =RATIO!E30 -> #DIV/0! | E32: =RATIO!F30 -> #DIV/0!
A33: Debtors Turonver Ratio (Days) | B33: =RATIO!C46 -> #DIV/0! | C33: =RATIO!D46 -> #DIV/0! | D33: =RATIO!E46 -> #DIV/0! | E33: =RATIO!F46 -> #DIV/0!
A34: Current Ratio | B34: =RATIO!C11 -> #DIV/0! | C34: =RATIO!D11 -> #DIV/0! | D34: =RATIO!E11 -> #DIV/0! | E34: =RATIO!F11 -> #DIV/0!
A35: Total outside Liabilities to Total Networth | B35: =RATIO!C56 -> #DIV/0! | C35: =RATIO!D56 -> #DIV/0! | D35: =RATIO!E56 -> #DIV/0! | E35: =RATIO!F56 -> #DIV/0!
A37: MAXIMUM PERMISSABLE BANK FINANCE:
A38: Method 1 : Working capital Method | C38: ='MPBF '!B28 -> #DIV/0! | D38: ='MPBF '!C28 -> #DIV/0! | E38: ='MPBF '!D28 -> #DIV/0!
A39: Method 1 : Current Assets Method | C39: ='MPBF '!B55 -> #DIV/0! | D39: ='MPBF '!C55 -> #DIV/0! | E39: ='MPBF '!D55 -> #DIV/0!
A40: Method 3 : Nayak Committee | C40: =nayak!C23 -> #DIV/0! | D40: =nayak!D23 -> #DIV/0! | E40: =nayak!E23 -> #DIV/0!

Sheet coverpage
D6: PROJECTIONS AND ESTIMATIONS
E8: OF | T8: Please use "IF" function in following cases
D10: =Assumptions.1!I3 -> 0
T11: In case of | U11: Designation
T12: Companies | U12: Managing Director
D13: =Assumptions.1!I5 -> 0 | T13: LLP | U13: Designated Partner
T14: Soleproprietor | U14: Proprietor
T15: Partnership firm | U15: Managing Partner
D18: =Assumptions.1!I8 -> 0
D22: =Assumptions.1!I6 -> 0
D26: Working(CC) capital Loan | H26: =Assumptions.1!I12 -> 0
E30: PREPARED BY
D32: FINVOIS OPEN BUSINESS SOLUTIONS LLP
D33: MSME & DPR Consultants
D34: Contact : 9618221011

Sheet PLBS
A1: =Assumptions.1!I3 -> 0
A2: =Assumptions.1!I5 -> 0
A3: =Assumptions.1!I6 -> 0
A4: TRADING, PROFIT & LOSS ACCOUNT FOR YEAR ENDED
A5: PARTICULARS | B5: Schedules | C5: =FinalWorkings!B5 -> Audited | D5: =FinalWorkings!C5 -> Estimated | E5: =FinalWorkings!D5 -> Projected | F5: =FinalWorkings!E5 -> Projected
C6: =FinalWorkings!B6 -> 0 | D6: =FinalWorkings!C6 -> 0 | E6: =FinalWorkings!D6 -> 0 | F6: =FinalWorkings!E6 -> 0
A8: Gross Revenue / Turnover:
A10: Revenue | C10: =wp!C10 -> 0 | D10: =ROUND(FinalWorkings!C9,-4) -> #DIV/0! | E10: =ROUND(FinalWorkings!D9,-4) -> #DIV/0! | F10: =ROUND(FinalWorkings!E9,-4) -> #DIV/0!
C12: =SUM(C10:C11) -> 0 | D12: =SUM(D10:D11) -> #DIV/0! | E12: =SUM(E10:E11) -> #DIV/0! | F12: =SUM(F10:F11) -> #DIV/0!
A14: Cost of Goods Sold:
A16: Opening Stock | C16: =wp!C16 -> 0 | D16: =wp!D16 -> 0 | E16: =wp!E16 -> 0 | F16: =wp!F16 -> 0
A17: Direct Material & Expenses | C17: =wp!C17 -> 0 | D17: =ROUND(FinalWorkings!C10,-4) -> #DIV/0! | E17: =ROUND(FinalWorkings!D10,-4) -> #DIV/0! | F17: =ROUND(FinalWorkings!E10,-4) -> #DIV/0!
A18: Closing Stock / WIP | C18: =wp!C18 -> 0 | D18: =ROUND(FinalWorkings!C11,-3) -> 0 | E18: =ROUND(FinalWorkings!D11,-3) -> 0 | F18: =ROUND(FinalWorkings!E11,-3) -> 0
A19: Operating Expenses | C19: =C16+C17-C18 -> 0 | D19: =D16+D17-D18 -> #DIV/0! | E19: =E16+E17-E18 -> #DIV/0! | F19: =F16+F17-F18 -> #DIV/0!
A21: Gross Profit | C21: =C12-C19 -> 0 | D21: =D12-D19 -> #DIV/0! | E21: =E12-E19 -> #DIV/0! | F21: =F12-F19 -> #DIV/0!
A23: Non Operating Income | C23: =wp!C23 -> 0 | D23: =ROUND(FinalWorkings!C12,-3) -> 0 | E23: =ROUND(FinalWorkings!D12,-3) -> 0 | F23: =ROUND(FinalWorkings!E12,-3) -> 0
A25: Less :Admintrative & Selling Expenses | B25: Sch 1 | C25: =C85 -> 0 | D25: =D85 -> #DIV/0! | E25: =E85 -> #DIV/0! | F25: =F85 -> #DIV/0!
A27: EBDIT | C27: =C21+C23-C25 -> 0 | D27: =D21+D23-D25 -> #DIV/0! | E27: =E21+E23-E25 -> #DIV/0! | F27: =F21+F23-F25 -> #DIV/0!
A29: Less : Depreciation | C29: =wp!C29 -> 0 | D29: =wp!D29 -> 0 | E29: =wp!E29 -> 0 | F29: =wp!F29 -> 0
A31: EBIT | C31: =C27-C29 -> 0 | D31: =D27-D29 -> #DIV/0! | E31: =E27-E29 -> #DIV/0! | F31: =F27-F29 -> #DIV/0!
A33: Less: Interest | B33: Sch 2 | C33: =C94 -> 0 | D33: =D94 -> #DIV/0! | E33: =E94 -> #DIV/0! | F33: =F94 -> #DIV/0!
A35: EBT | C35: =C31-C33 -> 0 | D35: =D31-D33 -> #DIV/0! | E35: =E31-E33 -> #DIV/0! | F35: =F31-F33 -> #DIV/0!
A38: =A1 -> 0
A39: =A2 -> 0
A40: =A3 -> 0
A42: BALANCE SHEET AS ON
A43: Particulars | B43: Schedules | C43: =C5 -> Audited | D43: =D5 -> Estimated | E43: =E5 -> Projected | F43: =F5 -> Projected
C44: =C6 -> 0 | D44: =D6 -> 0 | E44: =E6 -> 0 | F44: =F6 -> 0
A45: SOURCES OF FUNDS:
A47: Net Capital Including Net Reserves & Surplus | C47: =wp!C48 -> 0 | D47: =D56-SUM(D48:D55) -> #DIV/0! | E47: =E56-SUM(E48:E55) -> #DIV/0! | F47: =F56-SUM(F48:F55) -> #DIV/0!
A48: (Opening capital + Net profit -Drawings)
A49: TERM LOANS:
A50: Secured and Unsecured Loans | C50: =wp!C51 -> 0 | D50: =ROUND(FinalWorkings!C22,-3) -> 0 | E50: =ROUND(FinalWorkings!D22,-3) -> 0 | F50: =ROUND(FinalWorkings!E22,-3) -> 0
A52: CURRENT LIABILITIES:
A53: Bank CC/OD loan | C53: =wp!C55 -> 0 | D53: =wp!D55 -> #DIV/0! | E53: =wp!E55 -> #DIV/0! | F53: =wp!F55 -> #DIV/0!
A54: Other current liabilities | C54: =wp!C56 -> 0 | D54: =ROUND(FinalWorkings!C24,-4) -> 0 | E54: =ROUND(FinalWorkings!D24,-4) -> 0 | F54: =ROUND(FinalWorkings!E24,-4) -> 0
C56: =SUM(C47:C55) -> 0 | D56: =D70 -> #DIV/0! | E56: =E70 -> #DIV/0! | F56: =F70 -> #DIV/0!
A58: APPLICATION OF FUNDS:
A60: FIXED ASSETS: | C60: =wp!C64 -> 0 | D60: =wp!D64 -> 0 | E60: =wp!E64 -> 0 | F60: =wp!F64 -> 0
A62: INVESTMENTS: | C62: =wp!C66 -> 0 | D62: =ROUND(FinalWorkings!C25,-4) -> 0 | E62: =ROUND(FinalWorkings!D25,-4) -> 0 | F62: =ROUND(FinalWorkings!E25,-4) -> 0
...

Sheet RATIO
A1: =Assumptions.1!I3 -> 0
A2: =Assumptions.1!I5 -> 0
A3: =Assumptions.1!I6 -> 0
A5: RATIO ANALYSIS
A7: A . CURRENT RATIO
D8: IDEAL RATIO > 1.33
A9: Particulars | C9: =C98 -> 0 | D9: =D98 -> 0 | E9: =E98 -> 0 | F9: =F98 -> 0
A11: Current Assets / Current Liabilities | C11: =C13/C14 -> #DIV/0! | D11: =D13/D14 -> #DIV/0! | E11: =E13/E14 -> #DIV/0! | F11: =F13/F14 -> #DIV/0!
A13: Current Assets | C13: =SUM(PLBS!C65:C69) -> 0 | D13: =SUM(PLBS!D65:D69) -> #DIV/0! | E13: =SUM(PLBS!E65:E69) -> #DIV/0! | F13: =SUM(PLBS!F65:F69) -> #DIV/0!
A14: Current Liabilities | C14: =SUM(PLBS!C53:C55) -> 0 | D14: =SUM(PLBS!D53:D55) -> #DIV/0! | E14: =SUM(PLBS!E53:E55) -> #DIV/0! | F14: =SUM(PLBS!F53:F55) -> #DIV/0!
A16: NOTES : Indicates Ability to repay short term commitments promptly .
A18: B . GROSS PROFIT RATIO
A20: Particulars | C20: =C63 -> 0 | D20: =D63 -> 0 | E20: =E63 -> 0 | F20: =F63 -> 0
A22: Gross profit / Sales * 100 | C22: =PLBS!C21/PLBS!C10*100 -> #DIV/0! | D22: =PLBS!D21/PLBS!D10*100 -> #DIV/0! | E22: =PLBS!E21/PLBS!E10*100 -> #DIV/0! | F22: =PLBS!F21/PLBS!F10*100 -> #DIV/0!
A24: NOTES : Indicates Basic Profitability of the Business.
A26: C . NETPROFIT RATIO
A28: Particulars | C28: =C20 -> 0 | D28: =D20 -> 0 | E28: =E20 -> 0 | F28: =F20 -> 0
A30: Netprofit / Sales * 100 | C30: =PLBS!C35/PLBS!C10*100 -> #DIV/0! | D30: =PLBS!D35/PLBS!D10*100 -> #DIV/0! | E30: =PLBS!E35/PLBS!E10*100 -> #DIV/0! | F30: =PLBS!F35/PLBS!F10*100 -> #DIV/0!
A32: NOTES : Indicates overall Profitability of the Business.
A37: D . DEBTORS TURNOVER RATIO
A38: Particulars | C38: =C86 -> 0 | D38: =D86 -> 0 | E38: =E86 -> 0 | F38: =F86 -> 0
A40: Credit sales / Average debtors | C40: =PLBS!C10/PLBS!C67 -> #DIV/0! | D40: =PLBS!D10/PLBS!D67 -> #DIV/0! | E40: =PLBS!E10/PLBS!E67 -> #DIV/0! | F40: =PLBS!F10/PLBS!F67 -> #DIV/0!
A41: *Sales assumed as credit sales
A43: NOTES : It indicates velocity of debt collection. Higer the DTR indicates good vellocity of debt
A44: collection.
A46: DEBTORS COLLECTION PERIOD : | C46: =B49/C40 -> #DIV/0! | D46: =B49/D40 -> #DIV/0! | E46: =B49/E40 -> #DIV/0! | F46: =B49/F40 -> #DIV/0!
A47: (No of days/debtor turnover ratio)
A49: * No. of Days Assumed as | B49: 365
A52: E . TOTAL OUTSIDE LIABILITIES TO TOTAL NETWORTH RATIO :
A54: Particulars | C54: =C9 -> 0 | D54: =D9 -> 0 | E54: =E9 -> 0 | F54: =F9 -> 0
A56: TOL / TW | C56: =SUM(PLBS!C49:C55)/PLBS!C47 -> #DIV/0! | D56: =SUM(PLBS!D49:D55)/PLBS!D47 -> #DIV/0! | E56: =SUM(PLBS!E49:E55)/PLBS!E47 -> #DIV/0! | F56: =SUM(PLBS!F49:F55)/PLBS!F47 -> #DIV/0!
A58: NOTES : Indicates Extent of own funds used in business.
A61: F . INTEREST COVERAGE RATIO
E62: IDEAL RATIO - > 1
A63: Partiiculars | C63: =wp!C6 -> 0 | D63: =wp!D6 -> 0 | E63: =wp!E6 -> 0 | F63: =wp!F6 -> 0
A65: E B I / Interest | C65: =C67/C68 -> #DIV/0! | D65: =D67/D68 -> #DIV/0! | E65: =E67/E68 -> #DIV/0! | F65: =F67/F68 -> #DIV/0!
A67: EBI | C67: =PLBS!C31 -> 0 | D67: =PLBS!D31 -> #DIV/0! | E67: =PLBS!E31 -> #DIV/0! | F67: =PLBS!F31 -> #DIV/0!
A68: Interest | C68: =PLBS!C94 -> 0 | D68: =PLBS!D94 -> #DIV/0! | E68: =PLBS!E94 -> #DIV/0! | F68: =PLBS!F94 -> #DIV/0!
A70: NOTE : Indicates ability to meet Interest Obligation of the current year .
A74: G . WORKING CAPITAL TURNOVER RATIO :
...

Sheet MPBF 
A1: =Assumptions.1!I3 -> 0
A2: =Assumptions.1!I5 -> 0
A3: =Assumptions.1!I6 -> 0
A5: CALCULATION OF MAXIMUM PERMISSIBLE BANK FINANCE
A7: MPBF - Method 1 - 25%(Working Capital Gap)
A8: Particulars | B8: =wp!D5 -> Estimated | C8: =wp!E5 -> Projected | D8: =wp!F5 -> Projected
B9: =wp!D6 -> 0 | C9: =wp!E6 -> 0 | D9: =wp!F6 -> 0
A11: 1. Total current assets | B11: =SUM(PLBS!D64:D69) -> #DIV/0! | C11: =SUM(PLBS!E64:E69) -> #DIV/0! | D11: =SUM(PLBS!F64:F69) -> #DIV/0!
A13: 2. Other current liabilities | B13: =SUM(wp!D56:D57) -> 0 | C13: =SUM(wp!E56:E57) -> 0 | D13: =SUM(wp!F56:F57) -> 0
A14: (Other than bank borrowings )
A16: 3. Working capital gap | B16: =+B11-B13 -> #DIV/0! | C16: =+C11-C13 -> #DIV/0! | D16: =+D11-D13 -> #DIV/0!
A18: 4. Min. stipulated Networking capital
A19: (25% of WCG excluding export | B19: =+B16*0.25 -> #DIV/0! | C19: =+C16*0.25 -> #DIV/0! | D19: =+D16*0.25 -> #DIV/0!
A20: receivables)
A22: 5. Actual/projected net working capital | B22: =RATIO!D13-RATIO!D14 -> #DIV/0! | C22: =RATIO!E13-RATIO!E14 -> #DIV/0! | D22: =RATIO!F13-RATIO!F14 -> #DIV/0!
A24: 6.Item 3 minus item 4 | B24: =+B16-B19 -> #DIV/0! | C24: =+C16-C19 -> #DIV/0! | D24: =+D16-D19 -> #DIV/0!
A26: 7.Item 3 minus item 5 | B26: =B16-B22 -> #DIV/0! | C26: =C16-C22 -> #DIV/0! | D26: =D16-D22 -> #DIV/0!
A28: 8. Maximum permissible bank | B28: =IF(B24<B26,B24,B26) -> #DIV/0! | C28: =IF(C24<C26,C24,C26) -> #DIV/0! | D28: =IF(D24<D26,D24,D26) -> #DIV/0!
A29: finance(lower of 6 or 7 )
A33: =A5 -> CALCULATION OF MAXIMUM PERMISSIBLE BANK FINANCE
A35: MPBF - Method 2 - 25%(Current Assets)
A36: Particulars | B36: =B8 -> Estimated | C36: =C8 -> Projected | D36: =D8 -> Projected
B37: =B9 -> 0 | C37: =C9 -> 0 | D37: =D9 -> 0
A39: 1. Total current assets | B39: =B11 -> #DIV/0! | C39: =C11 -> #DIV/0! | D39: =D11 -> #DIV/0!
A41: 2. Other current liabilities | B41: =B13 -> 0 | C41: =C13 -> 0 | D41: =D13 -> 0
A42: (Other than bank borrowings )
A44: 3. Working capital gap | B44: =+B39-B41 -> #DIV/0! | C44: =+C39-C41 -> #DIV/0! | D44: =+D39-D41 -> #DIV/0!
A46: 4. Min. stipulated Networking capital
A47: (25% of Current Assets) | B47: =25/100*B39 -> #DIV/0! | C47: =25/100*C39 -> #DIV/0! | D47: =25/100*D39 -> #DIV/0!
A49: 5. Actual/projected net working capital | B49: =B22 -> #DIV/0! | C49: =C22 -> #DIV/0! | D49: =D22 -> #DIV/0!
A51: 6.Item 3 minus item 4 | B51: =+B44-B47 -> #DIV/0! | C51: =+C44-C47 -> #DIV/0! | D51: =+D44-D47 -> #DIV/0!
A53: 7.Item 3 minus item 5 | B53: =B44-B49 -> #DIV/0! | C53: =C44-C49 -> #DIV/0! | D53: =D44-D49 -> #DIV/0!
A55: 8. Maximum permissible bank | B55: =IF(B51<B53,B51,B53) -> #DIV/0! | C55: =IF(C51<C53,C51,C53) -> #DIV/0! | D55: =IF(D51<D53,D51,D53) -> #DIV/0!
A56: finance(lower of 6 or 7 )

Sheet nayak
A2: MEDICAID LABS LLP
A3: =Assumptions.1!I5 -> 0
A4: AUTONAGAR , VIJAYAWADA - 520 007
A6: WORKING CAPITAL ASSESSMENT - TURNOVER METHOD
A8: NAYAK COMMITTEE RECOMONDATIONS
A10: PARTICULARS | C10: ='MPBF '!B8 -> Estimated | D10: ='MPBF '!C8 -> Projected | E10: ='MPBF '!D8 -> Projected
C11: ='MPBF '!B9 -> 0 | D11: ='MPBF '!C9 -> 0 | E11: ='MPBF '!D9 -> 0
A13: Turnover | C13: =PLBS!D10 -> #DIV/0! | D13: =PLBS!E10 -> #DIV/0! | E13: =PLBS!F10 -> #DIV/0!
A15: Working Capital Requirement | C15: =C13*25/100 -> #DIV/0! | D15: =D13*25/100 -> #DIV/0! | E15: =E13*25/100 -> #DIV/0!
A16: (25% of Turnover)
A18: Minimum Working Capital Limit | C18: =C15*80/100 -> #DIV/0! | D18: =D15*80/100 -> #DIV/0! | E18: =E15*80/100 -> #DIV/0!
A19: (80% of Working Capital Requirment)
A21: Drawing Power | C21: =Assumptions.1!I13 -> 0 | D21: =C21 -> 0 | E21: =D21 -> 0
A23: Maximum Bank CC Loan | C23: =IF(C18<C21,C18,C21) -> #DIV/0! | D23: =IF(D18<D21,D18,D21) -> #DIV/0! | E23: =IF(E18<E21,E18,E21) -> #DIV/0!
A27: Notes :
A28: 1. Maximum Working capital Limit Must not exceed Drawing power .
A29: 2. Four Operating cycles per Annum is Assumed.

Sheet Depsch
A1: =Assumptions.1!I3 -> 0
A2: =Assumptions.1!I5 -> 0
A3: =Assumptions.1!I6 -> 0
A5: CALCULATION OF DEPRECIATION AS PER INCOME TAX ACT
M7: Rs in lacs
B9: =Assumptions.1!B99 -> Plant and Machinery | C9: =Assumptions.1!B109 -> Service Equipment | D9: =Assumptions.1!B119 -> Shed and Civil works | E9: =Assumptions.1!B129 -> Land | F9: =Assumptions.1!B132 -> Electrical Items | G9: =Assumptions.1!B141 -> Electronic items | H9: =Assumptions.1!B151 -> Furniture and Fittings | I9: =Assumptions.1!B161 -> Vehicles | J9: =Assumptions.1!B171 -> Live stock | K9: =Assumptions.1!B180 -> Other Assets | L9: =Assumptions.1!B190 -> Other Assets (Nil Depreciation)
M11: Total
B12: =Assumptions.1!I69 -> 0.15 | C12: =Assumptions.1!I70 -> 0.15 | D12: =Assumptions.1!I71 -> 0.1 | E12: =Assumptions.1!I72 -> 0 | F12: =Assumptions.1!I74 -> 0.15 | G12: =Assumptions.1!I75 -> 0.15 | H12: =Assumptions.1!I73 -> 0.1 | I12: =Assumptions.1!I76 -> 0.15 | J12: =Assumptions.1!I77 -> 0 | K12: =Assumptions.1!I79 -> 0.1 | L12: =Assumptions.1!I78 -> 0
A15: =Assumptions.1!I19 -> 0
A16: WDV (31.03.2025) | B16: =Assumptions.1!F99 -> 0 | C16: =Assumptions.1!F109 -> 0 | D16: =Assumptions.1!F119 -> 0 | E16: =Assumptions.1!F129 -> 0 | F16: =Assumptions.1!F132 -> 0 | G16: =Assumptions.1!F141 -> 0 | H16: =Assumptions.1!F151 -> 0 | I16: =Assumptions.1!F161 -> 0 | J16: =Assumptions.1!F171 -> 0 | K16: =Assumptions.1!F180 -> 0 | L16: =Assumptions.1!F190 -> 0 | M16: =B16+C16+D16+E16+F16+G16+H16+I16+J16+K16+L16 -> 0
A17: Add Additions | B17: 0 | C17: 0 | D17: 0 | E17: 0 | F17: 0 | G17: 0 | H17: 0 | I17: 0 | J17: 0 | K17: 0 | L17: 0 | M17: =B17+C17+D17+E17+F17+G17+H17+I17+J17+K17+L17 -> 0
A18: Total | B18: =B16+B17 -> 0 | C18: =C16+C17 -> 0 | D18: =D16+D17 -> 0 | E18: =E16+E17 -> 0 | F18: =F16+F17 -> 0 | G18: =G16+G17 -> 0 | H18: =H16+H17 -> 0 | I18: =I16+I17 -> 0 | ... L18: =L16+L17 -> 0 | M18: =B18+C18+D18+E18+F18+G18+H18+I18+J18+K18+L18 -> 0
A19: Depreciation | B19: =B18*B12 -> 0 | C19: =C18*C12 -> 0 | D19: =D18*D12 -> 0 | E19: =E18*E12 -> 0 | F19: =F18*F12 -> 0 | G19: =G18*G12 -> 0 | H19: =H18*H12 -> 0 | I19: =I18*I12 -> 0 | ... L19: =L18*L12 -> 0 | M19: =B19+C19+D19+E19+F19+G19+H19+I19+J19+K19+L19 -> 0
A20: WDVat the end of 1st Year | B20: =B18-B19 -> 0 | C20: =C18-C19 -> 0 | D20: =D18-D19 -> 0 | E20: =E18-E19 -> 0 | F20: =F18-F19 -> 0 | G20: =G18-G19 -> 0 | H20: =H18-H19 -> 0 | I20: =I18-I19 -> 0 | ... L20: =L18-L19 -> 0 | M20: =B20+C20+D20+E20+F20+G20+H20+I20+J20+K20+L20 -> 0
M21: =B21+C21+D21+E21+F21+G21+H21+I21+J21+K21+L21 -> 0
A22: =Assumptions.1!I20 -> 0 | M22: =B22+C22+D22+E22+F22+G22+H22+I22+J22+K22+L22 -> 0
A23: WDV | B23: =B20 -> 0 | C23: =C20 -> 0 | D23: =D20 -> 0 | E23: =E20 -> 0 | F23: =F20 -> 0 | G23: =G20 -> 0 | H23: =H20 -> 0 | I23: =I20 -> 0 | ... L23: =L20 -> 0 | M23: =B23+C23+D23+E23+F23+G23+H23+I23+J23+K23+L23 -> 0
A24: Add Additions | B24: 0 | C24: 0 | D24: 0 | E24: 0 | F24: 0 | G24: 0 | H24: 0 | I24: 0 | J24: 0 | K24: 0 | L24: 0 | M24: =B24+C24+D24+E24+F24+G24+H24+I24+J24+K24+L24 -> 0
A25: Total | B25: =B23+B24 -> 0 | C25: =C23+C24 -> 0 | D25: =D23+D24 -> 0 | E25: =E23+E24 -> 0 | F25: =F23+F24 -> 0 | G25: =G23+G24 -> 0 | H25: =H23+H24 -> 0 | I25: =I23+I24 -> 0 | ... L25: =L23+L24 -> 0 | M25: =B25+C25+D25+E25+F25+G25+H25+I25+J25+K25+L25 -> 0
A26: Depreciation | B26: =B25*B12 -> 0 | C26: =C25*C12 -> 0 | D26: =D25*D12 -> 0 | E26: =E25*E12 -> 0 | F26: =F25*F12 -> 0 | G26: =G25*G12 -> 0 | H26: =H25*H12 -> 0 | I26: =I25*I12 -> 0 | ... L26: =L25*L12 -> 0 | M26: =B26+C26+D26+E26+F26+G26+H26+I26+J26+K26+L26 -> 0
A27: WDVat the end of 2nd Year | B27: =B25-B26 -> 0 | C27: =C25-C26 -> 0 | D27: =D25-D26 -> 0 | E27: =E25-E26 -> 0 | F27: =F25-F26 -> 0 | G27: =G25-G26 -> 0 | H27: =H25-H26 -> 0 | I27: =I25-I26 -> 0 | ... L27: =L25-L26 -> 0 | M27: =B27+C27+D27+E27+F27+G27+H27+I27+J27+K27+L27 -> 0
M28: =B28+C28+D28+E28+F28+G28+H28+I28+J28+K28+L28 -> 0
A29: =Assumptions.1!I21 -> 0 | M29: =B29+C29+D29+E29+F29+G29+H29+I29+J29+K29+L29 -> 0
A30: WDV | B30: =B27 -> 0 | C30: =C27 -> 0 | D30: =D27 -> 0 | E30: =E27 -> 0 | F30: =F27 -> 0 | G30: =G27 -> 0 | H30: =H27 -> 0 | I30: =I27 -> 0 | ... L30: =L27 -> 0 | M30: =B30+C30+D30+E30+F30+G30+H30+I30+J30+K30+L30 -> 0
A31: Add Additions | B31: 0 | C31: 0 | D31: 0 | E31: 0 | F31: 0 | G31: 0 | H31: 0 | I31: 0 | J31: 0 | K31: 0 | L31: 0 | M31: =B31+C31+D31+E31+F31+G31+H31+I31+J31+K31+L31 -> 0
A32: Total | B32: =B30+B31 -> 0 | C32: =C30+C31 -> 0 | D32: =D30+D31 -> 0 | E32: =E30+E31 -> 0 | F32: =F30+F31 -> 0 | G32: =G30+G31 -> 0 | H32: =H30+H31 -> 0 | I32: =I30+I31 -> 0 | ... L32: =L30+L31 -> 0 | M32: =B32+C32+D32+E32+F32+G32+H32+I32+J32+K32+L32 -> 0
A33: Depreciation | B33: =B32*B12 -> 0 | C33: =C32*C12 -> 0 | D33: =D32*D12 -> 0 | E33: =E32*E12 -> 0 | F33: =F32*F12 -> 0 | G33: =G32*G12 -> 0 | H33: =H32*H12 -> 0 | I33: =I32*I12 -> 0 | ... L33: =L32*L12 -> 0 | M33: =B33+C33+D33+E33+F33+G33+H33+I33+J33+K33+L33 -> 0
A34: WDVat the end of 3rd Year | B34: =B32-B33 -> 0 | C34: =C32-C33 -> 0 | D34: =D32-D33 -> 0 | E34: =E32-E33 -> 0 | F34: =F32-F33 -> 0 | G34: =G32-G33 -> 0 | H34: =H32-H33 -> 0 | I34: =I32-I33 -> 0 | ... L34: =L32-L33 -> 0 | M34: =B34+C34+D34+E34+F34+G34+H34+I34+J34+K34+L34 -> 0
